Workbook
Name CLASS: #REF!
Name CLASS: #REF!
Name CLASS: #REF!
Name CODE: #REF!
Name CODE: #REF!
Name CODE: #REF!
Name CODE: #REF!
Name CODE: #REF!
Name CODE: #REF!
Name CODE: #REF!
Name COURSE_NAME: #REF!
Name COURSE_NAME: #REF!
Name COURSE_NAME: #REF!
Name COURSE_NAME: #REF!
Name COURSE_NAME: #REF!
Name COURSE_NAME: #REF!
Name COURSE_NAME: #REF!
Name EA: #REF!
Name EA: #REF!
Name EA: #REF!
Name EA: #REF!
Name EA: #REF!
Name ED3_TEL: [1]tt!#REF!
Name ED4_IND: [1]tt!#REF!
Name EXAMINER: #REF!
Name EXAMINER: #REF!
Name EXAMINER: #REF!
Name EXAMINER: #REF!
Name EXAMINER: #REF!
Name EXAMINER: #REF!
Name EXAMINER: #REF!
Name hy: #REF!
Name hy: #REF!
Name hy: #REF!
Name hy: #REF!
Name hy: #REF!
Name po: #REF!
Name po: #REF!
Name po: #REF!
Name po: #REF!
Name po: #REF!
Name room_no: #REF!
Name room_no: #REF!
Name room_no: #REF!
Name room_no: #REF!
Name room_no: #REF!
Name ROOM_NO.: #REF!
Name ROOM_NO.: #REF!
Name ROOM_NO.: #REF!
Name ROOM_NO.: #REF!
Name ROOM_NO.: #REF!
Name ROOM_NO.: #REF!
Name ROOM_NO.: #REF!
Name STDS: #REF!
Name STDS: #REF!
Name STDS: #REF!
Name STDS: #REF!
Name STDS: #REF!
Name STDS: #REF!
Name STDS: #REF!

Sheet TT 1.0
A1: Monday, 17 August 2026 | I1: Tuesday, 11 April 2023,,
A2: Session, 1 (8:30 AM - 10:30 AM) | I2: Session, 1 (8:30 AM - 10:30 AM),,
A3: CODE | B3: COURSE NAME | C3: EXAMINER | D3: CLASS | E3: # STDS | F3: ROOM NO. | G3: TO PRT | I3: CODE ,COURSE NAME ,# STDS
A4: CHE 258 | B4: {=IFERROR(VLOOKUP(I4:I10,Lectures_1!A2:F534,2,FALSE()),0)} -> DRAWING FOR ENGINEERS | C4: {=IFERROR(VLOOKUP(I4:I10,Lectures_1!A2:F534,3,FALSE()),0)} -> Darkwah Lawrence | D4: ED2-CHE | E4: {=IFERROR(VLOOKUP(I4:I10,Lectures_1!A2:F534,4,FALSE()),0)} -> 160 | G4: =E4*1.1 -> 176 | I4: =CONCATENATE(A4,",",D4) -> CHE 258,ED2-CHE
A5: CHE 258 | B5: DRAWING FOR ENGINEERS | C5: Darkwah Lawrence | D5: ED2-PCE | E5: 65 | G5: =E5*1.1 -> 71.5 | I5: =CONCATENATE(A5,",",D5) -> CHE 258,ED2-PCE
A6: COE 354 | B6: OPERATING SYSTEMS | C6: Kommey Benjamin | D6: ED3-COE | E6: 265 | G6: =E6*1.1 -> 291.5 | I6: =CONCATENATE(A6,",",D6) -> COE 354,ED3-COE
A7: PE 360 | B7: WELL TESTING | C7: Adenutsi Caspar Daniel | D7: ED3-PE | E7: 80 | G7: =E7*1.1 -> 88 | I7: =CONCATENATE(A7,",",D7) -> PE 360,ED3-PE
A8: EE 156 | B8: ELECTRICAL ENG. DRAWING | C8: Kwegyir Daniel | D8: ED1-COE | E8: 262 | F8: BYOD | G8: =E8*1.1 -> 288.2 | I8: =CONCATENATE(A8,",",D8) -> EE 156,ED1-COE
A9: AME 376 | B9: AUTOMOTIVE CHASSIS | C9: Ayetor Godwin Kafui Kwesi | D9: ED3-AUTO | E9: 40 | G9: =E9*1.1 -> 44 | I9: =CONCATENATE(A9,",",D9) -> AME 376,ED3-AUTO
A10: EE 272 | B10: DIGITAL SYSTEMS | C10: Opoku Daniel | D10: ED2-EE | E10: 340 | G10: =E10*1.1 -> 374 | I10: =CONCATENATE(A10,",",D10) -> EE 272,ED2-EE
D11: Total M1-1 | E11: =SUM(E4:E10) -> 1212 | I11: ,Total T1-1
A13: Monday, 17 August 2026 | I13: Tuesday, 11 April 2023,
A14: Session, 2 (12:00 PM - 2:00 PM) | I14: Session, 2 (12:00 PM - 2:00 PM),
A15: CODE | B15: COURSE NAME | C15: EXAMINER | D15: CLASS | E15: # STDS | F15: ROOM NO. | G15: TO PRT | I15: CODE ,CLASS
A16: ME 274 | B16: {=IFERROR(VLOOKUP(I16:I28,Lectures_1!A2:F534,2,FALSE()),0)} -> MACHINE DESIGN PROJECT | C16: {=IFERROR(VLOOKUP(I16:I28,Lectures_1!A2:F534,3,FALSE()),0)} -> Andoh Prince Yaw | D16: ED2-ME | E16: {=IFERROR(VLOOKUP(I16:I28,Lectures_1!A2:F534,4,FALSE()),0)} -> 240 | F16: Computer Based | G16: =E16*1.1 -> 264 | I16: =CONCATENATE(A16,",",D16) -> ME 274,ED2-ME
A17: AERO 274 | B17: AEROSPACE DESIGN PROJECT II | C17: Andoh Prince Yaw | D17: ED2-AERO | E17: 75 | G17: =E17*1.1 -> 82.5 | I17: =CONCATENATE(A17,",",D17) -> AERO 274,ED2-AERO
A18: IE 274 | B18: SECOND YEAR DESIGN PROJECT | C18: Andoh Prince Yaw | D18: ED2-IND | E18: 80 | G18: =E18*1.1 -> 88 | I18: =CONCATENATE(A18,",",D18) -> IE 274,ED2-IND
A19: AME 274 | B19: AUTOMOTIVE DESIGN PROJECT | C19: Andoh Prince Yaw | D19: ED2-AUTO | E19: 82 | G19: =E19*1.1 -> 90.2 | I19: =CONCATENATE(A19,",",D19) -> AME 274,ED2-AUTO
A20: MME 274 | B20: MARINE ENGINEERING DESIGN PROJECT II | C20: Andoh Prince Yaw | D20: ED2-MARI | E20: 37 | G20: =E20*1.1 -> 40.7 | I20: =CONCATENATE(A20,",",D20) -> MME 274,ED2-MARI
A21: PCE 450 | B21: PETROLEUM REFINING ENGINEERING | C21: Kwao-Boateng Emmanuela | D21: ED4-PCE | E21: 55 | G21: =E21*1.1 -> 60.5 | I21: =CONCATENATE(A21,",",D21) -> PCE 450,ED4-PCE
A22: PE 464 | B22: REFINING PROCESS TECHNOLOGY | C22: Kwao-Boateng Emmanuela | D22: ED4-PE | E22: 99 | G22: =E22*1.1 -> 108.9 | I22: =CONCATENATE(A22,",",D22) -> PE 464,ED4-PE
A23: PCE 464 | B23: REFINING PROCESSES TECHNOLOGY | C23: Kwao-Boateng Emmanuela | D23: ED4-CHE | E23: 50 | G23: =E23*1.1 -> 55 | I23: =CONCATENATE(A23,",",D23) -> PCE 464,ED4-CHE
A24: AE 458 | B24: CROP LOSSES AND THEIR CONTROL | C24: Darko Joseph Ofei | D24: ED4-AE | E24: 103 | G24: =E24*1.1 -> 113.3 | I24: =CONCATENATE(A24,",",D24) -> AE 458,ED4-AE
A25: EE 156 | B25: ELECTRICAL ENG. DRAWING | C25: Kwegyir Daniel | D25: ED1-EE | E25: 295 | F25: BYOD | G25: =E25*1.1 -> 324.5 | I25: =CONCATENATE(A25,",",D25) -> EE 156,ED1-EE
A26: GE 286 | B26: PRINCIPLES OF SURVEYING | C26: Akwasi Afrifa Acheampong | D26: ED2-AE | E26: 155 | G26: =E26*1.1 -> 170.5 | I26: =CONCATENATE(A26,",",D26) -> GE 286,ED2-AE
A27: CE 256 | B27: FLUID MECHANICS | C27: Anornu Geophrey Kwame | D27: ED2-GEOL | E27: 150 | G27: =E27*1.1 -> 165 | I27: =CONCATENATE(A27,",",D27) -> CE 256,ED2-GEOL
A28: CE 256 | B28: FLUID MECHANICS | C28: Anornu Geophrey Kwame | D28: ED2-CE | E28: 250 | G28: =E28*1.1 -> 275 | I28: =CONCATENATE(A28,",",D28) -> CE 256,ED2-CE
D29: Total M1-2 | E29: =SUM(E21:E28) -> 1157 | I29: ,Total T1-2
A31: Monday, 17 August 2026 | I31: Tuesday, 11 April 2023,
A32: Session, 3 (3:00 PM - 5:00 PM) | I32: Session, 2 (12:00 PM - 2:00 PM),
A33: CODE | B33: COURSE NAME | C33: EXAMINER | D33: CLASS | E33: # STDS | F33: ROOM NO. | G33: TO PRT | I33: CODE ,CLASS
A34: ME 374 | B34: {=IFERROR(VLOOKUP(I34:I42,Lectures_1!A2:F534,2,FALSE()),0)} -> MACHINE ELEMENTS DESIGN II | C34: {=IFERROR(VLOOKUP(I34:I42,Lectures_1!A2:F534,3,FALSE()),0)} -> Andoh Prince Yaw | D34: ED3-ME | E34: {=IFERROR(VLOOKUP(I34:I42,Lectures_1!A2:F534,4,FALSE()),0)} -> 222 | F34: BYOD | G34: =E34*1.1 -> 244.2 | I34: =CONCATENATE(A34,",",D34) -> ME 374,ED3-ME
A35: PCE 354 | B35: PETROCHEMICAL ENGINEERING LABORATORY II | C35: Bonsu Jude Kwaku | D35: ED3-PCE | E35: 53 | G35: =E35*1.1 -> 58.3 | I35: =CONCATENATE(A35,",",D35) -> PCE 354,ED3-PCE
A36: BME 372 | B36: BIOINSTRUMENTATION I | C36: Acquah Isaac | D36: ED3-BME | E36: 90 | G36: =E36*1.1 -> 99 | I36: =CONCATENATE(A36,",",D36) -> BME 372,ED3-BME
A37: ME 464 | B37: INSTRUMENTATION | C37: Adam Faisal Wahib | D37: ED4-ME | E37: 135 | G37: =E37*1.1 -> 148.5 | I37: =CONCATENATE(A37,",",D37) -> ME 464,ED4-ME
A38: MME 482 | B38: NAVAL ARCHITECTURE II | C38: Kudzedzi Emmanuel Yaw Mawuko | D38: ED4-MARI | E38: 23 | G38: =E38*1.1 -> 25.3 | I38: =CONCATENATE(A38,",",D38) -> MME 482,ED4-MARI
A39: EE 362 | B39: SUBSTATIONS AND TRANSMISSION LINE DESIGN | C39: Antoh Emmanuel Kwaku | D39: ED3-EE | E39: 240 | G39: =E39*1.1 -> 264 | I39: =CONCATENATE(A39,",",D39) -> EE 362,ED3-EE
A40: CHE 362 | B40: SILICATE TECHNOLOGY II | C40: Momade Zsuzsanna Gál | D40: ED3-CHE | E40: 15 | G40: =E40*1.1 -> 16.5 | I40: =CONCATENATE(A40,",",D40) -> CHE 362,ED3-CHE
A41: CE 154 | B41: PROPERTIES OF CIVIL ENGINEERING MATERIAL | C41: Kankam Charles Kwame | D41: ED1-CE | E41: 245 | G41: =E41*1.1 -> 269.5 | I41: =CONCATENATE(A41,",",D41) -> CE 154,ED1-CE
A42: GE 372 | B42: ANALYSIS OF ERRORS | C42: Collins Fosu | D42: ED3-GEOM | E42: 122 | G42: =E42*1.1 -> 134.2 | I42: =CONCATENATE(A42,",",D42) -> GE 372,ED3-GEOM
...

Sheet TTFINAL
A1: Monday, 17 August 2026 | I1: =A1 -> Monday, 17 August 2026
A2: Session, 1 (8:30 AM - 10:30 AM) | I2: =A2 -> Session, 1 (8:30 AM - 10:30 AM)
A3: CODE | B3: COURSE NAME | C3: EXAMINER | D3: CLASS | E3: # STDS | F3: ROOM NO. | G3: TO PRT | I3: CODE ,COURSE NAME ,# STDS
A4: CHE 258 | B4: {=IFERROR(VLOOKUP(I4:I9,Lectures_1!A2:F534,2,FALSE()),0)} -> DRAWING FOR ENGINEERS | C4: {=IFERROR(VLOOKUP(I4:I9,Lectures_1!A2:F534,3,FALSE()),0)} -> Darkwah Lawrence | D4: ED2-CHE | E4: {=IFERROR(VLOOKUP(I4:I9,Lectures_1!A2:F534,4,FALSE()),0)} -> 160 | F4: VSLA/303/RMA/RMB/206/304 | G4: =E4*1.1 -> 176 | H4: 45/30/22/22/22/20 | I4: =CONCATENATE(A4,",",D4) -> CHE 258,ED2-CHE
A5: CHE 258 | B5: DRAWING FOR ENGINEERS | C5: Darkwah Lawrence | D5: ED2-PCE | E5: 65 | F5: NEB-FF2/NEB-FF1 | G5: =E5*1.1 -> 71.5 | H5: 25/40 | I5: =CONCATENATE(A5,",",D5) -> CHE 258,ED2-PCE
A6: COE 354 | B6: OPERATING SYSTEMS | C6: Kommey Benjamin | D6: ED3-COE | E6: 265 | F6: PB001/PB014/PB020/PB201/PB214/PB008/PB208/PB212 | G6: =E6*1.1 -> 291.5 | H6: 36/36/36/36/36/30/30/22 | I6: =CONCATENATE(A6,",",D6) -> COE 354,ED3-COE
A7: EE 156 | B7: ELECTRICAL ENG. DRAWING | C7: Kwegyir Daniel | D7: ED1-COE | E7: 262 | F7: NEB-TF/NEB-SF | G7: =E7*1.1 -> 288.2 | H7: 131/131 | I7: =CONCATENATE(A7,",",D7) -> EE 156,ED1-COE
A8: AERO 368 | B8: PROPULSION | C8: Bofah Kwasi Kete | D8: ED3-AERO | E8: 76 | F8: NAF1/A110 | G8: =E8*1.1 -> 83.6 | H8: 46/30 | I8: =CONCATENATE(A8,",",D8) -> AERO 368,ED3-AERO
A9: EE 272 | B9: DIGITAL SYSTEMS | C9: Opoku Daniel | D9: ED2-EE | E9: 340 | F9: PB001/PB014/PB020/PB201/PB214/PB008/PB208/PB212/NEB-FF1/NEB-FF2 | G9: =E9*1.1 -> 374 | H9: 38/38/38/38/38/28/28/25/45/25 | I9: =CONCATENATE(A9,",",D9) -> EE 272,ED2-EE
D10: Total M1-1 | E10: =SUM(E4:E9) -> 1168 | I10: ,Total T1-1
A12: Monday, 17 August 2026 | I12: =A12 -> Monday, 17 August 2026
A13: Session, 2 (12:00 PM - 2:00 PM) | I13: =A13 -> Session, 2 (12:00 PM - 2:00 PM)
A14: CODE | B14: COURSE NAME | C14: EXAMINER | D14: CLASS | E14: # STDS | F14: ROOM NO. | G14: TO PRT | I14: CODE ,CLASS
A15: ME 274 | B15: {=IFERROR(VLOOKUP(I15:I28,Lectures_1!A2:F534,2,FALSE()),0)} -> MACHINE DESIGN PROJECT | C15: {=IFERROR(VLOOKUP(I15:I28,Lectures_1!A2:F534,3,FALSE()),0)} -> Andoh Prince Yaw | D15: ED2-ME | E15: {=IFERROR(VLOOKUP(I15:I28,Lectures_1!A2:F534,4,FALSE()),0)} -> 240 | F15: Computer Based | G15: =E15*1.1 -> 264 | I15: =CONCATENATE(A15,",",D15) -> ME 274,ED2-ME
A16: AERO 274 | B16: AEROSPACE DESIGN PROJECT II | C16: Andoh Prince Yaw | D16: ED2-AERO | E16: 75 | G16: =E16*1.1 -> 82.5 | I16: =CONCATENATE(A16,",",D16) -> AERO 274,ED2-AERO
A17: IE 274 | B17: SECOND YEAR DESIGN PROJECT | C17: Andoh Prince Yaw | D17: ED2-IND | E17: 80 | G17: =E17*1.1 -> 88 | I17: =CONCATENATE(A17,",",D17) -> IE 274,ED2-IND
A18: AME 274 | B18: AUTOMOTIVE DESIGN PROJECT | C18: Andoh Prince Yaw | D18: ED2-AUTO | E18: 82 | G18: =E18*1.1 -> 90.2 | I18: =CONCATENATE(A18,",",D18) -> AME 274,ED2-AUTO
A19: MME 274 | B19: MARINE ENGINEERING DESIGN PROJECT II | C19: Andoh Prince Yaw | D19: ED2-MARI | E19: 37 | G19: =E19*1.1 -> 40.7 | I19: =CONCATENATE(A19,",",D19) -> MME 274,ED2-MARI
A20: PCE 450 | B20: PETROLEUM REFINING ENGINEERING | C20: Kwao-Boateng Emmanuela | D20: ED4-PCE | E20: 55 | F20: VSLA/303 | G20: =E20*1.1 -> 60.5 | H20: 35/20 | I20: =CONCATENATE(A20,",",D20) -> PCE 450,ED4-PCE
A21: PCE 464 | B21: REFINING PROCESSES TECHNOLOGY | C21: Kwao-Boateng Emmanuela | D21: ED4-CHE | E21: 50 | F21: NEB-FF1 | G21: =E21*1.1 -> 55 | H21: 50 | I21: =CONCATENATE(A21,",",D21) -> PCE 464,ED4-CHE
A22: ME 296 | B22: MECHANICAL ENGINEERING LAB. II | C22: Boahen Samuel | D22: ED2-AE | E22: 155 | F22: VSLA/303/RMA/RMB/206/304 | G22: =E22*1.1 -> 170.5 | H22: 40/30/22/22/22/20 | I22: =CONCATENATE(A22,",",D22) -> ME 296,ED2-AE
A23: CHE 362 | B23: SILICATE TECHNOLOGY II | C23: Momade Zsuzsanna Gál | D23: ED3-CHE | E23: 15 | F23: RMA | G23: =E23*1.1 -> 16.5 | H23: 15 | I23: =CONCATENATE(A23,",",D23) -> CHE 362,ED3-CHE
A24: EE 152 | B24: BASIC ELECTRONICS | C24: Kwegyir Daniel | D24: ED1-GEOM | E24: 103 | F24: NEB-SF | G24: =E24*1.1 -> 113.3 | H24: 103 | I24: =CONCATENATE(A24,",",D24) -> EE 152,ED1-GEOM
A25: EE 152 | B25: BASIC ELECTRONICS | C25: Kwegyir Daniel | D25: ED1-GEOL | E25: 125 | F25: NEB-TF | G25: =E25*1.1 -> 137.5 | H25: 125 | I25: =CONCATENATE(A25,",",D25) -> EE 152,ED1-GEOL
A26: CE 154 | B26: PROPERTIES OF CIVIL ENGINEERING MATERIAL | C26: Kankam Charles Kwame | D26: ED1-CE | E26: 245 | F26: PB001/PB014/PB020/PB201/PB214/PB008/PB208/PB212 | G26: =E26*1.1 -> 269.5 | H26: 35/35/35/35/35/25/25/20 | I26: =CONCATENATE(A26,",",D26) -> CE 154,ED1-CE
A27: CE 256 | B27: FLUID MECHANICS | C27: Anornu Geophrey Kwame | D27: ED2-GEOL | E27: 150 | F27: NAF1/A110/EA/VCR/NEB-FF1 | G27: =E27*1.1 -> 165 | H27: 40/30/30/25/25 | I27: =CONCATENATE(A27,",",D27) -> CE 256,ED2-GEOL
A28: CE 256 | B28: FLUID MECHANICS | C28: Anornu Geophrey Kwame | D28: ED2-CE | E28: 250 | F28: PB001/PB014/PB020/PB201/PB214/PB008/PB208/PB212 | G28: =E28*1.1 -> 275 | H28: 36/36/36/36/36/25/25/20 | I28: =CONCATENATE(A28,",",D28) -> CE 256,ED2-CE
D29: Total M1-2 | E29: =SUM(E20:E28) -> 1148 | I29: ,Total T1-2
A31: Monday, 17 August 2026 | I31: =A31 -> Monday, 17 August 2026
A32: Session, 3 (3:00 PM - 5:00 PM) | I32: =A32 -> Session, 3 (3:00 PM - 5:00 PM)
A33: CODE | B33: COURSE NAME | C33: EXAMINER | D33: CLASS | E33: # STDS | F33: ROOM NO. | G33: TO PRT | I33: CODE ,CLASS
A34: ME 374 | B34: {=IFERROR(VLOOKUP(I34:I41,Lectures_1!A2:F534,2,FALSE()),0)} -> MACHINE ELEMENTS DESIGN II | C34: {=IFERROR(VLOOKUP(I34:I41,Lectures_1!A2:F534,3,FALSE()),0)} -> Andoh Prince Yaw | D34: ED3-ME | E34: {=IFERROR(VLOOKUP(I34:I41,Lectures_1!A2:F534,4,FALSE()),0)} -> 222 | F34: COMPUTER BASED | G34: =E34*1.1 -> 244.2 | I34: =CONCATENATE(A34,",",D34) -> ME 374,ED3-ME
A35: ME 464 | B35: INSTRUMENTATION | C35: Adam Faisal Wahib | D35: ED4-ME | E35: 135 | F35: VSLA/303/206/RMA/RMB | G35: =E35*1.1 -> 148.5 | H35: 40/30/22/22/21 | I35: =CONCATENATE(A35,",",D35) -> ME 464,ED4-ME
A36: CE 376 | B36: QUANTITIES AND COST ESTIMATION IN CIVIL ENGINEERING | C36: Osei Jack Banahene | D36: ED3-CE | E36: 230 | F36: NEB-FF1/NEB-FF2/NEB-SF/NEB-TF | G36: =E36*1.1 -> 253 | H36: 50/30/75/75 | I36: =CONCATENATE(A36,",",D36) -> CE 376,ED3-CE
A37: EE 362 | B37: SUBSTATIONS AND TRANSMISSION LINE DESIGN | C37: Antoh Emmanuel Kwaku | D37: ED3-EE | E37: 240 | F37: PB001/PB014/PB020/PB201/PB214/PB008/PB208 | G37: =E37*1.1 -> 264 | H37: 37/37/37/37/37/28/28 | I37: =CONCATENATE(A37,",",D37) -> EE 362,ED3-EE
A38: AME 386 | B38: MANUAL POWER TRAIN | C38: Abu Frimpong Solomon | D38: ED3-AUTO | E38: 40 | F38: PB001/PB014 | G38: =E38*1.1 -> 44 | H38: 20/20 | I38: =CONCATENATE(A38,",",D38) -> AME 386,ED3-AUTO
A39: MME 482 | B39: NAVAL ARCHITECTURE II | C39: Kudzedzi Emmanuel Yaw Mawuko | D39: ED4-MARI | E39: 23 | F39: PB020 | G39: =E39*1.1 -> 25.3 | H39: 23 | I39: =CONCATENATE(A39,",",D39) -> MME 482,ED4-MARI
A40: PE 360 | B40: WELL TESTING | C40: Adenutsi Caspar Daniel | D40: ED3-PE | E40: 80 | F40: NEB-TF/NEB-SF | G40: =E40*1.1 -> 88 | H40: 40/40 | I40: =CONCATENATE(A40,",",D40) -> PE 360,ED3-PE
A41: GE 372 | B41: ANALYSIS OF ERRORS | C41: Collins Fosu | D41: ED3-GEOM | E41: 122 | F41: NAF1/A110/EA/VCR | G41: =E41*1.1 -> 134.2 | H41: 40/30/30/22 | I41: =CONCATENATE(A41,",",D41) -> GE 372,ED3-GEOM
D42: Total M1-2 | E42: =SUM(E34:E41) -> 1092 | I42: ,Total T1-2
...

Sheet TT
A1: Monday, 17 August 2026 | I1: =A1 -> Monday, 17 August 2026
A2: Session, 1 (8:30 AM - 10:30 AM) | I2: =A2 -> Session, 1 (8:30 AM - 10:30 AM)
A3: CODE | B3: COURSE NAME | C3: EXAMINER | D3: CLASS | E3: # STDS | F3: ROOM NO. | G3: TO PRT | I3: CODE ,COURSE NAME ,# STDS
A4: CHE 258 | B4: {=IFERROR(VLOOKUP(I4:I9,Lectures_1!A2:F534,2,FALSE()),0)} -> DRAWING FOR ENGINEERS | C4: {=IFERROR(VLOOKUP(I4:I9,Lectures_1!A2:F534,3,FALSE()),0)} -> Darkwah Lawrence | D4: ED2-CHE | E4: {=IFERROR(VLOOKUP(I4:I9,Lectures_1!A2:F534,4,FALSE()),0)} -> 160 | F4: VSLA/303/RMA/RMB/206/304 | G4: =E4*1.1 -> 176 | H4: 45/30/22/22/22/20 | I4: =CONCATENATE(A4,",",D4) -> CHE 258,ED2-CHE
A5: CHE 258 | B5: DRAWING FOR ENGINEERS | C5: Darkwah Lawrence | D5: ED2-PCE | E5: 65 | F5: NEB-FF2/NEB-FF1 | G5: =E5*1.1 -> 71.5 | H5: 25/40 | I5: =CONCATENATE(A5,",",D5) -> CHE 258,ED2-PCE
A6: COE 354 | B6: OPERATING SYSTEMS | C6: Kommey Benjamin | D6: ED3-COE | E6: 265 | F6: PB001/PB014/PB020/PB201/PB214/PB008/PB208/PB212 | G6: =E6*1.1 -> 291.5 | H6: 36/36/36/36/36/30/30/22 | I6: =CONCATENATE(A6,",",D6) -> COE 354,ED3-COE
A7: EE 156 | B7: ELECTRICAL ENG. DRAWING | C7: Kwegyir Daniel | D7: ED1-COE | E7: 262 | F7: BYOD1/BYOD2 | G7: =E7*1.1 -> 288.2 | H7: 131/131 | I7: =CONCATENATE(A7,",",D7) -> EE 156,ED1-COE
A8: AERO 368 | B8: PROPULSION | C8: Bofah Kwasi Kete | D8: ED3-AERO | E8: 76 | F8: NAF1/A110 | G8: =E8*1.1 -> 83.6 | H8: 46/30 | I8: =CONCATENATE(A8,",",D8) -> AERO 368,ED3-AERO
A9: EE 272 | B9: DIGITAL SYSTEMS | C9: Opoku Daniel | D9: ED2-EE | E9: 340 | F9: PB001/PB014/PB020/PB201/PB214/PB008/PB208/PB212/NEB-FF1/NEB-FF2 | G9: =E9*1.1 -> 374 | H9: 38/38/38/38/38/28/28/25/45/25 | I9: =CONCATENATE(A9,",",D9) -> EE 272,ED2-EE
D10: Total M1-1 | E10: =SUM(E4:E9) -> 1168 | I10: ,Total T1-1
A12: Monday, 17 August 2026 | I12: =A12 -> Monday, 17 August 2026
A13: Session, 2 (12:00 PM - 2:00 PM) | I13: =A13 -> Session, 2 (12:00 PM - 2:00 PM)
A14: CODE | B14: COURSE NAME | C14: EXAMINER | D14: CLASS | E14: # STDS | F14: ROOM NO. | G14: TO PRT | I14: CODE ,CLASS
A15: ME 274 | B15: {=IFERROR(VLOOKUP(I15:I28,Lectures_1!A2:F534,2,FALSE()),0)} -> MACHINE DESIGN PROJECT | C15: {=IFERROR(VLOOKUP(I15:I28,Lectures_1!A2:F534,3,FALSE()),0)} -> Andoh Prince Yaw | D15: ED2-ME | E15: {=IFERROR(VLOOKUP(I15:I28,Lectures_1!A2:F534,4,FALSE()),0)} -> 240 | F15: Computer Based | G15: =E15*1.1 -> 264 | I15: =CONCATENATE(A15,",",D15) -> ME 274,ED2-ME
A16: AERO 274 | B16: AEROSPACE DESIGN PROJECT II | C16: Andoh Prince Yaw | D16: ED2-AERO | E16: 75 | G16: =E16*1.1 -> 82.5 | I16: =CONCATENATE(A16,",",D16) -> AERO 274,ED2-AERO
A17: IE 274 | B17: SECOND YEAR DESIGN PROJECT | C17: Andoh Prince Yaw | D17: ED2-IND | E17: 80 | G17: =E17*1.1 -> 88 | I17: =CONCATENATE(A17,",",D17) -> IE 274,ED2-IND
A18: AME 274 | B18: AUTOMOTIVE DESIGN PROJECT | C18: Andoh Prince Yaw | D18: ED2-AUTO | E18: 82 | G18: =E18*1.1 -> 90.2 | I18: =CONCATENATE(A18,",",D18) -> AME 274,ED2-AUTO
A19: MME 274 | B19: MARINE ENGINEERING DESIGN PROJECT II | C19: Andoh Prince Yaw | D19: ED2-MARI | E19: 37 | G19: =E19*1.1 -> 40.7 | I19: =CONCATENATE(A19,",",D19) -> MME 274,ED2-MARI
A20: PCE 450 | B20: PETROLEUM REFINING ENGINEERING | C20: Kwao-Boateng Emmanuela | D20: ED4-PCE | E20: 55 | F20: VSLA/303 | G20: =E20*1.1 -> 60.5 | H20: 35/20 | I20: =CONCATENATE(A20,",",D20) -> PCE 450,ED4-PCE
A21: PCE 464 | B21: REFINING PROCESSES TECHNOLOGY | C21: Kwao-Boateng Emmanuela | D21: ED4-CHE | E21: 50 | F21: NEB-FF1 | G21: =E21*1.1 -> 55 | H21: 50 | I21: =CONCATENATE(A21,",",D21) -> PCE 464,ED4-CHE
A22: ME 296 | B22: MECHANICAL ENGINEERING LAB. II | C22: Boahen Samuel | D22: ED2-AE | E22: 155 | F22: VSLA/303/RMA/RMB/206/304 | G22: =E22*1.1 -> 170.5 | H22: 40/30/22/22/22/20 | I22: =CONCATENATE(A22,",",D22) -> ME 296,ED2-AE
A23: CHE 362 | B23: SILICATE TECHNOLOGY II | C23: Momade Zsuzsanna Gál | D23: ED3-CHE | E23: 15 | F23: RMA | G23: =E23*1.1 -> 16.5 | H23: 15 | I23: =CONCATENATE(A23,",",D23) -> CHE 362,ED3-CHE
A24: EE 152 | B24: BASIC ELECTRONICS | C24: Kwegyir Daniel | D24: ED1-GEOM | E24: 103 | F24: BYOD2 | G24: =E24*1.1 -> 113.3 | H24: 103 | I24: =CONCATENATE(A24,",",D24) -> EE 152,ED1-GEOM
A25: EE 152 | B25: BASIC ELECTRONICS | C25: Kwegyir Daniel | D25: ED1-GEOL | E25: 125 | F25: BYOD1 | G25: =E25*1.1 -> 137.5 | H25: 125 | I25: =CONCATENATE(A25,",",D25) -> EE 152,ED1-GEOL
A26: CE 154 | B26: PROPERTIES OF CIVIL ENGINEERING MATERIAL | C26: Kankam Charles Kwame | D26: ED1-CE | E26: 245 | F26: PB001/PB014/PB020/PB201/PB214/PB008/PB208/PB212 | G26: =E26*1.1 -> 269.5 | H26: 35/35/35/35/35/25/25/20 | I26: =CONCATENATE(A26,",",D26) -> CE 154,ED1-CE
A27: CE 256 | B27: FLUID MECHANICS | C27: Anornu Geophrey Kwame | D27: ED2-GEOL | E27: 150 | F27: NAF1/A110/EA/VCR/NEB-FF1 | G27: =E27*1.1 -> 165 | H27: 40/30/30/25/25 | I27: =CONCATENATE(A27,",",D27) -> CE 256,ED2-GEOL
A28: CE 256 | B28: FLUID MECHANICS | C28: Anornu Geophrey Kwame | D28: ED2-CE | E28: 250 | F28: PB001/PB014/PB020/PB201/PB214/PB008/PB208/PB212 | G28: =E28*1.1 -> 275 | H28: 36/36/36/36/36/25/25/20 | I28: =CONCATENATE(A28,",",D28) -> CE 256,ED2-CE
D29: Total M1-2 | E29: =SUM(E20:E28) -> 1148 | I29: ,Total T1-2
A31: Monday, 17 August 2026 | I31: =A31 -> Monday, 17 August 2026
A32: Session, 3 (3:00 PM - 5:00 PM) | I32: =A32 -> Session, 3 (3:00 PM - 5:00 PM)
A33: CODE | B33: COURSE NAME | C33: EXAMINER | D33: CLASS | E33: # STDS | F33: ROOM NO. | G33: TO PRT | I33: CODE ,CLASS
A34: ME 374 | B34: {=IFERROR(VLOOKUP(I34:I41,Lectures_1!A2:F534,2,FALSE()),0)} -> MACHINE ELEMENTS DESIGN II | C34: {=IFERROR(VLOOKUP(I34:I41,Lectures_1!A2:F534,3,FALSE()),0)} -> Andoh Prince Yaw | D34: ED3-ME | E34: {=IFERROR(VLOOKUP(I34:I41,Lectures_1!A2:F534,4,FALSE()),0)} -> 222 | F34: COMPUTER BASED | G34: =E34*1.1 -> 244.2 | I34: =CONCATENATE(A34,",",D34) -> ME 374,ED3-ME
A35: ME 464 | B35: INSTRUMENTATION | C35: Adam Faisal Wahib | D35: ED4-ME | E35: 135 | F35: VSLA/303/206/RMA/RMB | G35: =E35*1.1 -> 148.5 | H35: 40/30/22/22/21 | I35: =CONCATENATE(A35,",",D35) -> ME 464,ED4-ME
A36: CE 376 | B36: QUANTITIES AND COST ESTIMATION IN CIVIL ENGINEERING | C36: Osei Jack Banahene | D36: ED3-CE | E36: 230 | F36: NEB-FF1/NEB-FF2/NEB-SF/NEB-TF | G36: =E36*1.1 -> 253 | H36: 50/30/75/75 | I36: =CONCATENATE(A36,",",D36) -> CE 376,ED3-CE
A37: EE 362 | B37: SUBSTATIONS AND TRANSMISSION LINE DESIGN | C37: Antoh Emmanuel Kwaku | D37: ED3-EE | E37: 240 | F37: PB001/PB014/PB020/PB201/PB214/PB008/PB208 | G37: =E37*1.1 -> 264 | H37: 37/37/37/37/37/28/28 | I37: =CONCATENATE(A37,",",D37) -> EE 362,ED3-EE
A38: AME 386 | B38: MANUAL POWER TRAIN | C38: Abu Frimpong Solomon | D38: ED3-AUTO | E38: 40 | F38: PB001/PB014 | G38: =E38*1.1 -> 44 | H38: 20/20 | I38: =CONCATENATE(A38,",",D38) -> AME 386,ED3-AUTO
A39: MME 482 | B39: NAVAL ARCHITECTURE II | C39: Kudzedzi Emmanuel Yaw Mawuko | D39: ED4-MARI | E39: 23 | F39: PB020 | G39: =E39*1.1 -> 25.3 | H39: 23 | I39: =CONCATENATE(A39,",",D39) -> MME 482,ED4-MARI
A40: PE 360 | B40: WELL TESTING | C40: Adenutsi Caspar Daniel | D40: ED3-PE | E40: 80 | F40: NEB-TF/NEB-SF | G40: =E40*1.1 -> 88 | H40: 40/40 | I40: =CONCATENATE(A40,",",D40) -> PE 360,ED3-PE
A41: GE 372 | B41: ANALYSIS OF ERRORS | C41: Collins Fosu | D41: ED3-GEOM | E41: 122 | F41: NAF1/A110/EA/VCR | G41: =E41*1.1 -> 134.2 | H41: 40/30/30/22 | I41: =CONCATENATE(A41,",",D41) -> GE 372,ED3-GEOM
D42: Total M1-2 | E42: =SUM(E34:E41) -> 1092 | I42: ,Total T1-2
...

Sheet TALLY
B1: M1 | E1: T1 | H1: W1 | K1: H1 | N1: F1 | Q1: M2 | T1: T2 | W1: W2 | Z1: H2 | AC1: F2 | AF1: M3 | AI1: T3 | AL1: W3 | AO1: H3 | AR1: F3
B2: S1 | C2: S2 | D2: S3 | E2: S1 | F2: S2 | G2: S3 | H2: S1 | I2: S2 | J2: S3 | K2: S1 | L2: S2 | M2: S3 | N2: S1 | O2: S2 | P2: S3 | Q2: S1 | R2: S2 | S2: S3 | T2: S1 | U2: S2 | V2: S3 | W2: S1 | X2: S2 | Y2: S3 | Z2: S1 | AA2: S2 | AB2: S3 | AC2: S1 | AD2: S2 | AE2: S3 | AF2: S1 | AG2: S2 | AH2: S3 | AI2: S1 | AJ2: S2 | AK2: S3 | AL2: S1 | AM2: S2 | AN2: S3 | AO2: S1 | AP2: S2 | AQ2: S3 | AR2: S1 | AS2: S2 | AT2: S3 | AV2: M1 | AW2: T1 | AX2: W1 | AY2: H1 | AZ2: F1 | BA2: M2 | BB2: T2 | BC2: W2 | BD2: H2 | BE2: F2 | BF2: M3 | BG2: T3 | BH2: W3 | BI2: H3 | BJ2: F3
A3: ED1-AE | B3: =COUNTIF(TT!$D$4:$D$9,TALLY!A3) -> 0 | C3: =COUNTIF(TT!$D$15:$D$28,TALLY!A3) -> 0 | D3: =COUNTIF(TT!$D$34:$D$41,TALLY!A3) -> 0 | E3: =COUNTIF(TT!$D$47:$D$60,TALLY!A3) -> 0 | F3: =COUNTIF(TT!$D$66:$D$79,TALLY!A3) -> 0 | G3: =COUNTIF(TT!$D$84:$D$93,TALLY!A3) -> 0 | H3: =COUNTIF(TT!$D$98:$D$106,TALLY!A3) -> 0 | I3: =COUNTIF(TT!$D$111:$D$121,TALLY!A3) -> 1 | J3: =COUNTIF(TT!$D$126:$D$134,TALLY!A3) -> 0 | K3: =COUNTIF(TT!$D$139:$D$151,TALLY!A3) -> 0 | L3: =COUNTIF(TT!$D$156:$D$164,TALLY!A3) -> 0 | M3: =COUNTIF(TT!$D$169:$D$180,TALLY!A3) -> 0 | N3: =COUNTIF(TT!$D$185:$D$197,TALLY!A3) -> 1 | O3: =COUNTIF(TT!$D$202:$D$208,TALLY!A3) -> 0 | P3: =COUNTIF(TT!$D$213:$D$220,TALLY!A3) -> 0 | Q3: =COUNTIF(TT!$D$225:$D$239,TALLY!A3) -> 0 | R3: =COUNTIF(TT!$D$244:$D$254,TALLY!A3) -> 0 | S3: =COUNTIF(TT!$D$259:$D$268,TALLY!A3) -> 0 | T3: =COUNTIF(TT!$D$271:$D$282,TALLY!A3) -> 0 | U3: =COUNTIF(TT!$D$287:$D$298,TALLY!A3) -> 1 | V3: =COUNTIF(TT!$D$303:$D$311,TALLY!A3) -> 0 | W3: =COUNTIF(TT!$D$316:$D$337,TALLY!A3) -> 0 | X3: =COUNTIF(TT!$D$342:$D$350,TALLY!A3) -> 1 | Y3: =COUNTIF(TT!$D$357:$D$365,TALLY!A3) -> 0 | Z3: =COUNTIF(TT!$D$370:$D$377,TALLY!A3) -> 0 | AA3: =COUNTIF(TT!$D$382:$D$393,TALLY!A3) -> 0 | AB3: =COUNTIF(TT!$D$398:$D$408,TALLY!A3) -> 0 | AC3: =COUNTIF(TT!$D$413:$D$425,TALLY!A3) -> 1 | AD3: =COUNTIF(TT!$D$430:$D$433,TALLY!A3) -> 0 | AE3: =COUNTIF(TT!$D$454:$D$466,TALLY!A3) -> 0 | AF3: =COUNTIF(TT!$D$471:$D$480,TALLY!A3) -> 1 | AG3: =COUNTIF(TT!$D$487:$D$496,TALLY!A3) -> 0 | AH3: =COUNTIF(TT!$D$501:$D$517,TALLY!A3) -> 0 | AI3: =COUNTIF(TT!$D$522:$D$533,TALLY!A3) -> 0 | AJ3: =COUNTIF(TT!$D$538:$D$550,TALLY!A3) -> 0 | AK3: =COUNTIF(TT!$D$555:$D$569,TALLY!A3) -> 0 | AL3: =COUNTIF(TT!$D$574:$D$582,TALLY!A3) -> 1 | AM3: =COUNTIF(TT!$D$587:$D$593,TALLY!A3) -> 0 | AN3: =COUNTIF(TT!$D$598:$D$606,TALLY!A3) -> 0 | AO3: =COUNTIF(TT!$D$611:$D$620,TALLY!A3) -> 0 | AP3: =COUNTIF(TT!$D$627:$D$639,TALLY!A3) -> 0 | AQ3: =COUNTIF(TT!$D$645:$D$657,TALLY!A3) -> 0 | AR3: =COUNTIF(TT!$D$663:$D$671,TALLY!A3) -> 1 | AS3: =COUNTIF(TT!$D$677:$D$685,TALLY!A3) -> 0 | AT3: =COUNTIF(TT!$D$689:$D$698,TALLY!A3) -> 0 | AU3: ED1-AE | AV3: =SUM($B3:$D3) -> 0 | AW3: =SUM($E3:$G3) -> 0 | AX3: =SUM($H3:$J3) -> 1 | AY3: =SUM($K3:$M3) -> 0 | AZ3: =SUM($N3:$P3) -> 1 | BA3: =SUM($Q3:$S3) -> 0 | BB3: =SUM($T3:$V3) -> 1 | BC3: =SUM($W3:$Y3) -> 1 | BD3: =SUM($Z3:$AB3) -> 0 | BE3: =SUM($AC3:$AE3) -> 1 | BF3: =SUM($AF3:$AH3) -> 1 | BG3: =SUM($AI3:$AK3) -> 0 | BH3: =SUM($AL3:$AN3) -> 1 | BI3: =SUM($AO3:$AQ3) -> 0 | BJ3: =SUM($AR3:$AT3) -> 1 | BK3: =SUM(AV3:BJ3) -> 8
A4: ED1-AERO | B4: =COUNTIF(TT!$D$4:$D$9,TALLY!A4) -> 0 | C4: =COUNTIF(TT!$D$15:$D$28,TALLY!A4) -> 0 | D4: =COUNTIF(TT!$D$34:$D$41,TALLY!A4) -> 0 | E4: =COUNTIF(TT!$D$47:$D$60,TALLY!A4) -> 0 | F4: =COUNTIF(TT!$D$66:$D$79,TALLY!A4) -> 0 | G4: =COUNTIF(TT!$D$84:$D$93,TALLY!A4) -> 0 | H4: =COUNTIF(TT!$D$98:$D$106,TALLY!A4) -> 0 | I4: =COUNTIF(TT!$D$111:$D$121,TALLY!A4) -> 0 | J4: =COUNTIF(TT!$D$126:$D$134,TALLY!A4) -> 0 | K4: =COUNTIF(TT!$D$139:$D$151,TALLY!A4) -> 1 | L4: =COUNTIF(TT!$D$156:$D$164,TALLY!A4) -> 0 | M4: =COUNTIF(TT!$D$169:$D$180,TALLY!A4) -> 0 | N4: =COUNTIF(TT!$D$185:$D$197,TALLY!A4) -> 0 | O4: =COUNTIF(TT!$D$202:$D$208,TALLY!A4) -> 0 | P4: =COUNTIF(TT!$D$213:$D$220,TALLY!A4) -> 0 | Q4: =COUNTIF(TT!$D$225:$D$239,TALLY!A4) -> 0 | R4: =COUNTIF(TT!$D$244:$D$254,TALLY!A4) -> 0 | S4: =COUNTIF(TT!$D$259:$D$268,TALLY!A4) -> 1 | T4: =COUNTIF(TT!$D$271:$D$282,TALLY!A4) -> 0 | U4: =COUNTIF(TT!$D$287:$D$298,TALLY!A4) -> 1 | V4: =COUNTIF(TT!$D$303:$D$311,TALLY!A4) -> 0 | W4: =COUNTIF(TT!$D$316:$D$337,TALLY!A4) -> 0 | X4: =COUNTIF(TT!$D$342:$D$350,TALLY!A4) -> 0 | Y4: =COUNTIF(TT!$D$357:$D$365,TALLY!A4) -> 0 | Z4: =COUNTIF(TT!$D$370:$D$377,TALLY!A4) -> 0 | AA4: =COUNTIF(TT!$D$382:$D$393,TALLY!A4) -> 0 | AB4: =COUNTIF(TT!$D$398:$D$408,TALLY!A4) -> 0 | AC4: =COUNTIF(TT!$D$413:$D$425,TALLY!A4) -> 1 | AD4: =COUNTIF(TT!$D$430:$D$433,TALLY!A4) -> 0 | AE4: =COUNTIF(TT!$D$454:$D$466,TALLY!A4) -> 0 | AF4: =COUNTIF(TT!$D$471:$D$480,TALLY!A4) -> 0 | AG4: =COUNTIF(TT!$D$487:$D$496,TALLY!A4) -> 0 | AH4: =COUNTIF(TT!$D$501:$D$517,TALLY!A4) -> 0 | AI4: =COUNTIF(TT!$D$522:$D$533,TALLY!A4) -> 0 | AJ4: =COUNTIF(TT!$D$538:$D$550,TALLY!A4) -> 1 | AK4: =COUNTIF(TT!$D$555:$D$569,TALLY!A4) -> 0 | AL4: =COUNTIF(TT!$D$574:$D$582,TALLY!A4) -> 0 | AM4: =COUNTIF(TT!$D$587:$D$593,TALLY!A4) -> 0 | AN4: =COUNTIF(TT!$D$598:$D$606,TALLY!A4) -> 0 | AO4: =COUNTIF(TT!$D$611:$D$620,TALLY!A4) -> 1 | AP4: =COUNTIF(TT!$D$627:$D$639,TALLY!A4) -> 0 | AQ4: =COUNTIF(TT!$D$645:$D$657,TALLY!A4) -> 0 | AR4: =COUNTIF(TT!$D$663:$D$671,TALLY!A4) -> 1 | AS4: =COUNTIF(TT!$D$677:$D$685,TALLY!A4) -> 0 | AT4: =COUNTIF(TT!$D$689:$D$698,TALLY!A4) -> 0 | AU4: ED1-AERO | AV4: =SUM($B4:$D4) -> 0 | AW4: =SUM($E4:$G4) -> 0 | AX4: =SUM($H4:$J4) -> 0 | AY4: =SUM($K4:$M4) -> 1 | AZ4: =SUM($N4:$P4) -> 0 | BA4: =SUM($Q4:$S4) -> 1 | BB4: =SUM($T4:$V4) -> 1 | BC4: =SUM($W4:$Y4) -> 0 | BD4: 0 | BE4: =SUM($AC4:$AE4) -> 1 | BF4: =SUM($AF4:$AH4) -> 0 | BG4: =SUM($AI4:$AK4) -> 1 | BH4: =SUM($AL4:$AN4) -> 0 | BI4: =SUM($AO4:$AQ4) -> 1 | BJ4: =SUM($AR4:$AT4) -> 1 | BK4: =SUM(AV4:BJ4) -> 7
A5: ED1-AUTO | B5: =COUNTIF(TT!$D$4:$D$9,TALLY!A5) -> 0 | C5: =COUNTIF(TT!$D$15:$D$28,TALLY!A5) -> 0 | D5: =COUNTIF(TT!$D$34:$D$41,TALLY!A5) -> 0 | E5: =COUNTIF(TT!$D$47:$D$60,TALLY!A5) -> 0 | F5: =COUNTIF(TT!$D$66:$D$79,TALLY!A5) -> 0 | G5: =COUNTIF(TT!$D$84:$D$93,TALLY!A5) -> 0 | H5: =COUNTIF(TT!$D$98:$D$106,TALLY!A5) -> 0 | I5: =COUNTIF(TT!$D$111:$D$121,TALLY!A5) -> 1 | J5: =COUNTIF(TT!$D$126:$D$134,TALLY!A5) -> 0 | K5: =COUNTIF(TT!$D$139:$D$151,TALLY!A5) -> 0 | L5: =COUNTIF(TT!$D$156:$D$164,TALLY!A5) -> 0 | M5: =COUNTIF(TT!$D$169:$D$180,TALLY!A5) -> 0 | N5: =COUNTIF(TT!$D$185:$D$197,TALLY!A5) -> 0 | O5: =COUNTIF(TT!$D$202:$D$208,TALLY!A5) -> 0 | P5: =COUNTIF(TT!$D$213:$D$220,TALLY!A5) -> 0 | Q5: =COUNTIF(TT!$D$225:$D$239,TALLY!A5) -> 0 | R5: =COUNTIF(TT!$D$244:$D$254,TALLY!A5) -> 0 | S5: =COUNTIF(TT!$D$259:$D$268,TALLY!A5) -> 0 | T5: =COUNTIF(TT!$D$271:$D$282,TALLY!A5) -> 0 | U5: =COUNTIF(TT!$D$287:$D$298,TALLY!A5) -> 1 | V5: =COUNTIF(TT!$D$303:$D$311,TALLY!A5) -> 0 | W5: =COUNTIF(TT!$D$316:$D$337,TALLY!A5) -> 0 | X5: =COUNTIF(TT!$D$342:$D$350,TALLY!A5) -> 0 | Y5: =COUNTIF(TT!$D$357:$D$365,TALLY!A5) -> 0 | Z5: =COUNTIF(TT!$D$370:$D$377,TALLY!A5) -> 0 | AA5: =COUNTIF(TT!$D$382:$D$393,TALLY!A5) -> 0 | AB5: =COUNTIF(TT!$D$398:$D$408,TALLY!A5) -> 0 | AC5: =COUNTIF(TT!$D$413:$D$425,TALLY!A5) -> 0 | AD5: =COUNTIF(TT!$D$430:$D$433,TALLY!A5) -> 1 | AE5: =COUNTIF(TT!$D$454:$D$466,TALLY!A5) -> 0 | AF5: =COUNTIF(TT!$D$471:$D$480,TALLY!A5) -> 1 | AG5: =COUNTIF(TT!$D$487:$D$496,TALLY!A5) -> 0 | AH5: =COUNTIF(TT!$D$501:$D$517,TALLY!A5) -> 0 | AI5: =COUNTIF(TT!$D$522:$D$533,TALLY!A5) -> 1 | AJ5: =COUNTIF(TT!$D$538:$D$550,TALLY!A5) -> 0 | AK5: =COUNTIF(TT!$D$555:$D$569,TALLY!A5) -> 0 | AL5: =COUNTIF(TT!$D$574:$D$582,TALLY!A5) -> 0 | AM5: =COUNTIF(TT!$D$587:$D$593,TALLY!A5) -> 0 | AN5: =COUNTIF(TT!$D$598:$D$606,TALLY!A5) -> 0 | AO5: =COUNTIF(TT!$D$611:$D$620,TALLY!A5) -> 1 | AP5: =COUNTIF(TT!$D$627:$D$639,TALLY!A5) -> 0 | AQ5: =COUNTIF(TT!$D$645:$D$657,TALLY!A5) -> 0 | AR5: =COUNTIF(TT!$D$663:$D$671,TALLY!A5) -> 0 | AS5: =COUNTIF(TT!$D$677:$D$685,TALLY!A5) -> 1 | AT5: =COUNTIF(TT!$D$689:$D$698,TALLY!A5) -> 0 | AU5: ED1-AUTO | AV5: =SUM($B5:$D5) -> 0 | AW5: =SUM($E5:$G5) -> 0 | AX5: =SUM($H5:$J5) -> 1 | AY5: =SUM($K5:$M5) -> 0 | AZ5: =SUM($N5:$P5) -> 0 | BA5: =SUM($Q5:$S5) -> 0 | BB5: =SUM($T5:$V5) -> 1 | BC5: =SUM($W5:$Y5) -> 0 | BD5: =SUM($Z5:$AB5) -> 0 | BE5: =SUM($AC5:$AE5) -> 1 | BF5: =SUM($AF5:$AH5) -> 1 | BG5: =SUM($AI5:$AK5) -> 1 | BH5: =SUM($AL5:$AN5) -> 0 | BI5: =SUM($AO5:$AQ5) -> 1 | BJ5: =SUM($AR5:$AT5) -> 1 | BK5: =SUM(AV5:BJ5) -> 7
A6: ED1-BME | B6: =COUNTIF(TT!$D$4:$D$9,TALLY!A6) -> 0 | C6: =COUNTIF(TT!$D$15:$D$28,TALLY!A6) -> 0 | D6: =COUNTIF(TT!$D$34:$D$41,TALLY!A6) -> 0 | E6: =COUNTIF(TT!$D$47:$D$60,TALLY!A6) -> 0 | F6: =COUNTIF(TT!$D$66:$D$79,TALLY!A6) -> 0 | G6: =COUNTIF(TT!$D$84:$D$93,TALLY!A6) -> 1 | H6: =COUNTIF(TT!$D$98:$D$106,TALLY!A6) -> 0 | I6: =COUNTIF(TT!$D$111:$D$121,TALLY!A6) -> 0 | J6: =COUNTIF(TT!$D$126:$D$134,TALLY!A6) -> 0 | K6: =COUNTIF(TT!$D$139:$D$151,TALLY!A6) -> 0 | L6: =COUNTIF(TT!$D$156:$D$164,TALLY!A6) -> 1 | M6: =COUNTIF(TT!$D$169:$D$180,TALLY!A6) -> 0 | N6: =COUNTIF(TT!$D$185:$D$197,TALLY!A6) -> 0 | O6: =COUNTIF(TT!$D$202:$D$208,TALLY!A6) -> 0 | P6: =COUNTIF(TT!$D$213:$D$220,TALLY!A6) -> 0 | Q6: =COUNTIF(TT!$D$225:$D$239,TALLY!A6) -> 0 | R6: =COUNTIF(TT!$D$244:$D$254,TALLY!A6) -> 1 | S6: =COUNTIF(TT!$D$259:$D$268,TALLY!A6) -> 0 | T6: =COUNTIF(TT!$D$271:$D$282,TALLY!A6) -> 0 | U6: =COUNTIF(TT!$D$287:$D$298,TALLY!A6) -> 0 | V6: =COUNTIF(TT!$D$303:$D$311,TALLY!A6) -> 0 | W6: =COUNTIF(TT!$D$316:$D$337,TALLY!A6) -> 0 | X6: =COUNTIF(TT!$D$342:$D$350,TALLY!A6) -> 1 | Y6: =COUNTIF(TT!$D$357:$D$365,TALLY!A6) -> 0 | Z6: =COUNTIF(TT!$D$370:$D$377,TALLY!A6) -> 0 | AA6: =COUNTIF(TT!$D$382:$D$393,TALLY!A6) -> 0 | AB6: =COUNTIF(TT!$D$398:$D$408,TALLY!A6) -> 0 | AC6: =COUNTIF(TT!$D$413:$D$425,TALLY!A6) -> 1 | AD6: =COUNTIF(TT!$D$430:$D$433,TALLY!A6) -> 0 | AE6: =COUNTIF(TT!$D$454:$D$466,TALLY!A6) -> 0 | AF6: =COUNTIF(TT!$D$471:$D$480,TALLY!A6) -> 0 | AG6: =COUNTIF(TT!$D$487:$D$496,TALLY!A6) -> 0 | AH6: =COUNTIF(TT!$D$501:$D$517,TALLY!A6) -> 0 | AI6: =COUNTIF(TT!$D$522:$D$533,TALLY!A6) -> 1 | AJ6: =COUNTIF(TT!$D$538:$D$550,TALLY!A6) -> 0 | AK6: =COUNTIF(TT!$D$555:$D$569,TALLY!A6) -> 0 | AL6: =COUNTIF(TT!$D$574:$D$582,TALLY!A6) -> 0 | AM6: =COUNTIF(TT!$D$587:$D$593,TALLY!A6) -> 0 | AN6: =COUNTIF(TT!$D$598:$D$606,TALLY!A6) -> 0 | AO6: =COUNTIF(TT!$D$611:$D$620,TALLY!A6) -> 0 | AP6: =COUNTIF(TT!$D$627:$D$639,TALLY!A6) -> 0 | AQ6: =COUNTIF(TT!$D$645:$D$657,TALLY!A6) -> 0 | AR6: =COUNTIF(TT!$D$663:$D$671,TALLY!A6) -> 1 | AS6: =COUNTIF(TT!$D$677:$D$685,TALLY!A6) -> 0 | AT6: =COUNTIF(TT!$D$689:$D$698,TALLY!A6) -> 0 | AU6: ED1-BME | AV6: =SUM($B6:$D6) -> 0 | AW6: =SUM($E6:$G6) -> 1 | AX6: =SUM($H6:$J6) -> 0 | AY6: =SUM($K6:$M6) -> 1 | AZ6: =SUM($N6:$P6) -> 0 | BA6: =SUM($Q6:$S6) -> 1 | BB6: =SUM($T6:$V6) -> 0 | BC6: =SUM($W6:$Y6) -> 1 | BD6: =SUM($Z6:$AB6) -> 0 | BE6: =SUM($AC6:$AE6) -> 1 | BF6: =SUM($AF6:$AH6) -> 0 | BG6: =SUM($AI6:$AK6) -> 1 | BH6: =SUM($AL6:$AN6) -> 0 | BI6: =SUM($AO6:$AQ6) -> 0 | BJ6: =SUM($AR6:$AT6) -> 1 | BK6: =SUM(AV6:BJ6) -> 7
A7: ED1-CE | B7: =COUNTIF(TT!$D$4:$D$9,TALLY!A7) -> 0 | C7: =COUNTIF(TT!$D$15:$D$28,TALLY!A7) -> 1 | D7: =COUNTIF(TT!$D$34:$D$41,TALLY!A7) -> 0 | E7: =COUNTIF(TT!$D$47:$D$60,TALLY!A7) -> 1 | F7: =COUNTIF(TT!$D$66:$D$79,TALLY!A7) -> 0 | G7: =COUNTIF(TT!$D$84:$D$93,TALLY!A7) -> 0 | H7: =COUNTIF(TT!$D$98:$D$106,TALLY!A7) -> 0 | I7: =COUNTIF(TT!$D$111:$D$121,TALLY!A7) -> 0 | J7: =COUNTIF(TT!$D$126:$D$134,TALLY!A7) -> 0 | K7: =COUNTIF(TT!$D$139:$D$151,TALLY!A7) -> 0 | L7: =COUNTIF(TT!$D$156:$D$164,TALLY!A7) -> 1 | M7: =COUNTIF(TT!$D$169:$D$180,TALLY!A7) -> 0 | N7: =COUNTIF(TT!$D$185:$D$197,TALLY!A7) -> 0 | O7: =COUNTIF(TT!$D$202:$D$208,TALLY!A7) -> 1 | P7: =COUNTIF(TT!$D$213:$D$220,TALLY!A7) -> 0 | Q7: =COUNTIF(TT!$D$225:$D$239,TALLY!A7) -> 1 | R7: =COUNTIF(TT!$D$244:$D$254,TALLY!A7) -> 0 | S7: =COUNTIF(TT!$D$259:$D$268,TALLY!A7) -> 0 | T7: =COUNTIF(TT!$D$271:$D$282,TALLY!A7) -> 0 | U7: =COUNTIF(TT!$D$287:$D$298,TALLY!A7) -> 0 | V7: =COUNTIF(TT!$D$303:$D$311,TALLY!A7) -> 0 | W7: =COUNTIF(TT!$D$316:$D$337,TALLY!A7) -> 0 | X7: =COUNTIF(TT!$D$342:$D$350,TALLY!A7) -> 0 | Y7: =COUNTIF(TT!$D$357:$D$365,TALLY!A7) -> 0 | Z7: =COUNTIF(TT!$D$370:$D$377,TALLY!A7) -> 0 | AA7: =COUNTIF(TT!$D$382:$D$393,TALLY!A7) -> 0 | AB7: =COUNTIF(TT!$D$398:$D$408,TALLY!A7) -> 0 | AC7: =COUNTIF(TT!$D$413:$D$425,TALLY!A7) -> 1 | AD7: =COUNTIF(TT!$D$430:$D$433,TALLY!A7) -> 0 | AE7: =COUNTIF(TT!$D$454:$D$466,TALLY!A7) -> 0 | AF7: =COUNTIF(TT!$D$471:$D$480,TALLY!A7) -> 0 | AG7: =COUNTIF(TT!$D$487:$D$496,TALLY!A7) -> 0 | AH7: =COUNTIF(TT!$D$501:$D$517,TALLY!A7) -> 1 | AI7: =COUNTIF(TT!$D$522:$D$533,TALLY!A7) -> 0 | AJ7: =COUNTIF(TT!$D$538:$D$550,TALLY!A7) -> 0 | AK7: =COUNTIF(TT!$D$555:$D$569,TALLY!A7) -> 0 | AL7: =COUNTIF(TT!$D$574:$D$582,TALLY!A7) -> 1 | AM7: =COUNTIF(TT!$D$587:$D$593,TALLY!A7) -> 0 | AN7: =COUNTIF(TT!$D$598:$D$606,TALLY!A7) -> 0 | AO7: =COUNTIF(TT!$D$611:$D$620,TALLY!A7) -> 0 | AP7: =COUNTIF(TT!$D$627:$D$639,TALLY!A7) -> 0 | AQ7: =COUNTIF(TT!$D$645:$D$657,TALLY!A7) -> 0 | AR7: =COUNTIF(TT!$D$663:$D$671,TALLY!A7) -> 1 | AS7: =COUNTIF(TT!$D$677:$D$685,TALLY!A7) -> 0 | AT7: =COUNTIF(TT!$D$689:$D$698,TALLY!A7) -> 0 | AU7: ED1-CE | AV7: =SUM($B7:$D7) -> 1 | AW7: =SUM($E7:$G7) -> 1 | AX7: =SUM($H7:$J7) -> 0 | AY7: =SUM($K7:$M7) -> 1 | AZ7: =SUM($N7:$P7) -> 1 | BA7: =SUM($Q7:$S7) -> 1 | BB7: =SUM($T7:$V7) -> 0 | BC7: =SUM($W7:$Y7) -> 0 | BD7: =SUM($Z7:$AB7) -> 0 | BE7: =SUM($AC7:$AE7) -> 1 | BF7: =SUM($AF7:$AH7) -> 1 | BG7: =SUM($AI7:$AK7) -> 0 | BH7: =SUM($AL7:$AN7) -> 1 | BI7: =SUM($AO7:$AQ7) -> 0 | BJ7: =SUM($AR7:$AT7) -> 1 | BK7: =SUM(AV7:BJ7) -> 9
A8: ED1-CHE | B8: =COUNTIF(TT!$D$4:$D$9,TALLY!A8) -> 0 | C8: =COUNTIF(TT!$D$15:$D$28,TALLY!A8) -> 0 | D8: =COUNTIF(TT!$D$34:$D$41,TALLY!A8) -> 0 | E8: =COUNTIF(TT!$D$47:$D$60,TALLY!A8) -> 1 | F8: =COUNTIF(TT!$D$66:$D$79,TALLY!A8) -> 0 | G8: =COUNTIF(TT!$D$84:$D$93,TALLY!A8) -> 0 | H8: =COUNTIF(TT!$D$98:$D$106,TALLY!A8) -> 0 | I8: =COUNTIF(TT!$D$111:$D$121,TALLY!A8) -> 0 | J8: =COUNTIF(TT!$D$126:$D$134,TALLY!A8) -> 0 | K8: =COUNTIF(TT!$D$139:$D$151,TALLY!A8) -> 1 | L8: =COUNTIF(TT!$D$156:$D$164,TALLY!A8) -> 0 | M8: =COUNTIF(TT!$D$169:$D$180,TALLY!A8) -> 0 | N8: =COUNTIF(TT!$D$185:$D$197,TALLY!A8) -> 0 | O8: =COUNTIF(TT!$D$202:$D$208,TALLY!A8) -> 0 | P8: =COUNTIF(TT!$D$213:$D$220,TALLY!A8) -> 1 | Q8: =COUNTIF(TT!$D$225:$D$239,TALLY!A8) -> 0 | R8: =COUNTIF(TT!$D$244:$D$254,TALLY!A8) -> 0 | S8: =COUNTIF(TT!$D$259:$D$268,TALLY!A8) -> 0 | T8: =COUNTIF(TT!$D$271:$D$282,TALLY!A8) -> 0 | U8: =COUNTIF(TT!$D$287:$D$298,TALLY!A8) -> 0 | V8: =COUNTIF(TT!$D$303:$D$311,TALLY!A8) -> 0 | W8: =COUNTIF(TT!$D$316:$D$337,TALLY!A8) -> 1 | X8: =COUNTIF(TT!$D$342:$D$350,TALLY!A8) -> 0 | Y8: =COUNTIF(TT!$D$357:$D$365,TALLY!A8) -> 0 | Z8: =COUNTIF(TT!$D$370:$D$377,TALLY!A8) -> 0 | AA8: =COUNTIF(TT!$D$382:$D$393,TALLY!A8) -> 0 | AB8: =COUNTIF(TT!$D$398:$D$408,TALLY!A8) -> 0 | AC8: =COUNTIF(TT!$D$413:$D$425,TALLY!A8) -> 1 | AD8: =COUNTIF(TT!$D$430:$D$433,TALLY!A8) -> 0 | AE8: =COUNTIF(TT!$D$454:$D$466,TALLY!A8) -> 0 | AF8: =COUNTIF(TT!$D$471:$D$480,TALLY!A8) -> 1 | AG8: =COUNTIF(TT!$D$487:$D$496,TALLY!A8) -> 0 | AH8: =COUNTIF(TT!$D$501:$D$517,TALLY!A8) -> 0 | AI8: =COUNTIF(TT!$D$522:$D$533,TALLY!A8) -> 0 | AJ8: =COUNTIF(TT!$D$538:$D$550,TALLY!A8) -> 0 | AK8: =COUNTIF(TT!$D$555:$D$569,TALLY!A8) -> 0 | AL8: =COUNTIF(TT!$D$574:$D$582,TALLY!A8) -> 0 | AM8: =COUNTIF(TT!$D$587:$D$593,TALLY!A8) -> 0 | AN8: =COUNTIF(TT!$D$598:$D$606,TALLY!A8) -> 0 | AO8: =COUNTIF(TT!$D$611:$D$620,TALLY!A8) -> 0 | AP8: =COUNTIF(TT!$D$627:$D$639,TALLY!A8) -> 0 | AQ8: =COUNTIF(TT!$D$645:$D$657,TALLY!A8) -> 0 | AR8: =COUNTIF(TT!$D$663:$D$671,TALLY!A8) -> 0 | AS8: =COUNTIF(TT!$D$677:$D$685,TALLY!A8) -> 1 | AT8: =COUNTIF(TT!$D$689:$D$698,TALLY!A8) -> 0 | AU8: ED1-CHE | AV8: =SUM($B8:$D8) -> 0 | AW8: =SUM($E8:$G8) -> 1 | AX8: =SUM($H8:$J8) -> 0 | AY8: =SUM($K8:$M8) -> 1 | AZ8: =SUM($N8:$P8) -> 1 | BA8: =SUM($Q8:$S8) -> 0 | BB8: =SUM($T8:$V8) -> 0 | BC8: =SUM($W8:$Y8) -> 1 | BD8: =SUM($Z8:$AB8) -> 0 | BE8: =SUM($AC8:$AE8) -> 1 | BF8: =SUM($AF8:$AH8) -> 1 | BG8: =SUM($AI8:$AK8) -> 0 | BH8: =SUM($AL8:$AN8) -> 0 | BI8: =SUM($AO8:$AQ8) -> 0 | BJ8: =SUM($AR8:$AT8) -> 1 | BK8: =SUM(AV8:BJ8) -> 7
A9: ED1-COE | B9: =COUNTIF(TT!$D$4:$D$9,TALLY!A9) -> 1 | C9: =COUNTIF(TT!$D$15:$D$28,TALLY!A9) -> 0 | D9: =COUNTIF(TT!$D$34:$D$41,TALLY!A9) -> 0 | E9: =COUNTIF(TT!$D$47:$D$60,TALLY!A9) -> 0 | F9: =COUNTIF(TT!$D$66:$D$79,TALLY!A9) -> 0 | G9: =COUNTIF(TT!$D$84:$D$93,TALLY!A9) -> 0 | H9: =COUNTIF(TT!$D$98:$D$106,TALLY!A9) -> 0 | I9: =COUNTIF(TT!$D$111:$D$121,TALLY!A9) -> 0 | J9: =COUNTIF(TT!$D$126:$D$134,TALLY!A9) -> 1 | K9: =COUNTIF(TT!$D$139:$D$151,TALLY!A9) -> 0 | L9: =COUNTIF(TT!$D$156:$D$164,TALLY!A9) -> 0 | M9: =COUNTIF(TT!$D$169:$D$180,TALLY!A9) -> 0 | N9: =COUNTIF(TT!$D$185:$D$197,TALLY!A9) -> 0 | O9: =COUNTIF(TT!$D$202:$D$208,TALLY!A9) -> 0 | P9: =COUNTIF(TT!$D$213:$D$220,TALLY!A9) -> 0 | Q9: =COUNTIF(TT!$D$225:$D$239,TALLY!A9) -> 0 | R9: =COUNTIF(TT!$D$244:$D$254,TALLY!A9) -> 0 | S9: =COUNTIF(TT!$D$259:$D$268,TALLY!A9) -> 0 | T9: =COUNTIF(TT!$D$271:$D$282,TALLY!A9) -> 0 | U9: =COUNTIF(TT!$D$287:$D$298,TALLY!A9) -> 1 | V9: =COUNTIF(TT!$D$303:$D$311,TALLY!A9) -> 0 | W9: =COUNTIF(TT!$D$316:$D$337,TALLY!A9) -> 0 | X9: =COUNTIF(TT!$D$342:$D$350,TALLY!A9) -> 0 | Y9: =COUNTIF(TT!$D$357:$D$365,TALLY!A9) -> 0 | Z9: =COUNTIF(TT!$D$370:$D$377,TALLY!A9) -> 0 | AA9: =COUNTIF(TT!$D$382:$D$393,TALLY!A9) -> 0 | AB9: =COUNTIF(TT!$D$398:$D$408,TALLY!A9) -> 0 | AC9: =COUNTIF(TT!$D$413:$D$425,TALLY!A9) -> 1 | AD9: =COUNTIF(TT!$D$430:$D$433,TALLY!A9) -> 0 | AE9: =COUNTIF(TT!$D$454:$D$466,TALLY!A9) -> 0 | AF9: =COUNTIF(TT!$D$471:$D$480,TALLY!A9) -> 0 | AG9: =COUNTIF(TT!$D$487:$D$496,TALLY!A9) -> 0 | AH9: =COUNTIF(TT!$D$501:$D$517,TALLY!A9) -> 0 | AI9: =COUNTIF(TT!$D$522:$D$533,TALLY!A9) -> 0 | AJ9: =COUNTIF(TT!$D$538:$D$550,TALLY!A9) -> 0 | AK9: =COUNTIF(TT!$D$555:$D$569,TALLY!A9) -> 0 | AL9: =COUNTIF(TT!$D$574:$D$582,TALLY!A9) -> 0 | AM9: =COUNTIF(TT!$D$587:$D$593,TALLY!A9) -> 0 | AN9: =COUNTIF(TT!$D$598:$D$606,TALLY!A9) -> 1 | AO9: =COUNTIF(TT!$D$611:$D$620,TALLY!A9) -> 0 | AP9: =COUNTIF(TT!$D$627:$D$639,TALLY!A9) -> 0 | AQ9: =COUNTIF(TT!$D$645:$D$657,TALLY!A9) -> 0 | AR9: =COUNTIF(TT!$D$663:$D$671,TALLY!A9) -> 1 | AS9: =COUNTIF(TT!$D$677:$D$685,TALLY!A9) -> 0 | AT9: =COUNTIF(TT!$D$689:$D$698,TALLY!A9) -> 0 | AU9: ED1-COE | AV9: =SUM($B9:$D9) -> 1 | AW9: =SUM($E9:$G9) -> 0 | AX9: =SUM($H9:$J9) -> 1 | AY9: =SUM($K9:$M9) -> 0 | AZ9: =SUM($N9:$P9) -> 0 | BA9: =SUM($Q9:$S9) -> 0 | BB9: =SUM($T9:$V9) -> 1 | BC9: =SUM($W9:$Y9) -> 0 | BD9: =SUM($Z9:$AB9) -> 0 | BE9: =SUM($AC9:$AE9) -> 1 | BF9: =SUM($AF9:$AH9) -> 0 | BG9: =SUM($AI9:$AK9) -> 0 | BH9: =SUM($AL9:$AN9) -> 1 | BI9: =SUM($AO9:$AQ9) -> 0 | BJ9: =SUM($AR9:$AT9) -> 1 | BK9: =SUM(AV9:BJ9) -> 6
A10: ED1-EE | B10: =COUNTIF(TT!$D$4:$D$9,TALLY!A10) -> 0 | C10: =COUNTIF(TT!$D$15:$D$28,TALLY!A10) -> 0 | D10: =COUNTIF(TT!$D$34:$D$41,TALLY!A10) -> 0 | E10: =COUNTIF(TT!$D$47:$D$60,TALLY!A10) -> 0 | F10: =COUNTIF(TT!$D$66:$D$79,TALLY!A10) -> 0 | G10: =COUNTIF(TT!$D$84:$D$93,TALLY!A10) -> 1 | H10: =COUNTIF(TT!$D$98:$D$106,TALLY!A10) -> 0 | I10: =COUNTIF(TT!$D$111:$D$121,TALLY!A10) -> 0 | J10: =COUNTIF(TT!$D$126:$D$134,TALLY!A10) -> 0 | K10: =COUNTIF(TT!$D$139:$D$151,TALLY!A10) -> 1 | L10: =COUNTIF(TT!$D$156:$D$164,TALLY!A10) -> 0 | M10: =COUNTIF(TT!$D$169:$D$180,TALLY!A10) -> 0 | N10: =COUNTIF(TT!$D$185:$D$197,TALLY!A10) -> 0 | O10: =COUNTIF(TT!$D$202:$D$208,TALLY!A10) -> 0 | P10: =COUNTIF(TT!$D$213:$D$220,TALLY!A10) -> 1 | Q10: =COUNTIF(TT!$D$225:$D$239,TALLY!A10) -> 0 | R10: =COUNTIF(TT!$D$244:$D$254,TALLY!A10) -> 1 | S10: =COUNTIF(TT!$D$259:$D$268,TALLY!A10) -> 0 | T10: =COUNTIF(TT!$D$271:$D$282,TALLY!A10) -> 0 | U10: =COUNTIF(TT!$D$287:$D$298,TALLY!A10) -> 0 | V10: =COUNTIF(TT!$D$303:$D$311,TALLY!A10) -> 0 | W10: =COUNTIF(TT!$D$316:$D$337,TALLY!A10) -> 0 | X10: =COUNTIF(TT!$D$342:$D$350,TALLY!A10) -> 0 | Y10: =COUNTIF(TT!$D$357:$D$365,TALLY!A10) -> 0 | Z10: =COUNTIF(TT!$D$370:$D$377,TALLY!A10) -> 1 | AA10: =COUNTIF(TT!$D$382:$D$393,TALLY!A10) -> 0 | AB10: =COUNTIF(TT!$D$398:$D$408,TALLY!A10) -> 0 | AC10: =COUNTIF(TT!$D$413:$D$425,TALLY!A10) -> 0 | AD10: =COUNTIF(TT!$D$430:$D$433,TALLY!A10) -> 1 | AE10: =COUNTIF(TT!$D$454:$D$466,TALLY!A10) -> 0 | AF10: =COUNTIF(TT!$D$471:$D$480,TALLY!A10) -> 0 | AG10: =COUNTIF(TT!$D$487:$D$496,TALLY!A10) -> 0 | AH10: =COUNTIF(TT!$D$501:$D$517,TALLY!A10) -> 0 | AI10: =COUNTIF(TT!$D$522:$D$533,TALLY!A10) -> 1 | AJ10: =COUNTIF(TT!$D$538:$D$550,TALLY!A10) -> 0 | AK10: =COUNTIF(TT!$D$555:$D$569,TALLY!A10) -> 0 | AL10: =COUNTIF(TT!$D$574:$D$582,TALLY!A10) -> 0 | AM10: =COUNTIF(TT!$D$587:$D$593,TALLY!A10) -> 0 | AN10: =COUNTIF(TT!$D$598:$D$606,TALLY!A10) -> 0 | AO10: =COUNTIF(TT!$D$611:$D$620,TALLY!A10) -> 0 | AP10: =COUNTIF(TT!$D$627:$D$639,TALLY!A10) -> 0 | AQ10: =COUNTIF(TT!$D$645:$D$657,TALLY!A10) -> 0 | AR10: =COUNTIF(TT!$D$663:$D$671,TALLY!A10) -> 0 | AS10: =COUNTIF(TT!$D$677:$D$685,TALLY!A10) -> 1 | AT10: =COUNTIF(TT!$D$689:$D$698,TALLY!A10) -> 0 | AU10: ED1-EE | AV10: =SUM($B10:$D10) -> 0 | AW10: =SUM($E10:$G10) -> 1 | AX10: =SUM($H10:$J10) -> 0 | AY10: =SUM($K10:$M10) -> 1 | AZ10: =SUM($N10:$P10) -> 1 | BA10: =SUM($Q10:$S10) -> 1 | BB10: =SUM($T10:$V10) -> 0 | BC10: =SUM($W10:$Y10) -> 0 | BD10: =SUM($Z10:$AB10) -> 1 | BE10: =SUM($AC10:$AE10) -> 1 | BF10: =SUM($AF10:$AH10) -> 0 | BG10: =SUM($AI10:$AK10) -> 1 | BH10: =SUM($AL10:$AN10) -> 0 | BI10: =SUM($AO10:$AQ10) -> 0 | BJ10: =SUM($AR10:$AT10) -> 1 | BK10: =SUM(AV10:BJ10) -> 8
A11: ED1-GEOL | B11: =COUNTIF(TT!$D$4:$D$9,TALLY!A11) -> 0 | C11: =COUNTIF(TT!$D$15:$D$28,TALLY!A11) -> 1 | D11: =COUNTIF(TT!$D$34:$D$41,TALLY!A11) -> 0 | E11: =COUNTIF(TT!$D$47:$D$60,TALLY!A11) -> 0 | F11: =COUNTIF(TT!$D$66:$D$79,TALLY!A11) -> 0 | G11: =COUNTIF(TT!$D$84:$D$93,TALLY!A11) -> 0 | H11: =COUNTIF(TT!$D$98:$D$106,TALLY!A11) -> 0 | I11: =COUNTIF(TT!$D$111:$D$121,TALLY!A11) -> 0 | J11: =COUNTIF(TT!$D$126:$D$134,TALLY!A11) -> 0 | K11: =COUNTIF(TT!$D$139:$D$151,TALLY!A11) -> 1 | L11: =COUNTIF(TT!$D$156:$D$164,TALLY!A11) -> 0 | M11: =COUNTIF(TT!$D$169:$D$180,TALLY!A11) -> 0 | N11: =COUNTIF(TT!$D$185:$D$197,TALLY!A11) -> 0 | O11: =COUNTIF(TT!$D$202:$D$208,TALLY!A11) -> 0 | P11: =COUNTIF(TT!$D$213:$D$220,TALLY!A11) -> 0 | Q11: =COUNTIF(TT!$D$225:$D$239,TALLY!A11) -> 1 | R11: =COUNTIF(TT!$D$244:$D$254,TALLY!A11) -> 0 | S11: =COUNTIF(TT!$D$259:$D$268,TALLY!A11) -> 0 | T11: =COUNTIF(TT!$D$271:$D$282,TALLY!A11) -> 0 | U11: =COUNTIF(TT!$D$287:$D$298,TALLY!A11) -> 0 | V11: =COUNTIF(TT!$D$303:$D$311,TALLY!A11) -> 0 | W11: =COUNTIF(TT!$D$316:$D$337,TALLY!A11) -> 0 | X11: =COUNTIF(TT!$D$342:$D$350,TALLY!A11) -> 0 | Y11: =COUNTIF(TT!$D$357:$D$365,TALLY!A11) -> 0 | Z11: =COUNTIF(TT!$D$370:$D$377,TALLY!A11) -> 0 | AA11: =COUNTIF(TT!$D$382:$D$393,TALLY!A11) -> 0 | AB11: =COUNTIF(TT!$D$398:$D$408,TALLY!A11) -> 1 | AC11: =COUNTIF(TT!$D$413:$D$425,TALLY!A11) -> 0 | AD11: =COUNTIF(TT!$D$430:$D$433,TALLY!A11) -> 0 | AE11: =COUNTIF(TT!$D$454:$D$466,TALLY!A11) -> 0 | AF11: =COUNTIF(TT!$D$471:$D$480,TALLY!A11) -> 0 | AG11: =COUNTIF(TT!$D$487:$D$496,TALLY!A11) -> 0 | AH11: =COUNTIF(TT!$D$501:$D$517,TALLY!A11) -> 1 | AI11: =COUNTIF(TT!$D$522:$D$533,TALLY!A11) -> 1 | AJ11: =COUNTIF(TT!$D$538:$D$550,TALLY!A11) -> 0 | AK11: =COUNTIF(TT!$D$555:$D$569,TALLY!A11) -> 0 | AL11: =COUNTIF(TT!$D$574:$D$582,TALLY!A11) -> 1 | AM11: =COUNTIF(TT!$D$587:$D$593,TALLY!A11) -> 0 | AN11: =COUNTIF(TT!$D$598:$D$606,TALLY!A11) -> 0 | AO11: =COUNTIF(TT!$D$611:$D$620,TALLY!A11) -> 0 | AP11: =COUNTIF(TT!$D$627:$D$639,TALLY!A11) -> 0 | AQ11: =COUNTIF(TT!$D$645:$D$657,TALLY!A11) -> 1 | AR11: =COUNTIF(TT!$D$663:$D$671,TALLY!A11) -> 1 | AS11: =COUNTIF(TT!$D$677:$D$685,TALLY!A11) -> 0 | AT11: =COUNTIF(TT!$D$689:$D$698,TALLY!A11) -> 0 | AU11: ED1-GEOL | AV11: =SUM($B11:$D11) -> 1 | AW11: =SUM($E11:$G11) -> 0 | AX11: =SUM($H11:$J11) -> 0 | AY11: =SUM($K11:$M11) -> 1 | AZ11: =SUM($N11:$P11) -> 0 | BA11: =SUM($Q11:$S11) -> 1 | BB11: =SUM($T11:$V11) -> 0 | BC11: =SUM($W11:$Y11) -> 0 | BD11: =SUM($Z11:$AB11) -> 1 | BE11: =SUM($AC11:$AE11) -> 0 | BF11: =SUM($AF11:$AH11) -> 1 | BG11: =SUM($AI11:$AK11) -> 1 | BH11: =SUM($AL11:$AN11) -> 1 | BI11: =SUM($AO11:$AQ11) -> 1 | BJ11: =SUM($AR11:$AT11) -> 1 | BK11: =SUM(AV11:BJ11) -> 9
A12: ED1-GEOM | B12: =COUNTIF(TT!$D$4:$D$9,TALLY!A12) -> 0 | C12: =COUNTIF(TT!$D$15:$D$28,TALLY!A12) -> 1 | D12: =COUNTIF(TT!$D$34:$D$41,TALLY!A12) -> 0 | E12: =COUNTIF(TT!$D$47:$D$60,TALLY!A12) -> 0 | F12: =COUNTIF(TT!$D$66:$D$79,TALLY!A12) -> 0 | G12: =COUNTIF(TT!$D$84:$D$93,TALLY!A12) -> 0 | H12: =COUNTIF(TT!$D$98:$D$106,TALLY!A12) -> 0 | I12: =COUNTIF(TT!$D$111:$D$121,TALLY!A12) -> 0 | J12: =COUNTIF(TT!$D$126:$D$134,TALLY!A12) -> 0 | K12: =COUNTIF(TT!$D$139:$D$151,TALLY!A12) -> 0 | L12: =COUNTIF(TT!$D$156:$D$164,TALLY!A12) -> 1 | M12: =COUNTIF(TT!$D$169:$D$180,TALLY!A12) -> 0 | N12: =COUNTIF(TT!$D$185:$D$197,TALLY!A12) -> 0 | O12: =COUNTIF(TT!$D$202:$D$208,TALLY!A12) -> 0 | P12: =COUNTIF(TT!$D$213:$D$220,TALLY!A12) -> 0 | Q12: =COUNTIF(TT!$D$225:$D$239,TALLY!A12) -> 0 | R12: =COUNTIF(TT!$D$244:$D$254,TALLY!A12) -> 0 | S12: =COUNTIF(TT!$D$259:$D$268,TALLY!A12) -> 0 | T12: =COUNTIF(TT!$D$271:$D$282,TALLY!A12) -> 0 | U12: =COUNTIF(TT!$D$287:$D$298,TALLY!A12) -> 0 | V12: =COUNTIF(TT!$D$303:$D$311,TALLY!A12) -> 0 | W12: =COUNTIF(TT!$D$316:$D$337,TALLY!A12) -> 0 | X12: =COUNTIF(TT!$D$342:$D$350,TALLY!A12) -> 0 | Y12: =COUNTIF(TT!$D$357:$D$365,TALLY!A12) -> 0 | Z12: =COUNTIF(TT!$D$370:$D$377,TALLY!A12) -> 0 | AA12: =COUNTIF(TT!$D$382:$D$393,TALLY!A12) -> 0 | AB12: =COUNTIF(TT!$D$398:$D$408,TALLY!A12) -> 0 | AC12: =COUNTIF(TT!$D$413:$D$425,TALLY!A12) -> 0 | AD12: =COUNTIF(TT!$D$430:$D$433,TALLY!A12) -> 0 | AE12: =COUNTIF(TT!$D$454:$D$466,TALLY!A12) -> 0 | AF12: =COUNTIF(TT!$D$471:$D$480,TALLY!A12) -> 0 | AG12: =COUNTIF(TT!$D$487:$D$496,TALLY!A12) -> 0 | AH12: =COUNTIF(TT!$D$501:$D$517,TALLY!A12) -> 0 | AI12: =COUNTIF(TT!$D$522:$D$533,TALLY!A12) -> 0 | AJ12: =COUNTIF(TT!$D$538:$D$550,TALLY!A12) -> 1 | AK12: =COUNTIF(TT!$D$555:$D$569,TALLY!A12) -> 0 | AL12: =COUNTIF(TT!$D$574:$D$582,TALLY!A12) -> 0 | AM12: =COUNTIF(TT!$D$587:$D$593,TALLY!A12) -> 0 | AN12: =COUNTIF(TT!$D$598:$D$606,TALLY!A12) -> 0 | AO12: =COUNTIF(TT!$D$611:$D$620,TALLY!A12) -> 0 | AP12: =COUNTIF(TT!$D$627:$D$639,TALLY!A12) -> 0 | AQ12: =COUNTIF(TT!$D$645:$D$657,TALLY!A12) -> 1 | AR12: =COUNTIF(TT!$D$663:$D$671,TALLY!A12) -> 0 | AS12: =COUNTIF(TT!$D$677:$D$685,TALLY!A12) -> 1 | AT12: =COUNTIF(TT!$D$689:$D$698,TALLY!A12) -> 0 | AU12: ED1-GEOM | AV12: =SUM($B12:$D12) -> 1 | AW12: =SUM($E12:$G12) -> 0 | AX12: =SUM($H12:$J12) -> 0 | AY12: =SUM($K12:$M12) -> 1 | AZ12: =SUM($N12:$P12) -> 0 | BA12: =SUM($Q12:$S12) -> 0 | BB12: =SUM($T12:$V12) -> 0 | BC12: =SUM($W12:$Y12) -> 0 | BD12: =SUM($Z12:$AB12) -> 0 | BE12: =SUM($AC12:$AE12) -> 0 | BF12: =SUM($AF12:$AH12) -> 0 | BG12: =SUM($AI12:$AK12) -> 1 | BH12: =SUM($AL12:$AN12) -> 0 | BI12: =SUM($AO12:$AQ12) -> 1 | BJ12: =SUM($AR12:$AT12) -> 1 | BK12: =SUM(AV12:BJ12) -> 5
A13: ED1-IND | B13: =COUNTIF(TT!$D$4:$D$9,TALLY!A13) -> 0 | C13: =COUNTIF(TT!$D$15:$D$28,TALLY!A13) -> 0 | D13: =COUNTIF(TT!$D$34:$D$41,TALLY!A13) -> 0 | E13: =COUNTIF(TT!$D$47:$D$60,TALLY!A13) -> 0 | F13: =COUNTIF(TT!$D$66:$D$79,TALLY!A13) -> 1 | G13: =COUNTIF(TT!$D$84:$D$93,TALLY!A13) -> 0 | H13: =COUNTIF(TT!$D$98:$D$106,TALLY!A13) -> 0 | I13: =COUNTIF(TT!$D$111:$D$121,TALLY!A13) -> 1 | J13: =COUNTIF(TT!$D$126:$D$134,TALLY!A13) -> 0 | K13: =COUNTIF(TT!$D$139:$D$151,TALLY!A13) -> 0 | L13: =COUNTIF(TT!$D$156:$D$164,TALLY!A13) -> 0 | M13: =COUNTIF(TT!$D$169:$D$180,TALLY!A13) -> 0 | N13: =COUNTIF(TT!$D$185:$D$197,TALLY!A13) -> 0 | O13: =COUNTIF(TT!$D$202:$D$208,TALLY!A13) -> 0 | P13: =COUNTIF(TT!$D$213:$D$220,TALLY!A13) -> 0 | Q13: =COUNTIF(TT!$D$225:$D$239,TALLY!A13) -> 0 | R13: =COUNTIF(TT!$D$244:$D$254,TALLY!A13) -> 0 | S13: =COUNTIF(TT!$D$259:$D$268,TALLY!A13) -> 0 | T13: =COUNTIF(TT!$D$271:$D$282,TALLY!A13) -> 0 | U13: =COUNTIF(TT!$D$287:$D$298,TALLY!A13) -> 1 | V13: =COUNTIF(TT!$D$303:$D$311,TALLY!A13) -> 0 | W13: =COUNTIF(TT!$D$316:$D$337,TALLY!A13) -> 0 | X13: =COUNTIF(TT!$D$342:$D$350,TALLY!A13) -> 0 | Y13: =COUNTIF(TT!$D$357:$D$365,TALLY!A13) -> 0 | Z13: =COUNTIF(TT!$D$370:$D$377,TALLY!A13) -> 0 | AA13: =COUNTIF(TT!$D$382:$D$393,TALLY!A13) -> 0 | AB13: =COUNTIF(TT!$D$398:$D$408,TALLY!A13) -> 0 | AC13: =COUNTIF(TT!$D$413:$D$425,TALLY!A13) -> 0 | AD13: =COUNTIF(TT!$D$430:$D$433,TALLY!A13) -> 1 | AE13: =COUNTIF(TT!$D$454:$D$466,TALLY!A13) -> 0 | AF13: =COUNTIF(TT!$D$471:$D$480,TALLY!A13) -> 0 | AG13: =COUNTIF(TT!$D$487:$D$496,TALLY!A13) -> 0 | AH13: =COUNTIF(TT!$D$501:$D$517,TALLY!A13) -> 0 | AI13: =COUNTIF(TT!$D$522:$D$533,TALLY!A13) -> 0 | AJ13: =COUNTIF(TT!$D$538:$D$550,TALLY!A13) -> 1 | AK13: =COUNTIF(TT!$D$555:$D$569,TALLY!A13) -> 0 | AL13: =COUNTIF(TT!$D$574:$D$582,TALLY!A13) -> 0 | AM13: =COUNTIF(TT!$D$587:$D$593,TALLY!A13) -> 0 | AN13: =COUNTIF(TT!$D$598:$D$606,TALLY!A13) -> 0 | AO13: =COUNTIF(TT!$D$611:$D$620,TALLY!A13) -> 1 | AP13: =COUNTIF(TT!$D$627:$D$639,TALLY!A13) -> 0 | AQ13: =COUNTIF(TT!$D$645:$D$657,TALLY!A13) -> 0 | AR13: =COUNTIF(TT!$D$663:$D$671,TALLY!A13) -> 1 | AS13: =COUNTIF(TT!$D$677:$D$685,TALLY!A13) -> 0 | AT13: =COUNTIF(TT!$D$689:$D$698,TALLY!A13) -> 0 | AU13: ED1-IND | AV13: =SUM($B13:$D13) -> 0 | AW13: =SUM($E13:$G13) -> 1 | AX13: =SUM($H13:$J13) -> 1 | AY13: =SUM($K13:$M13) -> 0 | AZ13: =SUM($N13:$P13) -> 0 | BA13: =SUM($Q13:$S13) -> 0 | BB13: =SUM($T13:$V13) -> 1 | BC13: =SUM($W13:$Y13) -> 0 | BD13: =SUM($Z13:$AB13) -> 0 | BE13: =SUM($AC13:$AE13) -> 1 | BF13: =SUM($AF13:$AH13) -> 0 | BG13: =SUM($AI13:$AK13) -> 1 | BH13: =SUM($AL13:$AN13) -> 0 | BI13: =SUM($AO13:$AQ13) -> 1 | BJ13: =SUM($AR13:$AT13) -> 1 | BK13: =SUM(AV13:BJ13) -> 7
A14: ED1-MARI | B14: =COUNTIF(TT!$D$4:$D$9,TALLY!A14) -> 0 | C14: =COUNTIF(TT!$D$15:$D$28,TALLY!A14) -> 0 | D14: =COUNTIF(TT!$D$34:$D$41,TALLY!A14) -> 0 | E14: =COUNTIF(TT!$D$47:$D$60,TALLY!A14) -> 0 | F14: =COUNTIF(TT!$D$66:$D$79,TALLY!A14) -> 1 | G14: =COUNTIF(TT!$D$84:$D$93,TALLY!A14) -> 0 | H14: =COUNTIF(TT!$D$98:$D$106,TALLY!A14) -> 0 | I14: =COUNTIF(TT!$D$111:$D$121,TALLY!A14) -> 1 | J14: =COUNTIF(TT!$D$126:$D$134,TALLY!A14) -> 0 | K14: =COUNTIF(TT!$D$139:$D$151,TALLY!A14) -> 0 | L14: =COUNTIF(TT!$D$156:$D$164,TALLY!A14) -> 0 | M14: =COUNTIF(TT!$D$169:$D$180,TALLY!A14) -> 0 | N14: =COUNTIF(TT!$D$185:$D$197,TALLY!A14) -> 0 | O14: =COUNTIF(TT!$D$202:$D$208,TALLY!A14) -> 0 | P14: =COUNTIF(TT!$D$213:$D$220,TALLY!A14) -> 0 | Q14: =COUNTIF(TT!$D$225:$D$239,TALLY!A14) -> 1 | R14: =COUNTIF(TT!$D$244:$D$254,TALLY!A14) -> 0 | S14: =COUNTIF(TT!$D$259:$D$268,TALLY!A14) -> 0 | T14: =COUNTIF(TT!$D$271:$D$282,TALLY!A14) -> 0 | U14: =COUNTIF(TT!$D$287:$D$298,TALLY!A14) -> 1 | V14: =COUNTIF(TT!$D$303:$D$311,TALLY!A14) -> 0 | W14: =COUNTIF(TT!$D$316:$D$337,TALLY!A14) -> 0 | X14: =COUNTIF(TT!$D$342:$D$350,TALLY!A14) -> 0 | Y14: =COUNTIF(TT!$D$357:$D$365,TALLY!A14) -> 0 | Z14: =COUNTIF(TT!$D$370:$D$377,TALLY!A14) -> 0 | AA14: =COUNTIF(TT!$D$382:$D$393,TALLY!A14) -> 0 | AB14: =COUNTIF(TT!$D$398:$D$408,TALLY!A14) -> 0 | AC14: =COUNTIF(TT!$D$413:$D$425,TALLY!A14) -> 0 | AD14: =COUNTIF(TT!$D$430:$D$433,TALLY!A14) -> 0 | AE14: =COUNTIF(TT!$D$454:$D$466,TALLY!A14) -> 1 | AF14: =COUNTIF(TT!$D$471:$D$480,TALLY!A14) -> 0 | AG14: =COUNTIF(TT!$D$487:$D$496,TALLY!A14) -> 0 | AH14: =COUNTIF(TT!$D$501:$D$517,TALLY!A14) -> 0 | AI14: =COUNTIF(TT!$D$522:$D$533,TALLY!A14) -> 0 | AJ14: =COUNTIF(TT!$D$538:$D$550,TALLY!A14) -> 1 | AK14: =COUNTIF(TT!$D$555:$D$569,TALLY!A14) -> 0 | AL14: =COUNTIF(TT!$D$574:$D$582,TALLY!A14) -> 0 | AM14: =COUNTIF(TT!$D$587:$D$593,TALLY!A14) -> 0 | AN14: =COUNTIF(TT!$D$598:$D$606,TALLY!A14) -> 0 | AO14: =COUNTIF(TT!$D$611:$D$620,TALLY!A14) -> 1 | AP14: =COUNTIF(TT!$D$627:$D$639,TALLY!A14) -> 0 | AQ14: =COUNTIF(TT!$D$645:$D$657,TALLY!A14) -> 0 | AR14: =COUNTIF(TT!$D$663:$D$671,TALLY!A14) -> 1 | AS14: =COUNTIF(TT!$D$677:$D$685,TALLY!A14) -> 0 | AT14: =COUNTIF(TT!$D$689:$D$698,TALLY!A14) -> 0 | AU14: ED1-MARI | AV14: =SUM($B14:$D14) -> 0 | AW14: =SUM($E14:$G14) -> 1 | AX14: =SUM($H14:$J14) -> 1 | AY14: =SUM($K14:$M14) -> 0 | AZ14: =SUM($N14:$P14) -> 0 | BA14: =SUM($Q14:$S14) -> 1 | BB14: =SUM($T14:$V14) -> 1 | BC14: =SUM($W14:$Y14) -> 0 | BD14: =SUM($Z14:$AB14) -> 0 | BE14: =SUM($AC14:$AE14) -> 1 | BF14: =SUM($AF14:$AH14) -> 0 | BG14: =SUM($AI14:$AK14) -> 1 | BH14: =SUM($AL14:$AN14) -> 0 | BI14: =SUM($AO14:$AQ14) -> 1 | BJ14: =SUM($AR14:$AT14) -> 1 | BK14: =SUM(AV14:BJ14) -> 8
A15: ED1-ME | B15: =COUNTIF(TT!$D$4:$D$9,TALLY!A15) -> 0 | C15: =COUNTIF(TT!$D$15:$D$28,TALLY!A15) -> 0 | D15: =COUNTIF(TT!$D$34:$D$41,TALLY!A15) -> 0 | E15: =COUNTIF(TT!$D$47:$D$60,TALLY!A15) -> 0 | F15: =COUNTIF(TT!$D$66:$D$79,TALLY!A15) -> 0 | G15: =COUNTIF(TT!$D$84:$D$93,TALLY!A15) -> 0 | H15: =COUNTIF(TT!$D$98:$D$106,TALLY!A15) -> 0 | I15: =COUNTIF(TT!$D$111:$D$121,TALLY!A15) -> 1 | J15: =COUNTIF(TT!$D$126:$D$134,TALLY!A15) -> 0 | K15: =COUNTIF(TT!$D$139:$D$151,TALLY!A15) -> 0 | L15: =COUNTIF(TT!$D$156:$D$164,TALLY!A15) -> 0 | M15: =COUNTIF(TT!$D$169:$D$180,TALLY!A15) -> 0 | N15: =COUNTIF(TT!$D$185:$D$197,TALLY!A15) -> 0 | O15: =COUNTIF(TT!$D$202:$D$208,TALLY!A15) -> 0 | P15: =COUNTIF(TT!$D$213:$D$220,TALLY!A15) -> 1 | Q15: =COUNTIF(TT!$D$225:$D$239,TALLY!A15) -> 0 | R15: =COUNTIF(TT!$D$244:$D$254,TALLY!A15) -> 0 | S15: =COUNTIF(TT!$D$259:$D$268,TALLY!A15) -> 1 | T15: =COUNTIF(TT!$D$271:$D$282,TALLY!A15) -> 0 | U15: =COUNTIF(TT!$D$287:$D$298,TALLY!A15) -> 0 | V15: =COUNTIF(TT!$D$303:$D$311,TALLY!A15) -> 0 | W15: =COUNTIF(TT!$D$316:$D$337,TALLY!A15) -> 0 | X15: =COUNTIF(TT!$D$342:$D$350,TALLY!A15) -> 0 | Y15: =COUNTIF(TT!$D$357:$D$365,TALLY!A15) -> 0 | Z15: =COUNTIF(TT!$D$370:$D$377,TALLY!A15) -> 0 | AA15: =COUNTIF(TT!$D$382:$D$393,TALLY!A15) -> 0 | AB15: =COUNTIF(TT!$D$398:$D$408,TALLY!A15) -> 0 | AC15: =COUNTIF(TT!$D$413:$D$425,TALLY!A15) -> 0 | AD15: =COUNTIF(TT!$D$430:$D$433,TALLY!A15) -> 0 | AE15: =COUNTIF(TT!$D$454:$D$466,TALLY!A15) -> 1 | AF15: =COUNTIF(TT!$D$471:$D$480,TALLY!A15) -> 0 | AG15: =COUNTIF(TT!$D$487:$D$496,TALLY!A15) -> 0 | AH15: =COUNTIF(TT!$D$501:$D$517,TALLY!A15) -> 0 | AI15: =COUNTIF(TT!$D$522:$D$533,TALLY!A15) -> 0 | AJ15: =COUNTIF(TT!$D$538:$D$550,TALLY!A15) -> 1 | AK15: =COUNTIF(TT!$D$555:$D$569,TALLY!A15) -> 0 | AL15: =COUNTIF(TT!$D$574:$D$582,TALLY!A15) -> 0 | AM15: =COUNTIF(TT!$D$587:$D$593,TALLY!A15) -> 0 | AN15: =COUNTIF(TT!$D$598:$D$606,TALLY!A15) -> 0 | AO15: =COUNTIF(TT!$D$611:$D$620,TALLY!A15) -> 1 | AP15: =COUNTIF(TT!$D$627:$D$639,TALLY!A15) -> 0 | AQ15: =COUNTIF(TT!$D$645:$D$657,TALLY!A15) -> 0 | AR15: =COUNTIF(TT!$D$663:$D$671,TALLY!A15) -> 0 | AS15: =COUNTIF(TT!$D$677:$D$685,TALLY!A15) -> 1 | AT15: =COUNTIF(TT!$D$689:$D$698,TALLY!A15) -> 0 | AU15: ED1-ME | AV15: =SUM($B15:$D15) -> 0 | AW15: =SUM($E15:$G15) -> 0 | AX15: =SUM($H15:$J15) -> 1 | AY15: =SUM($K15:$M15) -> 0 | AZ15: =SUM($N15:$P15) -> 1 | BA15: =SUM($Q15:$S15) -> 1 | BB15: =SUM($T15:$V15) -> 0 | BC15: =SUM($W15:$Y15) -> 0 | BD15: =SUM($Z15:$AB15) -> 0 | BE15: =SUM($AC15:$AE15) -> 1 | BF15: =SUM($AF15:$AH15) -> 0 | BG15: =SUM($AI15:$AK15) -> 1 | BH15: =SUM($AL15:$AN15) -> 0 | BI15: =SUM($AO15:$AQ15) -> 1 | BJ15: =SUM($AR15:$AT15) -> 1 | BK15: =SUM(AV15:BJ15) -> 7
