Workbook
Name CLASS: #REF!
Name CLASS: #REF!
Name CLASS: #REF!
Name CLASS: #REF!
Name CLASS: #REF!
Name CLASS: #REF!
Name CODE: #REF!
Name CODE: #REF!
Name CODE: #REF!
Name CODE: #REF!
Name CODE: #REF!
Name CODE: #REF!
Name CODE: #REF!
Name COURSE_NAME: #REF!
Name COURSE_NAME: #REF!
Name COURSE_NAME: #REF!
Name COURSE_NAME: #REF!
Name COURSE_NAME: #REF!
Name COURSE_NAME: #REF!
Name COURSE_NAME: #REF!
Name EXAMINER: #REF!
Name EXAMINER: #REF!
Name EXAMINER: #REF!
Name EXAMINER: #REF!
Name EXAMINER: #REF!
Name EXAMINER: #REF!
Name EXAMINER: #REF!
Name hy: #REF!
Name po: #REF!
Name room_no: #REF!
Name ROOM_NO.: #REF!
Name ROOM_NO.: #REF!
Name ROOM_NO.: #REF!
Name ROOM_NO.: #REF!
Name ROOM_NO.: #REF!
Name ROOM_NO.: #REF!
Name STDS: #REF!
Name STDS: #REF!
Name STDS: #REF!
Name STDS: #REF!
Name STDS: #REF!
Name STDS: #REF!
Name STDS: #REF!
Name TO_PRT: #REF!
Name TO_PRT: #REF!
Name TO_PRT: #REF!
Name TO_PRT: #REF!
Name TO_PRT: #REF!
Name TO_PRT: #REF!
Name TO_PRT: #REF!
Name Total_F1: [1]TT!$D$666:$D$681
Name Total_F1: '[2]TT (Working)'!$D$668:$D$683
Name Total_F1: '[2]TT (Working)'!$D$668:$D$683
Name Total_F1_1: [3]TT!$D$226:$D$238
Name Total_F1_1: '[4]TT (MAIN)'!$D$183:$D$215
Name Total_F1_1: [5]TT!$D$206:$D$219
Name Total_F1_2: [3]TT!$D$252:$D$267
Name Total_F1_2: [5]TT!$D$225:$D$227
Name Total_F1_3: [3]TT!$D$277:$D$290
Name Total_F1_3: [5]TT!$D$245:$D$261

Sheet TT 
A1: Monday, 23 February 2026 | I1: =CONCATENATE(A1,",",B1,",",E1) -> Monday, 23 February 2026,,
A2: Session, 1 (8:15AM - 9:15 AM) | I2: =CONCATENATE(A2,",",B2,",",E2) -> Session, 1 (8:15AM - 9:15 AM),, | L2: COMPARE
A3: CODE | B3: COURSE NAME | C3: EXAMINER | D3: CLASS | E3: # STDS | F3: ROOM NO. | G3: TO PRT | I3: =CONCATENATE(A3,",",B3,",",E3) -> CODE ,COURSE NAME ,# STDS
A4: MATH 351 | B4: {=IFERROR(VLOOKUP(I4:I31,Lecturers!A2:G597,7,FALSE),0)} -> NUMERICAL ANALYSIS | C4: {=IFERROR(VLOOKUP(I4:I31,Lecturers!A2:G597,2,FALSE),0)} -> Azure Isaac | D4: ED3-ME | E4: {=IFERROR(VLOOKUP(I4:I31,Lecturers!A2:G597,3,FALSE),0)} -> 230 | F4: Computer Based | G4: =1.1*E4 -> 253 | I4: =CONCATENATE(A4,",",D4) -> MATH 351,ED3-ME
A5: MATH 351 | B5: NUMERICAL ANALYSIS | C5: Azure Isaac | D5: ED3-AUTO | E5: 47 | F5: Computer Based | G5: =1.1*E5 -> 51.7 | I5: =CONCATENATE(A5,",",D5) -> MATH 351,ED3-AUTO
A6: MATH 351 | B6: NUMERICAL METHODS | C6: Azure Isaac | D6: ED3-BME | E6: 94 | F6: Computer Based | G6: =1.1*E6 -> 103.4 | I6: =CONCATENATE(A6,",",D6) -> MATH 351,ED3-BME
A7: MATH 351 | B7: NUMERICAL ANALYSIS | C7: Borkor Reindorf Nartey | D7: ED3-AERO | E7: 76 | F7: Computer Based | G7: =1.1*E7 -> 83.6 | I7: =CONCATENATE(A7,",",D7) -> MATH 351,ED3-AERO
A8: MATH 351 | B8: NUMERICAL ANALYSIS | C8: Borkor Reindorf Nartey | D8: ED3-AE | E8: 105 | F8: Computer Based | G8: =1.1*E8 -> 115.5 | I8: =CONCATENATE(A8,",",D8) -> MATH 351,ED3-AE
A9: MATH 351 | B9: NUMERICAL ANALYSIS | C9: Borkor Reindorf Nartey | D9: ED3-GEOL | E9: 154 | F9: Computer Based | G9: =1.1*E9 -> 169.4 | I9: =CONCATENATE(A9,",",D9) -> MATH 351,ED3-GEOL
A10: MATH 351 | B10: NUMERICAL ANALYSIS | C10: Borkor Reindorf Nartey | D10: ED3-COE | E10: 276 | F10: Computer Based | G10: =1.1*E10 -> 303.6 | I10: =CONCATENATE(A10,",",D10) -> MATH 351,ED3-COE
A11: MATH 351 | B11: NUMERICAL ANALYSIS | C11: Awashie Gaston Edem | D11: ED3-TEL | E11: 147 | F11: Computer Based | G11: =1.1*E11 -> 161.7 | I11: =CONCATENATE(A11,",",D11) -> MATH 351,ED3-TEL
A12: MATH 351 | B12: NUMERICAL ANALYSIS | C12: Awashie Gaston Edem | D12: ED3-EE | E12: 254 | F12: Computer Based | G12: =1.1*E12 -> 279.4 | I12: =CONCATENATE(A12,",",D12) -> MATH 351,ED3-EE
A13: MATH 351 | B13: NUMERICAL ANALYSIS | C13: Awashie Gaston Edem | D13: ED3-IND | E13: 72 | F13: Computer Based | G13: =1.1*E13 -> 79.2 | I13: =CONCATENATE(A13,",",D13) -> MATH 351,ED3-IND
A14: MATH 351 | B14: NUMERICAL ANALYSIS | C14: Awashie Gaston Edem | D14: ED3-MARI | E14: 40 | F14: Computer Based | G14: =1.1*E14 -> 44 | I14: =CONCATENATE(A14,",",D14) -> MATH 351,ED3-MARI
A15: MATH 351 | B15: NUMERICAL ANALYSIS | C15: Borkor Reindorf Nartey | D15: ED3-CE | E15: 223 | F15: Computer Based | G15: =1.1*E15 -> 245.3 | I15: =CONCATENATE(A15,",",D15) -> MATH 351,ED3-CE
A16: PE 351 | B16: PETROLEUM ROCK MECHANICS | C16: Erzuah Samuel | D16: ED3-PE | E16: 82 | F16: EA/A110/VCR | G16: =1.1*E16 -> 90.2 | H16: 27/30/25 | I16: =CONCATENATE(A16,",",D16) -> PE 351,ED3-PE
A17: ACF 255 | B17: FINANCIAL ACCOUNTING I | C17: Yeboah Edward | D17: ED2-BME | E17: 16 | F17: N1 | G17: =1.1*E17 -> 17.6 | H17: 16 | I17: =CONCATENATE(A17,",",D17) -> ACF 255,ED2-BME
A18: ACF 255 | B18: FINANCIAL ACCOUNTING I | C18: Yeboah Edward | D18: ED2-COE | E18: 61 | F18: 303/304/206 | G18: =1.1*E18 -> 67.1 | H18: 25/20/16 | I18: =CONCATENATE(A18,",",D18) -> ACF 255,ED2-COE
A19: ACF 255 | B19: FINANCIAL ACCOUNTING I | C19: Yeboah Edward | D19: ED2-TEL | E19: 35 | F19: LT/RMB | G19: =1.1*E19 -> 38.5 | H19: 20/15 | I19: =CONCATENATE(A19,",",D19) -> ACF 255,ED2-TEL
A20: ACF 255 | B20: FINANCIAL ACCOUNTING I | C20: Yeboah Edward | D20: ED2-MSE | E20: 13 | F20: N1 | G20: =1.1*E20 -> 14.3 | H20: 13 | I20: =CONCATENATE(A20,",",D20) -> ACF 255,ED2-MSE
A21: ACF 255 | B21: FINANCIAL ACCOUNTING I | C21: Yeboah Edward | D21: ED3-GEOM | E21: 34 | F21: 206/RMB | G21: =1.1*E21 -> 37.4 | H21: 20/14 | I21: =CONCATENATE(A21,",",D21) -> ACF 255,ED3-GEOM
A22: ACF 255 | B22: FINANCIAL ACCOUNTING I | C22: Yeboah Edward | D22: ED1-GEOL | E22: 3 | F22: RMA | G22: =1.1*E22 -> 3.3 | H22: 3 | I22: =CONCATENATE(A22,",",D22) -> ACF 255,ED1-GEOL
A23: MSE 151 | B23: INTRODUCTION TO THERMODYNAMICS OF MATERIALS | C23: Gikunoo Emmanuel | D23: ED1-MSE | E23: 98 | F23: PB001/PB208/PB008 | G23: =1.1*E23 -> 107.8 | H23: 45/30/23 | I23: =CONCATENATE(A23,",",D23) -> MSE 151,ED1-MSE
A24: BME 161 | B24: CELL BIOLOGY | C24: Adjei Prince Ebenezer | D24: ED1-BME | E24: 136 | F24: PB201/PB214/PB020/PB212 | G24: =1.1*E24 -> 149.6 | H24: 40/40/40/16 | I24: =CONCATENATE(A24,",",D24) -> BME 161,ED1-BME
A25: GE 261 | B25: FIELD AND GEODETIC ASTRONOMY | C25: Ayer John Wise Divine | D25: ED2-GEOM | E25: 134 | F25: PB201/PB214/PB014/PB208 | G25: =1.1*E25 -> 147.4 | H25: 40/40/35/20 | I25: =CONCATENATE(A25,",",D25) -> GE 261,ED2-GEOM
A26: GE 151 | B26: CARTOGRAPHY I | C26: Quaye-Ballard Jonathan Arthur | D26: ED1-GEOM | E26: 100 | F26: 303/LT/VSLA | G26: =1.1*E26 -> 110 | H26: 30/30/40 | I26: =CONCATENATE(A26,",",D26) -> GE 151,ED1-GEOM
A27: EE 161 | B27: TRANSFORMERS | C27: Opoku Daniel | D27: ED1-EE | E27: 287 | F27: NEB-SF/NEB-TF/NEB-FF1/NEB-FF2/NAF1 | G27: =1.1*E27 -> 315.7 | H27: 85/80/55/30/37 | I27: =CONCATENATE(A27,",",D27) -> EE 161,ED1-EE
A28: GED 475 | B28: PRINCIPLES OF HYDROGEOLOGY | C28: Appiah-Adjei Emmanuel Kwame | D28: ED4-GEOL | E28: 102 | F28: NAF1/EA/A110 | G28: =1.1*E28 -> 112.2 | H28: 45/30/27 | I28: =CONCATENATE(A28,",",D28) -> GED 475,ED4-GEOL
A29: PE 459 | B29: NATURAL GAS ENGINEERING I | C29: Sarkodie Kwame | D29: ED4-PE | E29: 103 | F29: RMA/VSLA/304/N2 | G29: =1.1*E29 -> 113.3 | H29: 20/40/20/23 | I29: =CONCATENATE(A29,",",D29) -> PE 459,ED4-PE
... A31: GED 253 | B31: PHYSICAL GEOLOGY | C31: Mensah Emmanuel | D31: ED2-GEOL | E31: 154 | F31: PB014/PB001/PB020/PB008 | G31: =1.1*E31 -> 169.4 | H31: 42/42/42/28 | I31: =CONCATENATE(A31,",",D31) -> GED 253,ED2-GEOL
D32: Total M1 | E32: =SUM(E16:E31) -> 1618 | I32: =CONCATENATE(A32,",",D32) -> ,Total M1
I33: =CONCATENATE(A33,",",D33) -> ,
I34: =CONCATENATE(A34,",",D34) -> ,
A35: Monday, 23 February 2026 | I35: =CONCATENATE(A35,",",D35) -> Monday, 23 February 2026,
A36: Session, 2 (10:00AM - 11:00 AM) | I36: =CONCATENATE(A36,",",D36) -> Session, 2 (10:00AM - 11:00 AM),
A37: CODE | B37: COURSE NAME | C37: EXAMINER | D37: CLASS | E37: # STDS | F37: ROOM NO. | G37: TO PRT | I37: =CONCATENATE(A37,",",D37) -> CODE ,CLASS
A38: EE 467 | B38: {=IFERROR(VLOOKUP(I38:I49,Lecturers!A2:G597,7,FALSE),0)} -> POWER SYSTEMS OPERATION AND CONTROL | C38: {=IFERROR(VLOOKUP(I38:I49,Lecturers!A2:G597,2,FALSE),0)} -> Antoh Emmanuel Kwaku | D38: ED4-EE | E38: {=IFERROR(VLOOKUP(I38:I49,Lecturers!A2:G597,3,FALSE),0)} -> 224 | F38: VSLA/LT/303/304/206/RMA/RMB/N1/N2 | G38: =1.1*E38 -> 246.4 | H38: 45/30/30/20/20/20/20/20/20 | I38: =CONCATENATE(A38,",",D38) -> EE 467,ED4-EE
A39: COE 457 | B39: ARTIFICIAL INTELLIGENCE | C39: Nunoo-Mensah Henry | D39: ED4-COE | E39: 170 | F39: NEB-SF/NEB-FF1/NEB-FF2 | G39: =1.1*E39 -> 187 | H39: 85/55/30 | I39: =CONCATENATE(A39,",",D39) -> COE 457,ED4-COE
A40: CHE 255 | B40: FLUID TRANSPORT | C40: Momade Zsuzsanna Gál | D40: ED2-CHE | E40: 154 | F40: NEB-SF/NEB-FF1/NEB-FF2 | G40: =1.1*E40 -> 169.4 | H40: 80/46/28 | I40: =CONCATENATE(A40,",",D40) -> CHE 255,ED2-CHE
A41: CHE 255 | B41: FLUID TRANSPORT | C41: Dogbe Eunice Sefakor Aku | D41: ED2-PCE | E41: 59 | F41: 303/304/206 | G41: =1.1*E41 -> 64.9 | H41: 22/20/17 | I41: =CONCATENATE(A41,",",D41) -> CHE 255,ED2-PCE
...

Sheet Sheet1
A1: Monday, 23 February 2026
A2: Session, 1 (8:15AM - 9:15 AM)
A3: CODE | B3: COURSE NAME | C3: EXAMINER | D3: CLASS | E3: # STDS | F3: ROOM NO. | G3: TO PRT
A4: MATH 351 | B4: NUMERICAL ANALYSIS | C4: Azure Isaac | D4: ED3-ME | E4: 230 | F4: Computer Based | G4: 253
A5: MATH 351 | B5: NUMERICAL ANALYSIS | C5: Azure Isaac | D5: ED3-AUTO | E5: 47 | F5: Computer Based | G5: 51.7
A6: MATH 351 | B6: NUMERICAL METHODS | C6: Azure Isaac | D6: ED3-BME | E6: 94 | F6: Computer Based | G6: 103.4
A7: MATH 351 | B7: NUMERICAL ANALYSIS | C7: Borkor Reindorf Nartey | D7: ED3-AERO | E7: 76 | F7: Computer Based | G7: 83.6
A8: MATH 351 | B8: NUMERICAL ANALYSIS | C8: Borkor Reindorf Nartey | D8: ED3-AE | E8: 105 | F8: Computer Based | G8: 115.5
A9: MATH 351 | B9: NUMERICAL ANALYSIS | C9: Borkor Reindorf Nartey | D9: ED3-GEOL | E9: 154 | F9: Computer Based | G9: 169.4
A10: MATH 351 | B10: NUMERICAL ANALYSIS | C10: Borkor Reindorf Nartey | D10: ED3-COE | E10: 276 | F10: Computer Based | G10: 303.6
A11: MATH 351 | B11: NUMERICAL ANALYSIS | C11: Awashie Gaston Edem | D11: ED3-TEL | E11: 147 | F11: Computer Based | G11: 161.7
A12: MATH 351 | B12: NUMERICAL ANALYSIS | C12: Awashie Gaston Edem | D12: ED3-EE | E12: 254 | F12: Computer Based | G12: 279.4
A13: MATH 351 | B13: NUMERICAL ANALYSIS | C13: Awashie Gaston Edem | D13: ED3-IND | E13: 72 | F13: Computer Based | G13: 79.2
A14: MATH 351 | B14: NUMERICAL ANALYSIS | C14: Awashie Gaston Edem | D14: ED3-MARI | E14: 40 | F14: Computer Based | G14: 44
A15: MATH 351 | B15: NUMERICAL ANALYSIS | C15: Borkor Reindorf Nartey | D15: ED3-CE | E15: 223 | F15: Computer Based | G15: 245.3
A16: PE 351 | B16: PETROLEUM ROCK MECHANICS | C16: Erzuah Samuel | D16: ED3-PE | E16: 82 | F16: EA/A110/VCR | G16: 90.2 | H16: 27/30/25
A17: ACF 255 | B17: FINANCIAL ACCOUNTING I | C17: Yeboah Edward | D17: ED2-BME | E17: 16 | F17: N1 | G17: 17.6 | H17: 16
A18: ACF 255 | B18: FINANCIAL ACCOUNTING I | C18: Yeboah Edward | D18: ED2-COE | E18: 61 | F18: 303/304/206 | G18: 67.1 | H18: 25/20/16
A19: ACF 255 | B19: FINANCIAL ACCOUNTING I | C19: Yeboah Edward | D19: ED2-TEL | E19: 35 | F19: LT/RMB | G19: 38.5 | H19: 20/15
A20: ACF 255 | B20: FINANCIAL ACCOUNTING I | C20: Yeboah Edward | D20: ED2-MSE | E20: 13 | F20: N1 | G20: 14.3 | H20: 13
A21: ACF 255 | B21: FINANCIAL ACCOUNTING I | C21: Yeboah Edward | D21: ED3-GEOM | E21: 34 | F21: 206/RMB | G21: 37.4 | H21: 20/14
A22: ACF 255 | B22: FINANCIAL ACCOUNTING I | C22: Yeboah Edward | D22: ED1-GEOL | E22: 3 | F22: RMA | G22: 3.3 | H22: 3
A23: MSE 151 | B23: INTRODUCTION TO THERMODYNAMICS OF MATERIALS | C23: Gikunoo Emmanuel | D23: ED1-MSE | E23: 98 | F23: PB001/PB208/PB008 | G23: 107.8 | H23: 45/30/23
A24: BME 161 | B24: CELL BIOLOGY | C24: Adjei Prince Ebenezer | D24: ED1-BME | E24: 136 | F24: PB201/PB214/PB020/PB212 | G24: 149.6 | H24: 40/40/40/16
A25: GE 261 | B25: FIELD AND GEODETIC ASTRONOMY | C25: Ayer John Wise Divine | D25: ED2-GEOM | E25: 134 | F25: PB201/PB214/PB014/PB208 | G25: 147.4 | H25: 40/40/35/20
A26: GE 151 | B26: CARTOGRAPHY I | C26: Quaye-Ballard Jonathan Arthur | D26: ED1-GEOM | E26: 100 | F26: 303/LT/VSLA | G26: 110 | H26: 30/30/40
A27: EE 161 | B27: TRANSFORMERS | C27: Opoku Daniel | D27: ED1-EE | E27: 287 | F27: NEB-SF/NEB-TF/NEB-FF1/NEB-FF2/NAF1 | G27: 315.7 | H27: 85/80/55/30/37
A28: GED 475 | B28: PRINCIPLES OF HYDROGEOLOGY | C28: Appiah-Adjei Emmanuel Kwame | D28: ED4-GEOL | E28: 102 | F28: NAF1/EA/A110 | G28: 112.2 | H28: 45/30/27
A29: PE 459 | B29: NATURAL GAS ENGINEERING I | C29: Sarkodie Kwame | D29: ED4-PE | E29: 103 | F29: RMA/VSLA/304/N2 | G29: 113.3 | H29: 20/40/20/23
... A31: GED 253 | B31: PHYSICAL GEOLOGY | C31: Mensah Emmanuel | D31: ED2-GEOL | E31: 154 | F31: PB014/PB001/PB020/PB008 | G31: 169.4 | H31: 42/42/42/28
D32: Total M1 | E32: 1618
A35: Monday, 23 February 2026
A36: Session, 2 (10:00AM - 11:00 AM)
A37: CODE | B37: COURSE NAME | C37: EXAMINER | D37: CLASS | E37: # STDS | F37: ROOM NO. | G37: TO PRT
A38: EE 467 | B38: POWER SYSTEMS OPERATION AND CONTROL | C38: Antoh Emmanuel Kwaku | D38: ED4-EE | E38: 224 | F38: VSLA/LT/303/304/206/RMA/RMB/N1/N2 | G38: 246.4 | H38: 45/30/30/20/20/20/20/20/20
A39: COE 457 | B39: ARTIFICIAL INTELLIGENCE | C39: Nunoo-Mensah Henry | D39: ED4-COE | E39: 170 | F39: NEB-SF/NEB-FF1/NEB-FF2 | G39: 187 | H39: 85/55/30
A40: CHE 255 | B40: FLUID TRANSPORT | C40: Momade Zsuzsanna Gál | D40: ED2-CHE | E40: 154 | F40: NEB-SF/NEB-FF1/NEB-FF2 | G40: 169.4 | H40: 80/46/28
A41: CHE 255 | B41: FLUID TRANSPORT | C41: Dogbe Eunice Sefakor Aku | D41: ED2-PCE | E41: 59 | F41: 303/304/206 | G41: 64.9 | H41: 22/20/17
A42: CE 457 | B42: DRAINAGE SYSTEMS | C42: Adjei Kwaku Amaning | D42: ED4-CE | E42: 245 | F42: PB001/PB020/PB014/PB201/PB214/PB212 | G42: 269.5 | H42: 45/45/45/45/45/20
A43: BME 471 | B43: BIOINSTRUMENTATION II | C43: Acquah Isaac | D43: ED4-BME | E43: 84 | F43: PB008/PB208/PB212 | G43: 92.4 | H43: 30/30/24
...

Sheet TALLY
B1: M | I1: T | P1: W | W1: H | AD1: F | AL1: M | AM1: T | AN1: W | AO1: H | AP1: F
B2: M1 | C2: M2 | D2: M3 | E2: M4 | F2: M5 | G2: M6 | H2: M7 | I2: T1 | J2: T2 | K2: T3 | L2: T4 | M2: T5 | N2: T6 | O2: T7 | P2: W1 | Q2: W2 | R2: W3 | S2: W4 | T2: W5 | U2: W6 | V2: W7 | W2: H1 | X2: H2 | Y2: H3 | Z2: H4 | AA2: H5 | AB2: H6 | AC2: H7 | AD2: F1 | AE2: F2 | AF2: F3 | AG2: F4 | AH2: F5 | AI2: F6 | AL2: M | AM2: T | AN2: W | AO2: H | AP2: F | AT2: {=count} -> #NAME?
A3: ED1-AE | B3: =COUNTIF('TT '!$D$4:$D$31,TALLY!A3) -> 0 | C3: =COUNTIF('TT '!$D$38:$D$49,TALLY!A3) -> 0 | D3: =COUNTIF('TT '!$D$56:$D$78,TALLY!A3) -> 0 | E3: =COUNTIF('TT '!$D$85:$D$105,TALLY!A3) -> 1 | F3: =COUNTIF('TT '!$D$112:$D$126,TALLY!A3) -> 0 | G3: =COUNTIF('TT '!$D$133:$D$147,TALLY!A3) -> 0 | H3: =COUNTIF('TT '!$D$4:$D$31,TALLY!G3) -> 0 | I3: =COUNTIF('TT '!$D$154:$D$173,TALLY!A3) -> 0 | J3: =COUNTIF('TT '!$D$180:$D$197,TALLY!A3) -> 1 | K3: =COUNTIF('TT '!$D$204:$D$216,TALLY!A3) -> 0 | L3: =COUNTIF('TT '!$D$223:$D$235,TALLY!A3) -> 0 | M3: =COUNTIF('TT '!$D$242:$D$257,TALLY!A3) -> 1 | N3: =COUNTIF('TT '!$D$264:$D$276,TALLY!A3) -> 0 | O3: =COUNTIF([8]TT!$D$36:$D$41,$A3) -> #VALUE! | P3: =COUNTIF('TT '!$D$283:$D$294,TALLY!A3) -> 1 | Q3: =COUNTIF('TT '!$D$301:$D$317,TALLY!A3) -> 0 | R3: =COUNTIF('TT '!$D$324:$D$339,TALLY!A3) -> 0 | S3: =COUNTIF('TT '!$D$346:$D$362,TALLY!A3) -> 0 | T3: =COUNTIF('TT '!$D$369:$D$383,TALLY!A3) -> 0 | U3: =COUNTIF('TT '!$D$390:$D$409,TALLY!A3) -> 0 | V3: =COUNTIF([8]TT!$D$36:$D$41,$A3) -> #VALUE! | W3: =COUNTIF('TT '!$D$416:$D$429,TALLY!A3) -> 0 | X3: =COUNTIF('TT '!$D$436:$D$449,TALLY!A3) -> 0 | Y3: =COUNTIF('TT '!$D$456:$D$474,TALLY!A3) -> 0 | Z3: =COUNTIF('TT '!$D$481:$D$495,TALLY!A3) -> 1 | AA3: =COUNTIF('TT '!$D$502:$D$519,TALLY!A3) -> 0 | AB3: =COUNTIF('TT '!$D$526:$D$540,TALLY!A3) -> 0 | AC3: =COUNTIF([8]TT!$D$36:$D$41,$A3) -> #VALUE! | AD3: =COUNTIF('TT '!$D$547:$D$556,TALLY!A3) -> 0 | AE3: =COUNTIF('TT '!$D$563:$D$577,TALLY!A3) -> 0 | AF3: =COUNTIF('TT '!$D$584:$D$598,TALLY!A3) -> 0 | AG3: =COUNTIF('TT '!$D$605:$D$617,TALLY!A3) -> 0 | AH3: =COUNTIF('TT '!$D$624:$D$636,TALLY!A3) -> 1 | AI3: =COUNTIF('TT '!$D$643:$D$654,TALLY!A3) -> 0 | AJ3: =COUNTIF([8]TT!$D$36:$D$41,$A3) -> #VALUE! | AK3: =CONCATENATE(B3,C3,D3,E3,F3,G3,I3,J3,K3,L3,M3,N3,P3,Q3,R3,S3,T3,U3,W3,X3,Y3,Z3,AA3,AB3,AD3,AE3,AF3,AG3,AH3,AI3) -> 000100010010100000000100000010 | AL3: =SUM(B3:G3) -> 1 | AM3: =SUM(I3:N3) -> 2 | AN3: =SUM(P3:U3) -> 1 | AO3: =SUM(W3:AB3) -> 1 | AP3: =SUM(AD3:AI3) -> 1
A4: ED1-AERO | B4: =COUNTIF('TT '!$D$4:$D$31,TALLY!A4) -> 0 | C4: =COUNTIF('TT '!$D$38:$D$49,TALLY!A4) -> 0 | D4: =COUNTIF('TT '!$D$56:$D$78,TALLY!A4) -> 1 | E4: =COUNTIF('TT '!$D$85:$D$105,TALLY!A4) -> 0 | F4: =COUNTIF('TT '!$D$112:$D$126,TALLY!A4) -> 1 | G4: =COUNTIF('TT '!$D$133:$D$147,TALLY!A4) -> 0 | H4: =COUNTIF('TT '!$D$4:$D$31,TALLY!G4) -> 0 | I4: =COUNTIF('TT '!$D$154:$D$173,TALLY!A4) -> 0 | J4: =COUNTIF('TT '!$D$180:$D$197,TALLY!A4) -> 1 | K4: =COUNTIF('TT '!$D$204:$D$216,TALLY!A4) -> 0 | L4: =COUNTIF('TT '!$D$223:$D$235,TALLY!A4) -> 0 | M4: =COUNTIF('TT '!$D$242:$D$257,TALLY!A4) -> 1 | N4: =COUNTIF('TT '!$D$264:$D$276,TALLY!A4) -> 0 | O4: =COUNTIF([8]TT!$D$36:$D$41,$A4) -> #VALUE! | P4: =COUNTIF('TT '!$D$283:$D$294,TALLY!A4) -> 0 | Q4: =COUNTIF('TT '!$D$301:$D$317,TALLY!A4) -> 1 | R4: =COUNTIF('TT '!$D$324:$D$339,TALLY!A4) -> 0 | S4: =COUNTIF('TT '!$D$346:$D$362,TALLY!A4) -> 0 | T4: =COUNTIF('TT '!$D$369:$D$383,TALLY!A4) -> 0 | U4: =COUNTIF('TT '!$D$390:$D$409,TALLY!A4) -> 0 | V4: =COUNTIF([8]TT!$D$36:$D$41,$A4) -> #VALUE! | W4: =COUNTIF('TT '!$D$416:$D$429,TALLY!A4) -> 0 | X4: =COUNTIF('TT '!$D$436:$D$449,TALLY!A4) -> 0 | Y4: =COUNTIF('TT '!$D$456:$D$474,TALLY!A4) -> 0 | Z4: =COUNTIF('TT '!$D$481:$D$495,TALLY!A4) -> 1 | AA4: =COUNTIF('TT '!$D$502:$D$519,TALLY!A4) -> 0 | AB4: =COUNTIF('TT '!$D$526:$D$540,TALLY!A4) -> 0 | AC4: =COUNTIF([8]TT!$D$36:$D$41,$A4) -> #VALUE! | AD4: =COUNTIF('TT '!$D$547:$D$556,TALLY!A4) -> 1 | AE4: =COUNTIF('TT '!$D$563:$D$577,TALLY!A4) -> 0 | AF4: =COUNTIF('TT '!$D$584:$D$598,TALLY!A4) -> 0 | AG4: =COUNTIF('TT '!$D$605:$D$617,TALLY!A4) -> 0 | AH4: =COUNTIF('TT '!$D$624:$D$636,TALLY!A4) -> 0 | AI4: =COUNTIF('TT '!$D$643:$D$654,TALLY!A4) -> 0 | AJ4: =COUNTIF([8]TT!$D$36:$D$41,$A4) -> #VALUE! | AK4: =CONCATENATE(B4,C4,D4,E4,F4,G4,I4,J4,K4,L4,M4,N4,P4,Q4,R4,S4,T4,U4,W4,X4,Y4,Z4,AA4,AB4,AD4,AE4,AF4,AG4,AH4,AI4) -> 001010010010010000000100100000 | AL4: =SUM(B4:G4) -> 2 | AM4: =SUM(I4:N4) -> 2 | AN4: =SUM(P4:U4) -> 1 | AO4: =SUM(W4:AB4) -> 1 | AP4: =SUM(AD4:AI4) -> 1
A5: ED1-AUTO | B5: =COUNTIF('TT '!$D$4:$D$31,TALLY!A5) -> 0 | C5: =COUNTIF('TT '!$D$38:$D$49,TALLY!A5) -> 0 | D5: =COUNTIF('TT '!$D$56:$D$78,TALLY!A5) -> 1 | E5: =COUNTIF('TT '!$D$85:$D$105,TALLY!A5) -> 0 | F5: =COUNTIF('TT '!$D$112:$D$126,TALLY!A5) -> 0 | G5: =COUNTIF('TT '!$D$133:$D$147,TALLY!A5) -> 0 | H5: =COUNTIF('TT '!$D$4:$D$31,TALLY!G5) -> 0 | I5: =COUNTIF('TT '!$D$154:$D$173,TALLY!A5) -> 0 | J5: =COUNTIF('TT '!$D$180:$D$197,TALLY!A5) -> 1 | K5: =COUNTIF('TT '!$D$204:$D$216,TALLY!A5) -> 0 | L5: =COUNTIF('TT '!$D$223:$D$235,TALLY!A5) -> 0 | M5: =COUNTIF('TT '!$D$242:$D$257,TALLY!A5) -> 0 | N5: =COUNTIF('TT '!$D$264:$D$276,TALLY!A5) -> 0 | O5: =COUNTIF([8]TT!$D$36:$D$41,$A5) -> #VALUE! | P5: =COUNTIF('TT '!$D$283:$D$294,TALLY!A5) -> 0 | Q5: =COUNTIF('TT '!$D$301:$D$317,TALLY!A5) -> 0 | R5: =COUNTIF('TT '!$D$324:$D$339,TALLY!A5) -> 1 | S5: =COUNTIF('TT '!$D$346:$D$362,TALLY!A5) -> 0 | T5: =COUNTIF('TT '!$D$369:$D$383,TALLY!A5) -> 0 | U5: =COUNTIF('TT '!$D$390:$D$409,TALLY!A5) -> 1 | V5: =COUNTIF([8]TT!$D$36:$D$41,$A5) -> #VALUE! | W5: =COUNTIF('TT '!$D$416:$D$429,TALLY!A5) -> 0 | X5: =COUNTIF('TT '!$D$436:$D$449,TALLY!A5) -> 0 | Y5: =COUNTIF('TT '!$D$456:$D$474,TALLY!A5) -> 0 | Z5: =COUNTIF('TT '!$D$481:$D$495,TALLY!A5) -> 1 | AA5: =COUNTIF('TT '!$D$502:$D$519,TALLY!A5) -> 0 | AB5: =COUNTIF('TT '!$D$526:$D$540,TALLY!A5) -> 0 | AC5: =COUNTIF([8]TT!$D$36:$D$41,$A5) -> #VALUE! | AD5: =COUNTIF('TT '!$D$547:$D$556,TALLY!A5) -> 0 | AE5: =COUNTIF('TT '!$D$563:$D$577,TALLY!A5) -> 0 | AF5: =COUNTIF('TT '!$D$584:$D$598,TALLY!A5) -> 0 | AG5: =COUNTIF('TT '!$D$605:$D$617,TALLY!A5) -> 0 | AH5: =COUNTIF('TT '!$D$624:$D$636,TALLY!A5) -> 0 | AI5: =COUNTIF('TT '!$D$643:$D$654,TALLY!A5) -> 0 | AJ5: =COUNTIF([8]TT!$D$36:$D$41,$A5) -> #VALUE! | AK5: =CONCATENATE(B5,C5,D5,E5,F5,G5,I5,J5,K5,L5,M5,N5,P5,Q5,R5,S5,T5,U5,W5,X5,Y5,Z5,AA5,AB5,AD5,AE5,AF5,AG5,AH5,AI5) -> 001000010000001001000100000000 | AL5: =SUM(B5:G5) -> 1 | AM5: =SUM(I5:N5) -> 1 | AN5: =SUM(P5:U5) -> 2 | AO5: =SUM(W5:AB5) -> 1 | AP5: =SUM(AD5:AI5) -> 0
A6: ED1-BME | B6: =COUNTIF('TT '!$D$4:$D$31,TALLY!A6) -> 1 | C6: =COUNTIF('TT '!$D$38:$D$49,TALLY!A6) -> 0 | D6: =COUNTIF('TT '!$D$56:$D$78,TALLY!A6) -> 0 | E6: =COUNTIF('TT '!$D$85:$D$105,TALLY!A6) -> 1 | F6: =COUNTIF('TT '!$D$112:$D$126,TALLY!A6) -> 0 | G6: =COUNTIF('TT '!$D$133:$D$147,TALLY!A6) -> 0 | H6: =COUNTIF('TT '!$D$4:$D$31,TALLY!G6) -> 0 | I6: =COUNTIF('TT '!$D$154:$D$173,TALLY!A6) -> 0 | J6: =COUNTIF('TT '!$D$180:$D$197,TALLY!A6) -> 1 | K6: =COUNTIF('TT '!$D$204:$D$216,TALLY!A6) -> 0 | L6: =COUNTIF('TT '!$D$223:$D$235,TALLY!A6) -> 0 | M6: =COUNTIF('TT '!$D$242:$D$257,TALLY!A6) -> 0 | N6: =COUNTIF('TT '!$D$264:$D$276,TALLY!A6) -> 0 | O6: =COUNTIF([8]TT!$D$36:$D$41,$A6) -> #VALUE! | P6: =COUNTIF('TT '!$D$283:$D$294,TALLY!A6) -> 0 | Q6: =COUNTIF('TT '!$D$301:$D$317,TALLY!A6) -> 1 | R6: =COUNTIF('TT '!$D$324:$D$339,TALLY!A6) -> 0 | S6: =COUNTIF('TT '!$D$346:$D$362,TALLY!A6) -> 0 | T6: =COUNTIF('TT '!$D$369:$D$383,TALLY!A6) -> 0 | U6: =COUNTIF('TT '!$D$390:$D$409,TALLY!A6) -> 0 | V6: =COUNTIF([8]TT!$D$36:$D$41,$A6) -> #VALUE! | W6: =COUNTIF('TT '!$D$416:$D$429,TALLY!A6) -> 0 | X6: =COUNTIF('TT '!$D$436:$D$449,TALLY!A6) -> 0 | Y6: =COUNTIF('TT '!$D$456:$D$474,TALLY!A6) -> 0 | Z6: =COUNTIF('TT '!$D$481:$D$495,TALLY!A6) -> 1 | AA6: =COUNTIF('TT '!$D$502:$D$519,TALLY!A6) -> 0 | AB6: =COUNTIF('TT '!$D$526:$D$540,TALLY!A6) -> 0 | AC6: =COUNTIF([8]TT!$D$36:$D$41,$A6) -> #VALUE! | AD6: =COUNTIF('TT '!$D$547:$D$556,TALLY!A6) -> 0 | AE6: =COUNTIF('TT '!$D$563:$D$577,TALLY!A6) -> 0 | AF6: =COUNTIF('TT '!$D$584:$D$598,TALLY!A6) -> 1 | AG6: =COUNTIF('TT '!$D$605:$D$617,TALLY!A6) -> 0 | AH6: =COUNTIF('TT '!$D$624:$D$636,TALLY!A6) -> 0 | AI6: =COUNTIF('TT '!$D$643:$D$654,TALLY!A6) -> 0 | AJ6: =COUNTIF([8]TT!$D$36:$D$41,$A6) -> #VALUE! | AK6: =CONCATENATE(B6,C6,D6,E6,F6,G6,I6,J6,K6,L6,M6,N6,P6,Q6,R6,S6,T6,U6,W6,X6,Y6,Z6,AA6,AB6,AD6,AE6,AF6,AG6,AH6,AI6) -> 100100010000010000000100001000 | AL6: =SUM(B6:G6) -> 2 | AM6: =SUM(I6:N6) -> 1 | AN6: =SUM(P6:U6) -> 1 | AO6: =SUM(W6:AB6) -> 1 | AP6: =SUM(AD6:AI6) -> 1
A7: ED1-CE | B7: =COUNTIF('TT '!$D$4:$D$31,TALLY!A7) -> 0 | C7: =COUNTIF('TT '!$D$38:$D$49,TALLY!A7) -> 0 | D7: =COUNTIF('TT '!$D$56:$D$78,TALLY!A7) -> 1 | E7: =COUNTIF('TT '!$D$85:$D$105,TALLY!A7) -> 0 | F7: =COUNTIF('TT '!$D$112:$D$126,TALLY!A7) -> 0 | G7: =COUNTIF('TT '!$D$133:$D$147,TALLY!A7) -> 0 | H7: =COUNTIF('TT '!$D$4:$D$31,TALLY!G7) -> 0 | I7: =COUNTIF('TT '!$D$154:$D$173,TALLY!A7) -> 0 | J7: =COUNTIF('TT '!$D$180:$D$197,TALLY!A7) -> 1 | K7: =COUNTIF('TT '!$D$204:$D$216,TALLY!A7) -> 0 | L7: =COUNTIF('TT '!$D$223:$D$235,TALLY!A7) -> 0 | M7: =COUNTIF('TT '!$D$242:$D$257,TALLY!A7) -> 0 | N7: =COUNTIF('TT '!$D$264:$D$276,TALLY!A7) -> 1 | O7: =COUNTIF([8]TT!$D$36:$D$41,$A7) -> #VALUE! | P7: =COUNTIF('TT '!$D$283:$D$294,TALLY!A7) -> 0 | Q7: =COUNTIF('TT '!$D$301:$D$317,TALLY!A7) -> 1 | R7: =COUNTIF('TT '!$D$324:$D$339,TALLY!A7) -> 0 | S7: =COUNTIF('TT '!$D$346:$D$362,TALLY!A7) -> 0 | T7: =COUNTIF('TT '!$D$369:$D$383,TALLY!A7) -> 0 | U7: =COUNTIF('TT '!$D$390:$D$409,TALLY!A7) -> 1 | V7: =COUNTIF([8]TT!$D$36:$D$41,$A7) -> #VALUE! | W7: =COUNTIF('TT '!$D$416:$D$429,TALLY!A7) -> 0 | X7: =COUNTIF('TT '!$D$436:$D$449,TALLY!A7) -> 1 | Y7: =COUNTIF('TT '!$D$456:$D$474,TALLY!A7) -> 0 | Z7: =COUNTIF('TT '!$D$481:$D$495,TALLY!A7) -> 0 | AA7: =COUNTIF('TT '!$D$502:$D$519,TALLY!A7) -> 0 | AB7: =COUNTIF('TT '!$D$526:$D$540,TALLY!A7) -> 1 | AC7: =COUNTIF([8]TT!$D$36:$D$41,$A7) -> #VALUE! | AD7: =COUNTIF('TT '!$D$547:$D$556,TALLY!A7) -> 0 | AE7: =COUNTIF('TT '!$D$563:$D$577,TALLY!A7) -> 1 | AF7: =COUNTIF('TT '!$D$584:$D$598,TALLY!A7) -> 0 | AG7: =COUNTIF('TT '!$D$605:$D$617,TALLY!A7) -> 0 | AH7: =COUNTIF('TT '!$D$624:$D$636,TALLY!A7) -> 1 | AI7: =COUNTIF('TT '!$D$643:$D$654,TALLY!A7) -> 0 | AJ7: =COUNTIF([8]TT!$D$36:$D$41,$A7) -> #VALUE! | AK7: =CONCATENATE(B7,C7,D7,E7,F7,G7,I7,J7,K7,L7,M7,N7,P7,Q7,R7,S7,T7,U7,W7,X7,Y7,Z7,AA7,AB7,AD7,AE7,AF7,AG7,AH7,AI7) -> 001000010001010001010001010010 | AL7: =SUM(B7:G7) -> 1 | AM7: =SUM(I7:N7) -> 2 | AN7: =SUM(P7:U7) -> 2 | AO7: =SUM(W7:AB7) -> 2 | AP7: =SUM(AD7:AI7) -> 2
A8: ED1-CHE | B8: =COUNTIF('TT '!$D$4:$D$31,TALLY!A8) -> 0 | C8: =COUNTIF('TT '!$D$38:$D$49,TALLY!A8) -> 0 | D8: =COUNTIF('TT '!$D$56:$D$78,TALLY!A8) -> 0 | E8: =COUNTIF('TT '!$D$85:$D$105,TALLY!A8) -> 1 | F8: =COUNTIF('TT '!$D$112:$D$126,TALLY!A8) -> 0 | G8: =COUNTIF('TT '!$D$133:$D$147,TALLY!A8) -> 0 | H8: =COUNTIF('TT '!$D$4:$D$31,TALLY!G8) -> 0 | I8: =COUNTIF('TT '!$D$154:$D$173,TALLY!A8) -> 0 | J8: =COUNTIF('TT '!$D$180:$D$197,TALLY!A8) -> 1 | K8: =COUNTIF('TT '!$D$204:$D$216,TALLY!A8) -> 0 | L8: =COUNTIF('TT '!$D$223:$D$235,TALLY!A8) -> 0 | M8: =COUNTIF('TT '!$D$242:$D$257,TALLY!A8) -> 1 | N8: =COUNTIF('TT '!$D$264:$D$276,TALLY!A8) -> 0 | O8: =COUNTIF([8]TT!$D$36:$D$41,$A8) -> #VALUE! | P8: =COUNTIF('TT '!$D$283:$D$294,TALLY!A8) -> 0 | Q8: =COUNTIF('TT '!$D$301:$D$317,TALLY!A8) -> 0 | R8: =COUNTIF('TT '!$D$324:$D$339,TALLY!A8) -> 0 | S8: =COUNTIF('TT '!$D$346:$D$362,TALLY!A8) -> 0 | T8: =COUNTIF('TT '!$D$369:$D$383,TALLY!A8) -> 1 | U8: =COUNTIF('TT '!$D$390:$D$409,TALLY!A8) -> 0 | V8: =COUNTIF([8]TT!$D$36:$D$41,$A8) -> #VALUE! | W8: =COUNTIF('TT '!$D$416:$D$429,TALLY!A8) -> 0 | X8: =COUNTIF('TT '!$D$436:$D$449,TALLY!A8) -> 0 | Y8: =COUNTIF('TT '!$D$456:$D$474,TALLY!A8) -> 0 | Z8: =COUNTIF('TT '!$D$481:$D$495,TALLY!A8) -> 1 | AA8: =COUNTIF('TT '!$D$502:$D$519,TALLY!A8) -> 0 | AB8: =COUNTIF('TT '!$D$526:$D$540,TALLY!A8) -> 0 | AC8: =COUNTIF([8]TT!$D$36:$D$41,$A8) -> #VALUE! | AD8: =COUNTIF('TT '!$D$547:$D$556,TALLY!A8) -> 0 | AE8: =COUNTIF('TT '!$D$563:$D$577,TALLY!A8) -> 0 | AF8: =COUNTIF('TT '!$D$584:$D$598,TALLY!A8) -> 0 | AG8: =COUNTIF('TT '!$D$605:$D$617,TALLY!A8) -> 0 | AH8: =COUNTIF('TT '!$D$624:$D$636,TALLY!A8) -> 1 | AI8: =COUNTIF('TT '!$D$643:$D$654,TALLY!A8) -> 0 | AJ8: =COUNTIF([8]TT!$D$36:$D$41,$A8) -> #VALUE! | AK8: =CONCATENATE(B8,C8,D8,E8,F8,G8,I8,J8,K8,L8,M8,N8,P8,Q8,R8,S8,T8,U8,W8,X8,Y8,Z8,AA8,AB8,AD8,AE8,AF8,AG8,AH8,AI8) -> 000100010010000010000100000010 | AL8: =SUM(B8:G8) -> 1 | AM8: =SUM(I8:N8) -> 2 | AN8: =SUM(P8:U8) -> 1 | AO8: =SUM(W8:AB8) -> 1 | AP8: =SUM(AD8:AI8) -> 1
A9: ED1-COE | B9: =COUNTIF('TT '!$D$4:$D$31,TALLY!A9) -> 0 | C9: =COUNTIF('TT '!$D$38:$D$49,TALLY!A9) -> 0 | D9: =COUNTIF('TT '!$D$56:$D$78,TALLY!A9) -> 0 | E9: =COUNTIF('TT '!$D$85:$D$105,TALLY!A9) -> 1 | F9: =COUNTIF('TT '!$D$112:$D$126,TALLY!A9) -> 0 | G9: =COUNTIF('TT '!$D$133:$D$147,TALLY!A9) -> 0 | H9: =COUNTIF('TT '!$D$4:$D$31,TALLY!G9) -> 0 | I9: =COUNTIF('TT '!$D$154:$D$173,TALLY!A9) -> 0 | J9: =COUNTIF('TT '!$D$180:$D$197,TALLY!A9) -> 1 | K9: =COUNTIF('TT '!$D$204:$D$216,TALLY!A9) -> 0 | L9: =COUNTIF('TT '!$D$223:$D$235,TALLY!A9) -> 0 | M9: =COUNTIF('TT '!$D$242:$D$257,TALLY!A9) -> 1 | N9: =COUNTIF('TT '!$D$264:$D$276,TALLY!A9) -> 0 | O9: =COUNTIF([8]TT!$D$36:$D$41,$A9) -> #VALUE! | P9: =COUNTIF('TT '!$D$283:$D$294,TALLY!A9) -> 0 | Q9: =COUNTIF('TT '!$D$301:$D$317,TALLY!A9) -> 0 | R9: =COUNTIF('TT '!$D$324:$D$339,TALLY!A9) -> 1 | S9: =COUNTIF('TT '!$D$346:$D$362,TALLY!A9) -> 0 | T9: =COUNTIF('TT '!$D$369:$D$383,TALLY!A9) -> 0 | U9: =COUNTIF('TT '!$D$390:$D$409,TALLY!A9) -> 0 | V9: =COUNTIF([8]TT!$D$36:$D$41,$A9) -> #VALUE! | W9: =COUNTIF('TT '!$D$416:$D$429,TALLY!A9) -> 0 | X9: =COUNTIF('TT '!$D$436:$D$449,TALLY!A9) -> 0 | Y9: =COUNTIF('TT '!$D$456:$D$474,TALLY!A9) -> 0 | Z9: =COUNTIF('TT '!$D$481:$D$495,TALLY!A9) -> 1 | AA9: =COUNTIF('TT '!$D$502:$D$519,TALLY!A9) -> 0 | AB9: =COUNTIF('TT '!$D$526:$D$540,TALLY!A9) -> 0 | AC9: =COUNTIF([8]TT!$D$36:$D$41,$A9) -> #VALUE! | AD9: =COUNTIF('TT '!$D$547:$D$556,TALLY!A9) -> 0 | AE9: =COUNTIF('TT '!$D$563:$D$577,TALLY!A9) -> 0 | AF9: =COUNTIF('TT '!$D$584:$D$598,TALLY!A9) -> 0 | AG9: =COUNTIF('TT '!$D$605:$D$617,TALLY!A9) -> 0 | AH9: =COUNTIF('TT '!$D$624:$D$636,TALLY!A9) -> 0 | AI9: =COUNTIF('TT '!$D$643:$D$654,TALLY!A9) -> 1 | AJ9: =COUNTIF([8]TT!$D$36:$D$41,$A9) -> #VALUE! | AK9: =CONCATENATE(B9,C9,D9,E9,F9,G9,I9,J9,K9,L9,M9,N9,P9,Q9,R9,S9,T9,U9,W9,X9,Y9,Z9,AA9,AB9,AD9,AE9,AF9,AG9,AH9,AI9) -> 000100010010001000000100000001 | AL9: =SUM(B9:G9) -> 1 | AM9: =SUM(I9:N9) -> 2 | AN9: =SUM(P9:U9) -> 1 | AO9: =SUM(W9:AB9) -> 1 | AP9: =SUM(AD9:AI9) -> 1
A10: ED1-EE | B10: =COUNTIF('TT '!$D$4:$D$31,TALLY!A10) -> 1 | C10: =COUNTIF('TT '!$D$38:$D$49,TALLY!A10) -> 0 | D10: =COUNTIF('TT '!$D$56:$D$78,TALLY!A10) -> 0 | E10: =COUNTIF('TT '!$D$85:$D$105,TALLY!A10) -> 1 | F10: =COUNTIF('TT '!$D$112:$D$126,TALLY!A10) -> 0 | G10: =COUNTIF('TT '!$D$133:$D$147,TALLY!A10) -> 0 | H10: =COUNTIF('TT '!$D$4:$D$31,TALLY!G10) -> 0 | I10: =COUNTIF('TT '!$D$154:$D$173,TALLY!A10) -> 0 | J10: =COUNTIF('TT '!$D$180:$D$197,TALLY!A10) -> 1 | K10: =COUNTIF('TT '!$D$204:$D$216,TALLY!A10) -> 0 | L10: =COUNTIF('TT '!$D$223:$D$235,TALLY!A10) -> 0 | M10: =COUNTIF('TT '!$D$242:$D$257,TALLY!A10) -> 0 | N10: =COUNTIF('TT '!$D$264:$D$276,TALLY!A10) -> 0 | O10: =COUNTIF([8]TT!$D$36:$D$41,$A10) -> #VALUE! | P10: =COUNTIF('TT '!$D$283:$D$294,TALLY!A10) -> 1 | Q10: =COUNTIF('TT '!$D$301:$D$317,TALLY!A10) -> 0 | R10: =COUNTIF('TT '!$D$324:$D$339,TALLY!A10) -> 0 | S10: =COUNTIF('TT '!$D$346:$D$362,TALLY!A10) -> 0 | T10: =COUNTIF('TT '!$D$369:$D$383,TALLY!A10) -> 1 | U10: =COUNTIF('TT '!$D$390:$D$409,TALLY!A10) -> 0 | V10: =COUNTIF([8]TT!$D$36:$D$41,$A10) -> #VALUE! | W10: =COUNTIF('TT '!$D$416:$D$429,TALLY!A10) -> 0 | X10: =COUNTIF('TT '!$D$436:$D$449,TALLY!A10) -> 0 | Y10: =COUNTIF('TT '!$D$456:$D$474,TALLY!A10) -> 0 | Z10: =COUNTIF('TT '!$D$481:$D$495,TALLY!A10) -> 1 | AA10: =COUNTIF('TT '!$D$502:$D$519,TALLY!A10) -> 0 | AB10: =COUNTIF('TT '!$D$526:$D$540,TALLY!A10) -> 0 | AC10: =COUNTIF([8]TT!$D$36:$D$41,$A10) -> #VALUE! | AD10: =COUNTIF('TT '!$D$547:$D$556,TALLY!A10) -> 1 | AE10: =COUNTIF('TT '!$D$563:$D$577,TALLY!A10) -> 0 | AF10: =COUNTIF('TT '!$D$584:$D$598,TALLY!A10) -> 0 | AG10: =COUNTIF('TT '!$D$605:$D$617,TALLY!A10) -> 0 | AH10: =COUNTIF('TT '!$D$624:$D$636,TALLY!A10) -> 0 | AI10: =COUNTIF('TT '!$D$643:$D$654,TALLY!A10) -> 0 | AJ10: =COUNTIF([8]TT!$D$36:$D$41,$A10) -> #VALUE! | AK10: =CONCATENATE(B10,C10,D10,E10,F10,G10,I10,J10,K10,L10,M10,N10,P10,Q10,R10,S10,T10,U10,W10,X10,Y10,Z10,AA10,AB10,AD10,AE10,AF10,AG10,AH10,AI10) -> 100100010000100010000100100000 | AL10: =SUM(B10:G10) -> 2 | AM10: =SUM(I10:N10) -> 1 | AN10: =SUM(P10:U10) -> 2 | AO10: =SUM(W10:AB10) -> 1 | AP10: =SUM(AD10:AI10) -> 1
A11: ED1-GEOL | B11: =COUNTIF('TT '!$D$4:$D$31,TALLY!A11) -> 1 | C11: =COUNTIF('TT '!$D$38:$D$49,TALLY!A11) -> 0 | D11: =COUNTIF('TT '!$D$56:$D$78,TALLY!A11) -> 1 | E11: =COUNTIF('TT '!$D$85:$D$105,TALLY!A11) -> 0 | F11: =COUNTIF('TT '!$D$112:$D$126,TALLY!A11) -> 0 | G11: =COUNTIF('TT '!$D$133:$D$147,TALLY!A11) -> 0 | H11: =COUNTIF('TT '!$D$4:$D$31,TALLY!G11) -> 0 | I11: =COUNTIF('TT '!$D$154:$D$173,TALLY!A11) -> 0 | J11: =COUNTIF('TT '!$D$180:$D$197,TALLY!A11) -> 1 | K11: =COUNTIF('TT '!$D$204:$D$216,TALLY!A11) -> 0 | L11: =COUNTIF('TT '!$D$223:$D$235,TALLY!A11) -> 0 | M11: =COUNTIF('TT '!$D$242:$D$257,TALLY!A11) -> 0 | N11: =COUNTIF('TT '!$D$264:$D$276,TALLY!A11) -> 1 | O11: =COUNTIF([8]TT!$D$36:$D$41,$A11) -> #VALUE! | P11: =COUNTIF('TT '!$D$283:$D$294,TALLY!A11) -> 0 | Q11: =COUNTIF('TT '!$D$301:$D$317,TALLY!A11) -> 1 | R11: =COUNTIF('TT '!$D$324:$D$339,TALLY!A11) -> 0 | S11: =COUNTIF('TT '!$D$346:$D$362,TALLY!A11) -> 0 | T11: =COUNTIF('TT '!$D$369:$D$383,TALLY!A11) -> 0 | U11: =COUNTIF('TT '!$D$390:$D$409,TALLY!A11) -> 1 | V11: =COUNTIF([8]TT!$D$36:$D$41,$A11) -> #VALUE! | W11: =COUNTIF('TT '!$D$416:$D$429,TALLY!A11) -> 1 | X11: =COUNTIF('TT '!$D$436:$D$449,TALLY!A11) -> 0 | Y11: =COUNTIF('TT '!$D$456:$D$474,TALLY!A11) -> 0 | Z11: =COUNTIF('TT '!$D$481:$D$495,TALLY!A11) -> 0 | AA11: =COUNTIF('TT '!$D$502:$D$519,TALLY!A11) -> 0 | AB11: =COUNTIF('TT '!$D$526:$D$540,TALLY!A11) -> 0 | AC11: =COUNTIF([8]TT!$D$36:$D$41,$A11) -> #VALUE! | AD11: =COUNTIF('TT '!$D$547:$D$556,TALLY!A11) -> 0 | AE11: =COUNTIF('TT '!$D$563:$D$577,TALLY!A11) -> 1 | AF11: =COUNTIF('TT '!$D$584:$D$598,TALLY!A11) -> 0 | AG11: =COUNTIF('TT '!$D$605:$D$617,TALLY!A11) -> 0 | AH11: =COUNTIF('TT '!$D$624:$D$636,TALLY!A11) -> 1 | AI11: =COUNTIF('TT '!$D$643:$D$654,TALLY!A11) -> 0 | AJ11: =COUNTIF([8]TT!$D$36:$D$41,$A11) -> #VALUE! | AK11: =CONCATENATE(B11,C11,D11,E11,F11,G11,I11,J11,K11,L11,M11,N11,P11,Q11,R11,S11,T11,U11,W11,X11,Y11,Z11,AA11,AB11,AD11,AE11,AF11,AG11,AH11,AI11) -> 101000010001010001100000010010 | AL11: =SUM(B11:G11) -> 2 | AM11: =SUM(I11:N11) -> 2 | AN11: =SUM(P11:U11) -> 2 | AO11: =SUM(W11:AB11) -> 1 | AP11: =SUM(AD11:AI11) -> 2
A12: ED1-GEOM | B12: =COUNTIF('TT '!$D$4:$D$31,TALLY!A12) -> 1 | C12: =COUNTIF('TT '!$D$38:$D$49,TALLY!A12) -> 0 | D12: =COUNTIF('TT '!$D$56:$D$78,TALLY!A12) -> 0 | E12: =COUNTIF('TT '!$D$85:$D$105,TALLY!A12) -> 1 | F12: =COUNTIF('TT '!$D$112:$D$126,TALLY!A12) -> 0 | G12: =COUNTIF('TT '!$D$133:$D$147,TALLY!A12) -> 0 | H12: =COUNTIF('TT '!$D$4:$D$31,TALLY!G12) -> 0 | I12: =COUNTIF('TT '!$D$154:$D$173,TALLY!A12) -> 0 | J12: =COUNTIF('TT '!$D$180:$D$197,TALLY!A12) -> 1 | K12: =COUNTIF('TT '!$D$204:$D$216,TALLY!A12) -> 0 | L12: =COUNTIF('TT '!$D$223:$D$235,TALLY!A12) -> 0 | M12: =COUNTIF('TT '!$D$242:$D$257,TALLY!A12) -> 0 | N12: =COUNTIF('TT '!$D$264:$D$276,TALLY!A12) -> 0 | O12: =COUNTIF([8]TT!$D$36:$D$41,$A12) -> #VALUE! | P12: =COUNTIF('TT '!$D$283:$D$294,TALLY!A12) -> 1 | Q12: =COUNTIF('TT '!$D$301:$D$317,TALLY!A12) -> 0 | R12: =COUNTIF('TT '!$D$324:$D$339,TALLY!A12) -> 0 | S12: =COUNTIF('TT '!$D$346:$D$362,TALLY!A12) -> 0 | T12: =COUNTIF('TT '!$D$369:$D$383,TALLY!A12) -> 0 | U12: =COUNTIF('TT '!$D$390:$D$409,TALLY!A12) -> 0 | V12: =COUNTIF([8]TT!$D$36:$D$41,$A12) -> #VALUE! | W12: =COUNTIF('TT '!$D$416:$D$429,TALLY!A12) -> 1 | X12: =COUNTIF('TT '!$D$436:$D$449,TALLY!A12) -> 0 | Y12: =COUNTIF('TT '!$D$456:$D$474,TALLY!A12) -> 0 | Z12: =COUNTIF('TT '!$D$481:$D$495,TALLY!A12) -> 0 | AA12: =COUNTIF('TT '!$D$502:$D$519,TALLY!A12) -> 0 | AB12: =COUNTIF('TT '!$D$526:$D$540,TALLY!A12) -> 1 | AC12: =COUNTIF([8]TT!$D$36:$D$41,$A12) -> #VALUE! | AD12: =COUNTIF('TT '!$D$547:$D$556,TALLY!A12) -> 0 | AE12: =COUNTIF('TT '!$D$563:$D$577,TALLY!A12) -> 0 | AF12: =COUNTIF('TT '!$D$584:$D$598,TALLY!A12) -> 0 | AG12: =COUNTIF('TT '!$D$605:$D$617,TALLY!A12) -> 0 | AH12: =COUNTIF('TT '!$D$624:$D$636,TALLY!A12) -> 0 | AI12: =COUNTIF('TT '!$D$643:$D$654,TALLY!A12) -> 0 | AJ12: =COUNTIF([8]TT!$D$36:$D$41,$A12) -> #VALUE! | AK12: =CONCATENATE(B12,C12,D12,E12,F12,G12,I12,J12,K12,L12,M12,N12,P12,Q12,R12,S12,T12,U12,W12,X12,Y12,Z12,AA12,AB12,AD12,AE12,AF12,AG12,AH12,AI12) -> 100100010000100000100001000000 | AL12: =SUM(B12:G12) -> 2 | AM12: =SUM(I12:N12) -> 1 | AN12: =SUM(P12:U12) -> 1 | AO12: =SUM(W12:AB12) -> 2 | AP12: =SUM(AD12:AI12) -> 0
A13: ED1-IND | B13: =COUNTIF('TT '!$D$4:$D$31,TALLY!A13) -> 0 | C13: =COUNTIF('TT '!$D$38:$D$49,TALLY!A13) -> 0 | D13: =COUNTIF('TT '!$D$56:$D$78,TALLY!A13) -> 1 | E13: =COUNTIF('TT '!$D$85:$D$105,TALLY!A13) -> 0 | F13: =COUNTIF('TT '!$D$112:$D$126,TALLY!A13) -> 0 | G13: =COUNTIF('TT '!$D$133:$D$147,TALLY!A13) -> 0 | H13: =COUNTIF('TT '!$D$4:$D$31,TALLY!G13) -> 0 | I13: =COUNTIF('TT '!$D$154:$D$173,TALLY!A13) -> 0 | J13: =COUNTIF('TT '!$D$180:$D$197,TALLY!A13) -> 1 | K13: =COUNTIF('TT '!$D$204:$D$216,TALLY!A13) -> 0 | L13: =COUNTIF('TT '!$D$223:$D$235,TALLY!A13) -> 0 | M13: =COUNTIF('TT '!$D$242:$D$257,TALLY!A13) -> 1 | N13: =COUNTIF('TT '!$D$264:$D$276,TALLY!A13) -> 0 | O13: =COUNTIF([8]TT!$D$36:$D$41,$A13) -> #VALUE! | P13: =COUNTIF('TT '!$D$283:$D$294,TALLY!A13) -> 0 | Q13: =COUNTIF('TT '!$D$301:$D$317,TALLY!A13) -> 0 | R13: =COUNTIF('TT '!$D$324:$D$339,TALLY!A13) -> 1 | S13: =COUNTIF('TT '!$D$346:$D$362,TALLY!A13) -> 0 | T13: =COUNTIF('TT '!$D$369:$D$383,TALLY!A13) -> 0 | U13: =COUNTIF('TT '!$D$390:$D$409,TALLY!A13) -> 0 | V13: =COUNTIF([8]TT!$D$36:$D$41,$A13) -> #VALUE! | W13: =COUNTIF('TT '!$D$416:$D$429,TALLY!A13) -> 0 | X13: =COUNTIF('TT '!$D$436:$D$449,TALLY!A13) -> 0 | Y13: =COUNTIF('TT '!$D$456:$D$474,TALLY!A13) -> 0 | Z13: =COUNTIF('TT '!$D$481:$D$495,TALLY!A13) -> 1 | AA13: =COUNTIF('TT '!$D$502:$D$519,TALLY!A13) -> 0 | AB13: =COUNTIF('TT '!$D$526:$D$540,TALLY!A13) -> 0 | AC13: =COUNTIF([8]TT!$D$36:$D$41,$A13) -> #VALUE! | AD13: =COUNTIF('TT '!$D$547:$D$556,TALLY!A13) -> 1 | AE13: =COUNTIF('TT '!$D$563:$D$577,TALLY!A13) -> 0 | AF13: =COUNTIF('TT '!$D$584:$D$598,TALLY!A13) -> 0 | AG13: =COUNTIF('TT '!$D$605:$D$617,TALLY!A13) -> 0 | AH13: =COUNTIF('TT '!$D$624:$D$636,TALLY!A13) -> 0 | AI13: =COUNTIF('TT '!$D$643:$D$654,TALLY!A13) -> 0 | AJ13: =COUNTIF([8]TT!$D$36:$D$41,$A13) -> #VALUE! | AK13: =CONCATENATE(B13,C13,D13,E13,F13,G13,I13,J13,K13,L13,M13,N13,P13,Q13,R13,S13,T13,U13,W13,X13,Y13,Z13,AA13,AB13,AD13,AE13,AF13,AG13,AH13,AI13) -> 001000010010001000000100100000 | AL13: =SUM(B13:G13) -> 1 | AM13: =SUM(I13:N13) -> 2 | AN13: =SUM(P13:U13) -> 1 | AO13: =SUM(W13:AB13) -> 1 | AP13: =SUM(AD13:AI13) -> 1
A14: ED1-MARI | B14: =COUNTIF('TT '!$D$4:$D$31,TALLY!A14) -> 0 | C14: =COUNTIF('TT '!$D$38:$D$49,TALLY!A14) -> 0 | D14: =COUNTIF('TT '!$D$56:$D$78,TALLY!A14) -> 1 | E14: =COUNTIF('TT '!$D$85:$D$105,TALLY!A14) -> 0 | F14: =COUNTIF('TT '!$D$112:$D$126,TALLY!A14) -> 0 | G14: =COUNTIF('TT '!$D$133:$D$147,TALLY!A14) -> 1 | H14: =COUNTIF('TT '!$D$4:$D$31,TALLY!G14) -> 0 | I14: =COUNTIF('TT '!$D$154:$D$173,TALLY!A14) -> 0 | J14: =COUNTIF('TT '!$D$180:$D$197,TALLY!A14) -> 1 | K14: =COUNTIF('TT '!$D$204:$D$216,TALLY!A14) -> 0 | L14: =COUNTIF('TT '!$D$223:$D$235,TALLY!A14) -> 0 | M14: =COUNTIF('TT '!$D$242:$D$257,TALLY!A14) -> 0 | N14: =COUNTIF('TT '!$D$264:$D$276,TALLY!A14) -> 0 | O14: =COUNTIF([8]TT!$D$36:$D$41,$A14) -> #VALUE! | P14: =COUNTIF('TT '!$D$283:$D$294,TALLY!A14) -> 0 | Q14: =COUNTIF('TT '!$D$301:$D$317,TALLY!A14) -> 1 | R14: =COUNTIF('TT '!$D$324:$D$339,TALLY!A14) -> 0 | S14: =COUNTIF('TT '!$D$346:$D$362,TALLY!A14) -> 0 | T14: =COUNTIF('TT '!$D$369:$D$383,TALLY!A14) -> 0 | U14: =COUNTIF('TT '!$D$390:$D$409,TALLY!A14) -> 0 | V14: =COUNTIF([8]TT!$D$36:$D$41,$A14) -> #VALUE! | W14: =COUNTIF('TT '!$D$416:$D$429,TALLY!A14) -> 0 | X14: =COUNTIF('TT '!$D$436:$D$449,TALLY!A14) -> 0 | Y14: =COUNTIF('TT '!$D$456:$D$474,TALLY!A14) -> 0 | Z14: =COUNTIF('TT '!$D$481:$D$495,TALLY!A14) -> 1 | AA14: =COUNTIF('TT '!$D$502:$D$519,TALLY!A14) -> 0 | AB14: =COUNTIF('TT '!$D$526:$D$540,TALLY!A14) -> 0 | AC14: =COUNTIF([8]TT!$D$36:$D$41,$A14) -> #VALUE! | AD14: =COUNTIF('TT '!$D$547:$D$556,TALLY!A14) -> 1 | AE14: =COUNTIF('TT '!$D$563:$D$577,TALLY!A14) -> 0 | AF14: =COUNTIF('TT '!$D$584:$D$598,TALLY!A14) -> 0 | AG14: =COUNTIF('TT '!$D$605:$D$617,TALLY!A14) -> 1 | AH14: =COUNTIF('TT '!$D$624:$D$636,TALLY!A14) -> 0 | AI14: =COUNTIF('TT '!$D$643:$D$654,TALLY!A14) -> 0 | AJ14: =COUNTIF([8]TT!$D$36:$D$41,$A14) -> #VALUE! | AK14: =CONCATENATE(B14,C14,D14,E14,F14,G14,I14,J14,K14,L14,M14,N14,P14,Q14,R14,S14,T14,U14,W14,X14,Y14,Z14,AA14,AB14,AD14,AE14,AF14,AG14,AH14,AI14) -> 001001010000010000000100100100 | AL14: =SUM(B14:G14) -> 2 | AM14: =SUM(I14:N14) -> 1 | AN14: =SUM(P14:U14) -> 1 | AO14: =SUM(W14:AB14) -> 1 | AP14: =SUM(AD14:AI14) -> 2
... A74: ED4-TEL | B74: =COUNTIF('TT '!$D$4:$D$31,TALLY!A74) -> 0 | C74: =COUNTIF('TT '!$D$38:$D$49,TALLY!A74) -> 1 | D74: =COUNTIF('TT '!$D$56:$D$78,TALLY!A74) -> 0 | E74: =COUNTIF('TT '!$D$85:$D$105,TALLY!A74) -> 0 | F74: =COUNTIF('TT '!$D$112:$D$126,TALLY!A74) -> 0 | G74: =COUNTIF('TT '!$D$133:$D$147,TALLY!A74) -> 0 | H74: =COUNTIF('TT '!$D$4:$D$31,TALLY!G74) -> 0 | I74: =COUNTIF('TT '!$D$154:$D$173,TALLY!A74) -> 1 | J74: =COUNTIF('TT '!$D$180:$D$197,TALLY!A74) -> 0 | K74: =COUNTIF('TT '!$D$204:$D$216,TALLY!A74) -> 0 | L74: =COUNTIF('TT '!$D$223:$D$235,TALLY!A74) -> 0 | M74: =COUNTIF('TT '!$D$242:$D$257,TALLY!A74) -> 0 | N74: =COUNTIF('TT '!$D$264:$D$276,TALLY!A74) -> 1 | O74: =COUNTIF([8]TT!$D$36:$D$41,$A74) -> #VALUE! | P74: =COUNTIF('TT '!$D$283:$D$294,TALLY!A74) -> 0 | Q74: =COUNTIF('TT '!$D$301:$D$317,TALLY!A74) -> 0 | R74: =COUNTIF('TT '!$D$324:$D$339,TALLY!A74) -> 0 | S74: =COUNTIF('TT '!$D$346:$D$362,TALLY!A74) -> 0 | T74: =COUNTIF('TT '!$D$369:$D$383,TALLY!A74) -> 0 | U74: =COUNTIF('TT '!$D$390:$D$409,TALLY!A74) -> 1 | V74: =COUNTIF([8]TT!$D$36:$D$41,$A74) -> #VALUE! | W74: =COUNTIF('TT '!$D$416:$D$429,TALLY!A74) -> 0 | X74: =COUNTIF('TT '!$D$436:$D$449,TALLY!A74) -> 0 | Y74: =COUNTIF('TT '!$D$456:$D$474,TALLY!A74) -> 0 | Z74: =COUNTIF('TT '!$D$481:$D$495,TALLY!A74) -> 0 | AA74: =COUNTIF('TT '!$D$502:$D$519,TALLY!A74) -> 1 | AB74: =COUNTIF('TT '!$D$526:$D$540,TALLY!A74) -> 0 | AC74: =COUNTIF([8]TT!$D$36:$D$41,$A74) -> #VALUE! | AD74: =COUNTIF('TT '!$D$547:$D$556,TALLY!A74) -> 0 | AE74: =COUNTIF('TT '!$D$563:$D$577,TALLY!A74) -> 0 | AF74: =COUNTIF('TT '!$D$584:$D$598,TALLY!A74) -> 1 | AG74: =COUNTIF('TT '!$D$605:$D$617,TALLY!A74) -> 0 | AH74: =COUNTIF('TT '!$D$624:$D$636,TALLY!A74) -> 0 | AI74: =COUNTIF('TT '!$D$643:$D$654,TALLY!A74) -> 0 | AJ74: =COUNTIF([8]TT!$D$36:$D$41,$A74) -> #VALUE! | AK74: =CONCATENATE(B74,C74,D74,E74,F74,G74,I74,J74,K74,L74,M74,N74,P74,Q74,R74,S74,T74,U74,W74,X74,Y74,Z74,AA74,AB74,AD74,AE74,AF74,AG74,AH74,AI74) -> 010000100001000001000010001000 | AL74: =SUM(B74:G74) -> 1 | AM74: =SUM(I74:N74) -> 2 | AN74: =SUM(P74:U74) -> 1 | AO74: =SUM(W74:AB74) -> 1 | AP74: =SUM(AD74:AI74) -> 1

Sheet Lecturers
A1: Unnamed: 0 | B1: Unnamed: 6 | C1: No of students | E1: BSC. AEROSPACE ENG., Year 1 | F1: Unnamed: 2 | G1: Unnamed: 4
A2: =_xlfn.CONCAT(E2,",",D2) -> AERO 157,ED1-AERO | B2: Oppong David Kofi | C2: 70 | D2: ED1-AERO | E2: AERO 157 | G2: INTRODUCTION TO AVIATION TECHNOLOGY
A3: =_xlfn.CONCAT(E3,",",D3) -> CE 155,ED1-AERO | B3: =[9]Sheet1!$G$13 -> Appiah-Brempong Miriam | C3: 70 | D3: =D2 -> ED1-AERO | E3: CE 155 | G3: ENVIRONMENTAL STUDIES
A4: =_xlfn.CONCAT(E4,",",D4) -> EE 151,ED1-AERO | B4: Oteng Gyasi Kwame | C4: 70 | D4: =D3 -> ED1-AERO | E4: EE 151 | G4: APPLIED ELECTRICITY
A5: =_xlfn.CONCAT(E5,",",D5) -> ENGL 157,ED1-AERO | B5: =[9]Sheet1!$G$15 -> Appiah Franklin Benjamin | C5: 70 | D5: =D4 -> ED1-AERO | E5: ENGL 157 | G5: COMMUNICATION SKILLS I
A6: =_xlfn.CONCAT(E6,",",D6) -> MATH 151,ED1-AERO | B6: Fosu Gabriel Obed | C6: 70 | D6: =D5 -> ED1-AERO | E6: MATH 151 | G6: ALGEBRA
A7: =_xlfn.CONCAT(E7,",",D7) -> ME 157,ED1-AERO | B7: Sackey Michael Nii | C7: 70 | D7: =D6 -> ED1-AERO | E7: ME 157 | G7: INTRODUCTION TO INFORMATION TECHNOLOGY
A8: =_xlfn.CONCAT(E8,",",D8) -> ME 159,ED1-AERO | B8: =$B$470 -> Oppong Tawiah Peter | C8: 70 | D8: =D7 -> ED1-AERO | E8: ME 159 | G8: TECHNICAL DRAWING
A9: =_xlfn.CONCAT(E9,",",D9) -> ME 281,ED2-AERO | B9: Amoabeng Kofi Owura | C9: 74 | D9: ED2-AERO | E9: ME 281 | G9: ENGINEERING MATERIALS I
A10: =_xlfn.CONCAT(E10,",",D10) -> CENG 291,ED2-AERO | B10: Oppong David Kofi | C10: 74 | D10: =D9 -> ED2-AERO | E10: CENG 291 | G10: ENGINEERING IN SOCIETY
A11: =_xlfn.CONCAT(E11,",",D11) -> AERO 293,ED2-AERO | B11: Oppong David Kofi | C11: 74 | D11: =D10 -> ED2-AERO | E11: AERO 293 | G11: AEROSPACE ENGINEERING VACATION TRAINING I
A12: =_xlfn.CONCAT(E12,",",D12) -> ME 255,ED2-AERO | B12: Agyei Agyemang Anthony | C12: 74 | D12: =D11 -> ED2-AERO | E12: ME 255 | G12: STRENGTH OF MATERIALS I
A13: =_xlfn.CONCAT(E13,",",D13) -> ENGL 263,ED2-AERO | B13: =[9]Sheet2!$G$10 -> Yeboah Philomena Ama Okyeso | C13: 74 | D13: =D12 -> ED2-AERO | E13: ENGL 263 | G13: LITERATURE IN ENGLISH I
A14: =_xlfn.CONCAT(E14,",",D14) -> MATH 251,ED2-AERO | B14: Wireko Fredrick Asenso | C14: 74 | D14: =D13 -> ED2-AERO | E14: MATH 251 | G14: DIFFERENTIAL EQUATIONS
A15: =_xlfn.CONCAT(E15,",",D15) -> ME 251,ED2-AERO | B15: Fiagbe Yesuenyeagbe Atsu Kwabla | C15: 74 | D15: =D14 -> ED2-AERO | E15: ME 251 | G15: INTRODUCTION TO FLUID MECHANICS
A16: =_xlfn.CONCAT(E16,",",D16) -> ME 261,ED2-AERO | B16: Ampofo Joshua | C16: 74 | D16: =D15 -> ED2-AERO | E16: ME 261 | G16: =[9]Sheet2!$E$14 -> ENGINEERING MECHANICS II:DYNAMICS
A17: =_xlfn.CONCAT(E17,",",D17) -> ME 295,ED2-AERO | B17: D. K. Oppong | C17: 74 | D17: =D16 -> ED2-AERO | E17: ME 295 | G17: MECHANICAL ENGINEERING LAB. I
A18: =_xlfn.CONCAT(E18,",",D18) -> ECON 151,ED3-AERO | B18: Takyi Paul Owusu | C18: 76 | D18: ED3-AERO | E18: ECON 151 | G18: INTRODUCTION TO ECONOMICS I
A19: =_xlfn.CONCAT(E19,",",D19) -> AERO 393,ED3-AERO | B19: Oppong David Kofi | C19: 76 | D19: =D18 -> ED3-AERO | E19: AERO 393 | G19: AEROSPACE ENGINEERING VACATION TRAINING II
A20: =_xlfn.CONCAT(E20,",",D20) -> AERO 351,ED3-AERO | B20: Bofah Kwasi Kete | C20: 76 | D20: =D19 -> ED3-AERO | E20: AERO 351 | G20: AERODYNAMICS I
A21: =_xlfn.CONCAT(E21,",",D21) -> AERO 391,ED3-AERO | B21: K. K. Bofah | C21: 76 | D21: =D20 -> ED3-AERO | E21: AERO 391 | G21: AEROSPACE INDUSTRY AND ENGINEERING
A22: =_xlfn.CONCAT(E22,",",D22) -> AERO 395,ED3-AERO | B22: Oppong David Kofi | C22: 76 | D22: =D21 -> ED3-AERO | E22: AERO 395 | G22: AEROSPACE ENGINEERING LAB. I
A23: =_xlfn.CONCAT(E23,",",D23) -> MATH 351,ED3-AERO | B23: Borkor Reindorf Nartey | C23: 76 | D23: =D22 -> ED3-AERO | E23: MATH 351 | G23: NUMERICAL ANALYSIS
A24: =_xlfn.CONCAT(E24,",",D24) -> STAT 253,ED3-AERO | B24: C. F. A. Yirenkyi | C24: 76 | D24: =D23 -> ED3-AERO | E24: STAT 253 | G24: PROBABILITY AND STATISTICS
A25: =_xlfn.CONCAT(E25,",",D25) -> ME 363,ED3-AERO | B25: F. W. Adam | C25: 76 | D25: =D24 -> ED3-AERO | E25: ME 363 | G25: AUTOMATIC CONTROL I
A26: =_xlfn.CONCAT(E26,",",D26) -> AERO 473,ED4-AERO | B26: =[9]Sheet4!G8 -> Oppong David Kofi | C26: 61 | D26: ED4-AERO | E26: =[9]Sheet4!B8 -> AERO 473 | G26: =[9]Sheet4!E8 -> AEROSPACE VEHICLE DESIGN
A27: =_xlfn.CONCAT(E27,",",D27) -> AERO 483,ED4-AERO | B27: =[9]Sheet4!G9 -> Oppong David Kofi | C27: 61 | D27: =D26 -> ED4-AERO | E27: =[9]Sheet4!B9 -> AERO 483 | G27: =[9]Sheet4!E9 -> AVIONICS
A28: =_xlfn.CONCAT(E28,",",D28) -> AERO 491,ED4-AERO | B28: =[9]Sheet4!G10 -> Takyi Gabriel | C28: 61 | D28: =D27 -> ED4-AERO | E28: =[9]Sheet4!B10 -> AERO 491 | G28: =[9]Sheet4!E10 -> AVIATION BUSINESS MANAGEMENT
A29: =_xlfn.CONCAT(E29,",",D29) -> AERO 493,ED4-AERO | B29: =[9]Sheet4!G11 -> Oppong David Kofi | C29: 61 | D29: =D28 -> ED4-AERO | E29: =[9]Sheet4!B11 -> AERO 493 | G29: =[9]Sheet4!E11 -> AEROSPACE ENGINEERING VACATION TRAINING III
A30: =_xlfn.CONCAT(E30,",",D30) -> AERO 495,ED4-AERO | B30: =[9]Sheet4!G12 -> Oppong Tawiah Peter | C30: 61 | D30: =D29 -> ED4-AERO | E30: =[9]Sheet4!B12 -> AERO 495 | G30: =[9]Sheet4!E12 -> AIRCRAFT MAINTENANCE ENGINEERING
A31: =_xlfn.CONCAT(E31,",",D31) -> AERO 497,ED4-AERO | B31: =[9]Sheet4!G13 -> Tay Godwin Fabiola Kwaku | C31: 61 | D31: =D30 -> ED4-AERO | E31: =[9]Sheet4!B13 -> AERO 497 | G31: =[9]Sheet4!E13 -> PROJECT I
A32: =_xlfn.CONCAT(E32,",",D32) -> ME 451,ED4-AERO | B32: =[9]Sheet4!G14 -> Opoku Richard | C32: 61 | D32: =D31 -> ED4-AERO | E32: =[9]Sheet4!B14 -> ME 451 | G32: =[9]Sheet4!E14 -> BEHAVIOUR OF REAL FLUIDS
A33: =_xlfn.CONCAT(E33,",",D33) -> ME 465,ED4-AERO | B33: =[9]Sheet4!G15 -> Sekyere Charles Kofi Kafui | C33: 61 | D33: =D32 -> ED4-AERO | E33: =[9]Sheet4!B15 -> ME 465 | G33: =[9]Sheet4!E15 -> AIR CONDITIONING AND REFRIGERATION
A34: =_xlfn.CONCAT(E34,",",D34) -> ME 467,ED4-AERO | B34: =[9]Sheet4!G16 -> Quansah David Ato | C34: 61 | D34: =D33 -> ED4-AERO | E34: =[9]Sheet4!B16 -> ME 467 | G34: =[9]Sheet4!E16 -> RENEWABLE ENERGY CONVERSION
A35: =_xlfn.CONCAT(E35,",",D35) -> ME 473,ED4-AERO | B35: =[9]Sheet4!G17 -> Afriyie Nyarko Frank Kwabena | C35: 61 | D35: =D34 -> ED4-AERO | E35: =[9]Sheet4!B17 -> ME 473 | G35: =[9]Sheet4!E17 -> COMPUTER AIDED DESIGN AND MANUFACTURING
A36: =_xlfn.CONCAT(E36,",",D36) -> ME 499,ED4-AERO | B36: =[9]Sheet4!G18 -> Mensah Lena Dzifa | C36: 61 | D36: =D35 -> ED4-AERO | E36: =[9]Sheet4!B18 -> ME 499 | G36: =[9]Sheet4!E18 -> OPERATIONS RESEARCH
A37: =_xlfn.CONCAT(E37,",",D37) -> ,ED4-AERO | C37: 61 | D37: =D36 -> ED4-AERO | E37: =[9]Sheet4!B19 | G37: =[9]Sheet4!E19 -> 0
A38: =_xlfn.CONCAT(E38,",",D38) -> AE 153,ED1-AE | B38: =[9]Sheet4!G22 -> Bessah Enoch | C38: 126 | D38: ED1-AE | E38: =[9]Sheet4!B22 -> AE 153 | G38: =[9]Sheet4!E22 -> AGRIC. METEOROLOGY AND CLIMATOLOGY
A39: =_xlfn.CONCAT(E39,",",D39) -> EE 151,ED1-AE | B39: =[9]Sheet4!G23 -> Prah II Nicholas Kwesi | C39: 126 | D39: =D38 -> ED1-AE | E39: =[9]Sheet4!B23 -> EE 151 | G39: =[9]Sheet4!E23 -> APPLIED ELECTRICITY
A40: =_xlfn.CONCAT(E40,",",D40) -> ENGL 157,ED1-AE | B40: =[9]Sheet4!G24 -> Yeboah Philomena Ama Okyeso | C40: 126 | D40: =D39 -> ED1-AE | E40: =[9]Sheet4!B24 -> ENGL 157 | G40: =[9]Sheet4!E24 -> COMMUNICATION SKILLS I
...

Sheet ROOMS
A1: College of Engineering
A2: Available Rooms
A3: Rooms | B3: Exam Capacity | E3: Lecturers
A4: LT | B4: 60 | C4: COHORT A1 | D4: BAMFO KWAKYE A | E4: 1
A5: RMA | B5: 48 | E5: 1
A6: RMB | B6: 48 | E6: 1
A7: VSLA | B7: 100 | E7: 2
A8: 206 | B8: 48 | C8: COHORT A2 | E8: 1
A9: 303 | B9: 60 | E9: 1
A10: 304 | B10: 50 | E10: 1
A11: N1 | B11: 50 | C11: COHORT A3 | E11: 1
A12: N2 | B12: 48 | E12: 1 | F12: =SUM(B4:B12) -> 512
A13: PB001 | B13: 90 | C13: COHORT B1 | D13: PETROLEUM BUILDING B | E13: 2
A14: PB020 | B14: 90 | E14: 2
A15: PB014 | B15: 90 | E15: 2
A16: PB012
A17: PB008 | B17: 60 | E17: 2
A18: PB201 | B18: 90 | C18: COHORT B2 | E18: 2
A19: PB214 | B19: 90 | E19: 2
A20: PB212 | B20: 50 | E20: 1
A21: PB208 | B21: 60 | E21: 1 | F21: =SUM(B13:B21) -> 620
A22: VCR | B22: 50 | C22: COHORT C1 | D22: EXAMS OFFICE C | E22: 1
A23: ECR | B23: 50 | E23: 1
A24: A110 | B24: 60 | E24: 1
A25: EA | B25: 60 | C25: COHORT C2 | E25: 1
A26: NAF1 | B26: 90 | E26: 2 | F26: =SUM(B22:B26) -> 310
A27: NEB-SF | B27: 170 | C27: COHORT D1 | D27: NEB D | E27: 3
A28: NEB-TF | B28: 170 | C28: COHORT D2 | E28: 3
A29: NEB-FF1 | B29: 110 | C29: COHORT D3 | E29: 2
A30: NEB-FF2 | B30: 60 | E30: 1 | F30: =SUM(B27:B30) -> 510
E31: 1
A32: Total | B32: =SUM(B4:B30) -> 1952 | E32: =SUM(E4:E30) -> 39

Sheet WATER (2)
A1: College of Engineering
A2: Available Rooms | L2: College of Engineering
B3: INVIGILATORS | E3: TOTAL BOTLES | F3: Bottles x 6S + 1 | G3: Total Pack | H3: TOTAL BOTTLES | I3: TOTAL BOTTLES FOR PERIOD | J3: ROOM USAGE | L3: Available Rooms
A4: Rooms | B4: TA | C4: LT | D4: ATTD | E4: PER SESSION | F4: TT BOTTLES | G4: PACKS PER DAY | H4: OVERALL | L4: Rooms | M4: Name | N4: Contact | O4: Signature | P4: Bottles/Packs Collected
A5: LT | B5: 1 | C5: 1 | D5: 1 | E5: =SUM(B5:D5) -> 3 | F5: =E5*6 -> 18 | G5: =F5/16 -> 1.125 | I5: =E5*J5 -> 90 | J5: 30 | L5: LT | P5: 3btls
A6: RM A | B6: 1 | C6: 1 | D6: 1 | E6: =SUM(C6:D6) -> 2 | F6: =E6*6 -> 12 | G6: =F6/16 -> 0.75 | I6: =E6*J6 -> 60 | J6: 30 | L6: RMA | P6: 3btl
A7: RM B | B7: 1 | C7: 1 | D7: 1 | E7: =SUM(C7:D7) -> 2 | F7: =E7*6 -> 12 | G7: =F7/16 -> 0.75 | I7: =E7*J7 -> 60 | J7: 30 | L7: RMB | P7: 3btls
A8: 206 | B8: 1 | C8: 1 | D8: 1 | E8: =SUM(C8:D8) -> 2 | F8: =E8*6 -> 12 | G8: =F8/16 -> 0.75 | I8: =E8*J8 -> 52 | J8: 26 | L8: 206 | P8: 3btls
A9: 303 | B9: 1 | C9: 1 | D9: 1 | E9: =SUM(C9:D9) -> 2 | F9: =E9*6 -> 12 | G9: =F9/16 -> 0.75 | I9: =E9*J9 -> 60 | J9: 30 | L9: 303 | P9: 3btls
A10: 304 | B10: 1 | C10: 1 | D10: 1 | E10: =SUM(C10:D10) -> 2 | F10: =E10*6 -> 12 | G10: =F10/16 -> 0.75 | I10: =E10*J10 -> 52 | J10: 26 | L10: 304 | P10: 3btls
A11: EA | B11: 1 | C11: 1 | D11: 1 | E11: =SUM(C11:D11) -> 2 | F11: =E11*6 -> 12 | G11: =F11/16 -> 0.75 | I11: =E11*J11 -> 56 | J11: 28 | L11: EA | P11: 3btls
A12: NAF1 | B12: 1 | C12: 2 | D12: 1 | E12: =SUM(C12:D12) -> 3 | F12: =E12*6 -> 18 | G12: =F12/16 -> 1.125 | I12: =E12*J12 -> 90 | J12: 30 | L12: NAF1 | P12: 3btls
A13: A110 | B13: 1 | C13: 1 | D13: 1 | E13: =SUM(C13:D13) -> 2 | F13: =E13*6 -> 12 | G13: =F13/16 -> 0.75 | I13: =E13*J13 -> 56 | J13: 28 | L13: A110 | P13: 3btls
A14: VSLA | B14: 1 | C14: 2 | D14: 1 | E14: =SUM(C14:D14) -> 3 | F14: =E14*6 -> 18 | G14: =F14/16 -> 1.125 | I14: =E14*J14 -> 90 | J14: 30 | L14: VSLA | P14: 3btls
A15: PB001 | B15: 1 | C15: 2 | D15: 1 | E15: =SUM(C15:D15) -> 3 | F15: =E15*6 -> 18 | G15: =F15/16 -> 1.125 | I15: =E15*J15 -> 90 | J15: 30 | L15: PB001 | P15: 3btls
A16: PB020 | B16: 1 | C16: 2 | D16: 1 | E16: =SUM(C16:D16) -> 3 | F16: =E16*6 -> 18 | G16: =F16/16 -> 1.125 | I16: =E16*J16 -> 90 | J16: 30 | L16: PB020 | P16: 3btls
A17: PB014 | B17: 1 | C17: 2 | D17: 1 | E17: =SUM(C17:D17) -> 3 | F17: =E17*6 -> 18 | G17: =F17/16 -> 1.125 | I17: =E17*J17 -> 90 | J17: 30 | L17: PB014 | P17: 3btls
A18: PB008 | B18: 1 | C18: 2 | D18: 1 | E18: =SUM(C18:D18) -> 3 | F18: =E18*6 -> 18 | G18: =F18/16 -> 1.125 | I18: =E18*J18 -> 90 | J18: 30 | L18: PB008 | P18: 3btls
A19: PB201 | B19: 1 | C19: 2 | D19: 1 | E19: =SUM(C19:D19) -> 3 | F19: =E19*6 -> 18 | G19: =F19/16 -> 1.125 | I19: =E19*J19 -> 90 | J19: 30 | L19: PB201 | P19: 3btls
A20: PB214 | B20: 1 | C20: 2 | D20: 1 | E20: =SUM(C20:D20) -> 3 | F20: =E20*6 -> 18 | G20: =F20/16 -> 1.125 | I20: =E20*J20 -> 90 | J20: 30 | L20: PB214 | P20: 3btls
A21: PB212 | B21: 1 | C21: 1 | D21: 1 | E21: =SUM(C21:D21) -> 2 | F21: =E21*6 -> 12 | G21: =F21/16 -> 0.75 | I21: =E21*J21 -> 60 | J21: 30 | L21: PB212 | P21: 3btls
A22: PB208 | B22: 1 | C22: 1 | D22: 1 | E22: =SUM(C22:D22) -> 2 | F22: =E22*6 -> 12 | G22: =F22/16 -> 0.75 | I22: =E22*J22 -> 60 | J22: 30 | L22: PB208 | P22: 3btls
... A29: NEB-TF | B29: 2 | C29: 3 | D29: 2 | E29: =SUM(C29:D29) -> 5 | F29: =E29*6 -> 30 | G29: =F29/16 -> 1.875 | I29: =E29*J29 -> 150 | J29: 30 | L29: NEB-TF | P29: 5btls
A30: Computer Based | E30: 3 | F30: 80 | G30: 4 | H30: 10pks | I30: 80 | J30: 1 | L30: Computer Based | P30: 10pks
A31: Biometric | E31: 18 | F31: 126 | G31: 6 | H31: 8pks | I31: =6*F31 -> 756 | J31: 32 | L31: Biometric | P31: 8pks
A32: NEB OFFICE | E32: 9 | F32: 64 | G32: 2 | H32: 4pks | I32: =6*F32 -> 384 | J32: 32 | L32: NEB OFFICE | P32: 4pks
A33: EXAMS OFFICE | E33: 17 | F33: 112 | G33: 6 | H33: 7pks | I33: =6*F33 -> 672 | J33: 32 | L33: EXAMS OFFICE | P33: 8pks
A34: SCANTRON | E34: 6 | F34: 32 | G34: 6 | H34: 2pks | I34: =6*F34 -> 192 | J34: 32 | L34: SCANTRON | P34: 2pks
A35: BAMFO KWAKYE | E35: 9 | F35: 64 | G35: 4 | H35: 4pks | I35: =6*F35 -> 384 | J35: 32 | L35: BAMFO KWAKYE | P35: 4pks
A36: PB | E36: 9 | F36: 64 | G36: 2 | H36: 4pks | I36: =6*F36 -> 384 | J36: 32 | L36: PB | P36: 4pks
A37: SECURITY | E37: 23 | F37: 161 | G37: =F37/16 -> 10.0625 | H37: 10pks | I37: =6*F37 -> 966 | J37: 32 | L37: SECURITY | P37: 10pks
A38: NURSES | E38: 2 | F38: 8 | G38: =F38/16 -> 0.5 | H38: 8btls | I38: =6*F38 -> 48 | J38: 32 | L38: NURSES | P38: 12tls
E39: 0
A40: Totals Per Session | C40: =SUM(C5:C39) -> 39 | D40: =SUM(D5:D39) -> 29 | E40: =SUM(E5:E39) -> 165 | F40: =SUM(F5:F39) -> 1125 | G40: =SUM(G5:G38) -> 66.4375
A41: Totals Per Day | F41: ~ 74 packs a day (16 bottles per pack) | H41: ~ 370 Overall packs (16 bottles per pack) | L41: Total Collected for the day
L42: Total to be collected for the day
L43: Overall total left
L44: Total bottles for a Day

Sheet COMBINED_ATTD_INV (2)
A2: ROOM NO | B2: INVIGILATORS | C2: ATTENDANTS | D2: TAs | E2: DATE | F2: SESSION
A3: LT | B3: =VLOOKUP(A3,[10]Schedule_Invigilators!$A$2:$B$27,2,FALSE) -> Prince Yaw Andoh | C3: =VLOOKUP(A3,'[10]COMBINED_ATTD_INV (3)'!$A$351:$E$1175,2,FALSE) -> Mohammed Bakang// | D3: Kwabena Owusu-Osei | E3: Monday, 24 Febuary 2025 | F3: Session, 1 (8:15 AM - 9:15 AM)
A4: RM A | B4: =VLOOKUP(A4,[10]Schedule_Invigilators!$A$2:$B$27,2,FALSE) -> Prosper Akaba | C4: =VLOOKUP(A4,'[10]COMBINED_ATTD_INV (3)'!$A$351:$E$1175,2,FALSE) -> Derrick Owusu Mensah// | D4: Elesie Joseph | E4: Monday, 24 Febuary 2025 | F4: Session, 1 (8:15 AM - 9:15 AM)
A5: RM B | B5: =VLOOKUP(A5,[10]Schedule_Invigilators!$A$2:$B$27,2,FALSE) -> Casper Adenutsi | C5: =VLOOKUP(A5,'[10]COMBINED_ATTD_INV (3)'!$A$351:$E$1175,2,FALSE) -> Mercy Nimako// | D5: John Kwesi Baidoo | E5: Monday, 24 Febuary 2025 | F5: Session, 1 (8:15 AM - 9:15 AM)
A6: VSLA | B6: =VLOOKUP(A6,[10]Schedule_Invigilators!$A$2:$B$27,2,FALSE) -> Kenneth Adomako Tutu / Joshua Ampofo | C6: =VLOOKUP(A6,'[10]COMBINED_ATTD_INV (3)'!$A$351:$E$1175,2,FALSE) -> Issaka Ali Sambo/Paul Dery/ | D6: Agyapong Akosua Adubea | E6: Monday, 24 Febuary 2025 | F6: Session, 1 (8:15 AM - 9:15 AM)
A7: 206 | B7: =VLOOKUP(A7,[10]Schedule_Invigilators!$A$2:$B$27,2,FALSE) -> Emmanuel Appiah-Adjei | C7: =VLOOKUP(A7,'[10]COMBINED_ATTD_INV (3)'!$A$351:$E$1175,2,FALSE) -> Edward Kpetege// | D7: Roland Ashie | E7: Monday, 24 Febuary 2025 | F7: Session, 1 (8:15 AM - 9:15 AM)
A8: 303 | B8: =VLOOKUP(A8,[10]Schedule_Invigilators!$A$2:$B$27,2,FALSE) -> Jonathan Atuquaye Quaye / Eliel Keelson | C8: =VLOOKUP(A8,'[10]COMBINED_ATTD_INV (3)'!$A$351:$E$1175,2,FALSE) -> Benjamin Opoku Atuahene// | D8: Malick Ebiasah | E8: Monday, 24 Febuary 2025 | F8: Session, 1 (8:15 AM - 9:15 AM)
A9: 304 | B9: =VLOOKUP(A9,[10]Schedule_Invigilators!$A$2:$B$27,2,FALSE) -> Bernard Konadu Amoah | C9: =VLOOKUP(A9,'[10]COMBINED_ATTD_INV (3)'!$A$351:$E$1175,2,FALSE) -> Eric Soku// | D9: Ernest Kofi Nduakoh | E9: Monday, 24 Febuary 2025 | F9: Session, 1 (8:15 AM - 9:15 AM)
A10: N1 | B10: =VLOOKUP(A10,[10]Schedule_Invigilators!$A$2:$B$27,2,FALSE) -> James Dzisi Gadze | C10: =VLOOKUP(A10,'[10]COMBINED_ATTD_INV (3)'!$A$351:$E$1175,2,FALSE) -> Marian Bemma// | D10: Ofori Rockson Minkah | E10: Monday, 24 Febuary 2025 | F10: Session, 1 (8:15 AM - 9:15 AM)
A11: N2 | B11: =VLOOKUP(A11,[10]Schedule_Invigilators!$A$2:$B$27,2,FALSE) -> Samuel Boahen | C11: =VLOOKUP(A11,'[10]COMBINED_ATTD_INV (3)'!$A$351:$E$1175,2,FALSE) -> Derrick Amoateng// | D11: Joseph Dela Aziafor | E11: Monday, 24 Febuary 2025 | F11: Session, 1 (8:15 AM - 9:15 AM)
A12: PB001 | B12: =VLOOKUP(A12,[10]Schedule_Invigilators!$A$2:$B$27,2,FALSE) -> Martinson Addo Nartey / Benjamin Afotey | C12: =VLOOKUP(A12,'[10]COMBINED_ATTD_INV (3)'!$A$351:$E$1175,2,FALSE) -> John Ofosu// | D12: BELLO RAPHAEL AMETEFE KOMLA | E12: Monday, 24 Febuary 2025 | F12: Session, 1 (8:15 AM - 9:15 AM)
A13: PB020 | B13: =VLOOKUP(A13,[10]Schedule_Invigilators!$A$2:$B$27,2,FALSE) -> Vincent Kofi Abaka Acquaah / Matthew Coffie Wilson | C13: =VLOOKUP(A13,'[10]COMBINED_ATTD_INV (3)'!$A$351:$E$1175,2,FALSE) -> Owusu Stephen Akuoku/Evans Korletey/ | D13: Wiafe Yaw Karikari | E13: Monday, 24 Febuary 2025 | F13: Session, 1 (8:15 AM - 9:15 AM)
A14: PB014 | B14: =VLOOKUP(A14,[10]Schedule_Invigilators!$A$2:$B$27,2,FALSE) -> Prince Odame / Martin Kesse | C14: =VLOOKUP(A14,'[10]COMBINED_ATTD_INV (3)'!$A$351:$E$1175,2,FALSE) -> Kofi Bentum/Linda Berko/ | D14: Agblemiawo Marvin Selasi | E14: Monday, 24 Febuary 2025 | F14: Session, 1 (8:15 AM - 9:15 AM)
A15: PB201 | B15: =VLOOKUP(A15,[10]Schedule_Invigilators!$A$2:$B$27,2,FALSE) -> Sefakor Dogbe / Y. A. Sokama-Neuyam | C15: =VLOOKUP(A15,'[10]COMBINED_ATTD_INV (3)'!$A$351:$E$1175,2,FALSE) -> Joseph Benneth Kankam// | D15: Michael Bansah | E15: Monday, 24 Febuary 2025 | F15: Session, 1 (8:15 AM - 9:15 AM)
A16: PB214 | B16: =VLOOKUP(A16,[10]Schedule_Invigilators!$A$2:$B$27,2,FALSE) -> Godfred Boahen / Nancy Anataba Kyorku Dzikunu-Bansah | C16: =VLOOKUP(A16,'[10]COMBINED_ATTD_INV (3)'!$A$351:$E$1175,2,FALSE) -> Desmond Adu-Yeboah/Fatawu Yakubu/ | D16: Ibrahim Arhin | E16: Monday, 24 Febuary 2025 | F16: Session, 1 (8:15 AM - 9:15 AM)
A17: PB212 | B17: =VLOOKUP(A17,[10]Schedule_Invigilators!$A$2:$B$27,2,FALSE) -> Samuel Osah | C17: =VLOOKUP(A17,'[10]COMBINED_ATTD_INV (3)'!$A$351:$E$1175,2,FALSE) -> Clement Appiah// | D17: YEBOAH HAPPY OWUSU ANTWI | E17: Monday, 24 Febuary 2025 | F17: Session, 1 (8:15 AM - 9:15 AM)
A18: PB208 | B18: =VLOOKUP(A18,[10]Schedule_Invigilators!$A$2:$B$27,2,FALSE) -> Evans Amponsah / Albert Kwame Kwaw | C18: =VLOOKUP(A18,'[10]COMBINED_ATTD_INV (3)'!$A$351:$E$1175,2,FALSE) -> Godfred Appiah// | D18: Owusu Boakye Gideon | E18: Monday, 24 Febuary 2025 | F18: Session, 1 (8:15 AM - 9:15 AM)
A19: VCR | B19: =VLOOKUP(A19,[10]Schedule_Invigilators!$A$2:$B$27,2,FALSE) -> Blestmond Afrifa Brako | C19: =VLOOKUP(A19,'[10]COMBINED_ATTD_INV (3)'!$A$351:$E$1175,2,FALSE) -> Ruth Adwubi Sarfo// | D19: Elita Mawuse Djokotoe Dzontoh | E19: Monday, 24 Febuary 2025 | F19: Session, 1 (8:15 AM - 9:15 AM)
