Workbook
Name CLASS: #REF!
Name CLASS: TT!$D$233:$D$501
Name CODE: #REF!
Name CODE: #REF!
Name CODE: #REF!
Name COURSE_NAME: #REF!
Name COURSE_NAME: #REF!
Name COURSE_NAME: #REF!
Name EA: #REF!
Name ED3_PCE: TT!$D$299:$D$312
Name ED3_TEL: TT!$D$270:$D$277
Name ED4_IND: TT!$D$270:$D$277
Name EXAMINER: #REF!
Name EXAMINER: #REF!
Name EXAMINER: #REF!
Name hy: #REF!
Name po: #REF!
Name room_no: #REF!
Name ROOM_NO.: #REF!
Name ROOM_NO.: #REF!
Name ROOM_NO.: #REF!
Name STDS: #REF!
Name STDS: #REF!
Name STDS: #REF!
Name TO_PRT: #REF!
Name TO_PRT: #REF!
Name TO_PRT: #REF!
Name Total_F1: '[1]TT (Working)'!$D$668:$D$683
Name Total_F1: [2]TT!$D$540:$D$555
Name Total_F1: TT!$D$562:$D$686
Name Total_F1_1: '[3]TT (Values)'!$D$176:$D$194
Name Total_F1_1: '[3]TT (Values)'!$D$176:$D$194
Name Total_F1_1: [4]TT!$D$206:$D$219
Name Total_F1_1: [4]TT!$D$206:$D$219
Name Total_F1_2: [4]TT!$D$225:$D$227
Name Total_F1_2: [4]TT!$D$225:$D$227
Name Total_F1_3: [4]TT!$D$245:$D$261
Name Total_F1_3: [4]TT!$D$245:$D$261
Name Total_F2: '[1]TT (Working)'!$D$690:$D$712
Name Total_F2: [2]TT!$D$561:$D$580
Name Total_F2: TT!$D$581:$D$609
Name Total_F2_1: '[3]TT (Values)'!$D$450:$D$473
Name Total_F2_1: '[3]TT (Values)'!$D$450:$D$473
Name Total_F2_1: [4]TT!$D$503:$D$520
Name Total_F2_1: [4]TT!$D$503:$D$520
Name Total_F2_2: '[3]TT (Values)'!$D$479:$D$483
Name Total_F2_2: '[3]TT (Values)'!$D$479:$D$483
Name Total_F2_2: [4]TT!$D$526:$D$536
Name Total_F2_2: [4]TT!$D$526:$D$536
Name Total_F2_3: '[3]TT (Values)'!$D$489:$D$496
Name Total_F2_3: '[3]TT (Values)'!$D$489:$D$496
Name Total_F2_3: [4]TT!$D$542:$D$559
Name Total_F2_3: [4]TT!$D$542:$D$559
Name Total_F3: '[1]TT (Working)'!$D$718:$D$731
Name Total_F3: [2]TT!$D$586:$D$597
Name Total_F3: TT!$D$615:$D$625
Name Total_F3_1: '[3]TT (Values)'!$D$740:$D$753
Name Total_F3_1: '[3]TT (Values)'!$D$740:$D$753
Name Total_F3_1: [4]TT!$D$801:$D$817
Name Total_F3_1: [4]TT!$D$801:$D$817

Sheet TT
A1: Monday, 7 July 2025 | I1: =CONCATENATE(A1,",",B1,",",E1) -> Monday, 7 July 2025,,
A2: =[2]SESSIONS!$K$1 -> Session, 1 (8:15 AM - 9:15 AM) | I2: =CONCATENATE(A2,",",B2,",",E2) -> Session, 1 (8:15 AM - 9:15 AM),,
A3: CODE | B3: COURSE NAME | C3: EXAMINER | D3: CLASS | E3: # STDS | G3: TO PRT | I3: =CONCATENATE(A3,",",B3,",",E3) -> CODE ,COURSE NAME ,# STDS
A4: ENGL 158 | B4: =IFERROR(VLOOKUP($I4,'[5]Combined Data'!$D$1:$H$534,2,FALSE),0) -> Communication Skills II | C4: {=VLOOKUP(I4:I25,'Combined Data'!A1:E547,3,FALSE)} -> Yeboah Philomena Ama Okyeso | D4: ED1-AERO | E4: {=VLOOKUP(I4:I25,combined_data!A1:D549,4,FALSE)} -> 75 | F4: Computer Based | G4: =E4*1.1 -> 82.5 | I4: =CONCATENATE(A4,",",D4) -> ENGL 158,ED1-AERO
A5: ENGL 158 | B5: =IFERROR(VLOOKUP($I5,'[5]Combined Data'!$D$1:$H$534,2,FALSE),0) -> Communication Skills II | C5: Yeboah Philomena Ama Okyeso | D5: ED1-AE | E5: 157 | G5: =E5*1.1 -> 172.7 | I5: =CONCATENATE(A5,",",D5) -> ENGL 158,ED1-AE
A6: ENGL 158 | B6: =IFERROR(VLOOKUP($I6,'[5]Combined Data'!$D$1:$H$534,2,FALSE),0) -> Communication Skills II | C6: Z. Osei | D6: ED1-BME | E6: 86 | G6: =E6*1.1 -> 94.6 | I6: =CONCATENATE(A6,",",D6) -> ENGL 158,ED1-BME
A7: ENGL 158 | B7: =IFERROR(VLOOKUP($I7,'[5]Combined Data'!$D$1:$H$534,2,FALSE),0) -> Communication Skills II | C7: Yeboah Philomena Ama Okyeso | D7: ED1-CHE | E7: 155 | G7: =E7*1.1 -> 170.5 | I7: =CONCATENATE(A7,",",D7) -> ENGL 158,ED1-CHE
A8: ENGL 158 | B8: =IFERROR(VLOOKUP($I8,'[5]Combined Data'!$D$1:$H$534,2,FALSE),0) -> Communication Skills II | C8: B. Ampong | D8: ED1-COE | E8: 255 | G8: =E8*1.1 -> 280.5 | I8: =CONCATENATE(A8,",",D8) -> ENGL 158,ED1-COE
A9: ENGL 158 | B9: =IFERROR(VLOOKUP($I9,'[5]Combined Data'!$D$1:$H$534,2,FALSE),0) -> Communication Skills II | C9: Yeboah Philomena Ama Okyeso | D9: ED1-IND | E9: 88 | G9: =E9*1.1 -> 96.8 | I9: =CONCATENATE(A9,",",D9) -> ENGL 158,ED1-IND
A10: ME 282 | B10: =IFERROR(VLOOKUP($I10,'[5]Combined Data'!$D$1:$H$534,2,FALSE),0) -> Mechanical Engineering Materials II | C10: Arthur Emmanuel Kwesi | D10: ED2-AE | E10: 111 | F10: NAF1/EA/A110/ECR | G10: =E10*1.1 -> 122.1 | H10: 40/25/25/25 | I10: =CONCATENATE(A10,",",D10) -> ME 282,ED2-AE
A11: PE 264 | B11: =IFERROR(VLOOKUP($I11,'[5]Combined Data'!$D$1:$H$534,2,FALSE),0) -> Principles of Land Surveying and Hydrographic Science | C11: Asante Cosmas Yaw | D11: ED2-PETE | E11: 82 | F11: VSLA/303/LT | G11: =E11*1.1 -> 90.2 | H11: 40/25/20 | I11: =CONCATENATE(A11,",",D11) -> PE 264,ED2-PETE
A12: CE 262 | B12: =IFERROR(VLOOKUP($I12,'[5]Combined Data'!$D$1:$H$534,2,FALSE),0) -> Soil and Rocks Mechanics Laboratory | C12: Dzikunu-Bansah Nancy Anataba Kyorku | D12: ED2-CE | E12: 227 | F12: PB001/PB020/PB014/PB008/PB201/PB214 | G12: =E12*1.1 -> 249.7 | H12: 40/40/40/30/40/40 | I12: =CONCATENATE(A12,",",D12) -> CE 262,ED2-CE
A13: CE 462 | B13: =IFERROR(VLOOKUP($I13,'[5]Combined Data'!$D$1:$H$534,2,FALSE),0) -> Construction Management | C13: Obeng Daniel Atuah | D13: ED4-CE | E13: 255 | F13: PB001/PB020/PB014/PB008/PB201/PB214/PB212 | G13: =E13*1.1 -> 280.5 | H13: 40/40/40/30/40/40/25 | I13: =CONCATENATE(A13,",",D13) -> CE 462,ED4-CE
A14: AERO 452 | B14: =IFERROR(VLOOKUP($I14,'[5]Combined Data'!$D$1:$H$534,2,FALSE),0) -> Aerodynamics II | C14: Bofah Kwasi Kete | D14: ED4-AERO | E14: 75 | F14: NEB-FF1/NEB-FF2 | G14: =E14*1.1 -> 82.5 | H14: 50/25 | I14: =CONCATENATE(A14,",",D14) -> AERO 452,ED4-AERO
A15: AME 368 | B15: =IFERROR(VLOOKUP($I15,'[5]Combined Data'!$D$1:$H$534,2,FALSE),0) -> Automotive Spark-Ignition Engines | C15: Abu Frimpong Solomon | D15: ED3-AUTO | E15: 32 | F15: RMA/RMB | G15: =E15*1.1 -> 35.2 | H15: 16/16 | I15: =CONCATENATE(A15,",",D15) -> AME 368,ED3-AUTO
A16: BME 374 | B16: =IFERROR(VLOOKUP($I16,'[5]Combined Data'!$D$1:$H$534,2,FALSE),0) -> Biomedical Optics | C16: Kotei Addison Eric Clement | D16: ED3-BME | E16: 85 | F16: VSLA/303/LT | G16: =E16*1.1 -> 93.5 | H16: 40/25/20 | I16: =CONCATENATE(A16,",",D16) -> BME 374,ED3-BME
A17: COE 372 | B17: =IFERROR(VLOOKUP($I17,'[5]Combined Data'!$D$1:$H$534,2,FALSE),0) -> Digital Systems Design II | C17: Boateng Kwame Osei | D17: ED3-COE | E17: 170 | F17: NEB-TF/NEB-SF/NEB-FF2 | G17: =E17*1.1 -> 187 | H17: 75/75/20 | I17: =CONCATENATE(A17,",",D17) -> COE 372,ED3-COE
A18: COE 382 | B18: =IFERROR(VLOOKUP($I18,'[5]Combined Data'!$D$1:$H$534,2,FALSE),0) -> Digital Computer Design | C18: Boateng Kwame Osei | D18: ED3-EE | E18: 29 | F18: N1 | G18: =E18*1.1 -> 31.9 | H18: 29 | I18: =CONCATENATE(A18,",",D18) -> COE 382,ED3-EE
A19: CHE 464 | B19: =IFERROR(VLOOKUP($I19,'[5]Combined Data'!$D$1:$H$534,2,FALSE),0) -> Adsorption Separation Process Technology | C19: Ohemeng-Boahen Godfred | D19: ED4-PCE | E19: 50 | F19: NEB-FF1 | G19: =E19*1.1 -> 55 | H19: 50 | I19: =CONCATENATE(A19,",",D19) -> CHE 464,ED4-PCE
A20: ME 478 | B20: =IFERROR(VLOOKUP($I20,'[5]Combined Data'!$D$1:$H$534,2,FALSE),0) -> Production Engineering II | C20: Obeng George Yaw | D20: ED4-ME | E20: 53 | F20: PB208/PB212 | G20: =E20*1.1 -> 58.3 | H20: 30/25 | I20: =CONCATENATE(A20,",",D20) -> ME 478,ED4-ME
A21: COE 486 | B21: =IFERROR(VLOOKUP($I21,'[5]Combined Data'!$D$1:$H$534,2,FALSE),0) -> Introduction to VLSI | C21: Agbemenu Andrew Selasi | D21: ED4-EE | E21: 7 | F21: N1 | G21: =E21*1.1 -> 7.7 | H21: 7 | I21: =CONCATENATE(A21,",",D21) -> COE 486,ED4-EE
A22: COE 486 | B22: =IFERROR(VLOOKUP($I22,'[5]Combined Data'!$D$1:$H$534,2,FALSE),0) -> Introduction to VLSI | C22: Agbemenu Andrew Selasi | D22: ED4-COE | E22: 14 | F22: PB208 | G22: =E22*1.1 -> 15.4 | H22: 10 | I22: =CONCATENATE(A22,",",D22) -> COE 486,ED4-COE
A23: GE 272 | B23: =IFERROR(VLOOKUP($I23,'[5]Combined Data'!$D$1:$H$534,2,FALSE),0) -> Engineering Survey II | C23: Arko-Adjei Anthony | D23: ED2-GEOM | E23: 122 | F23: NAF1/EA/A110/ECR | G23: =E23*1.1 -> 134.2 | H23: 40/30/30/25 | I23: =CONCATENATE(A23,",",D23) -> GE 272,ED2-GEOM
A24: CHE 470 | B24: =IFERROR(VLOOKUP($I24,'[5]Combined Data'!$D$1:$H$534,2,FALSE),0) -> Pharmaceutical Technology | C24: Johnson Raphael | D24: ED4-CHE | E24: 71 | F24: RMA/RMB/206/N2 | G24: =E24*1.1 -> 78.1 | H24: 20/20/15/15 | I24: =CONCATENATE(A24,",",D24) -> CHE 470,ED4-CHE
A25: TE 374 | B25: COMPUTER NETWORKING | C25: K. A.-B. Opare | D25: ED3-TEL | E25: 142 | F25: NEB-TF/NEB-SF | G25: =E25*1.1 -> 156.2 | H25: 72/70 | I25: =CONCATENATE(A25,",",D25) -> TE 374,ED3-TEL
D27: Total M1 | E27: =SUM(E10:E25) -> 1525 | I27: =CONCATENATE(A27,",",D27) -> ,Total M1
I28: =CONCATENATE(A28,",",D28) -> ,
I29: =CONCATENATE(A29,",",D29) -> ,
A30: Monday, 7 July 2025 | I30: =CONCATENATE(A30,",",D30) -> Monday, 7 July 2025,
A31: =[2]SESSIONS!$K$2 -> Session, 2 (10:00 AM - 11:00 AM) | I31: =CONCATENATE(A31,",",D31) -> Session, 2 (10:00 AM - 11:00 AM),
A32: CODE | B32: COURSE NAME | C32: EXAMINER | D32: CLASS | E32: # STDS | F32: ROOM NO. | G32: TO PRT | I32: =CONCATENATE(A32,",",D32) -> CODE ,CLASS
A33: ENGL 158 | B33: =IFERROR(VLOOKUP($I33,'[5]Combined Data'!$D$1:$H$534,2,FALSE),0) -> Communication Skills II | C33: {=VLOOKUP(I33:I50,'Combined Data'!A1:E547,3,FALSE)} -> P.G. Asamoah | D33: ED1-CE | E33: {=VLOOKUP(I33:I50,combined_data!A1:D549,4,FALSE)} -> 260 | F33: Computer Based | G33: =E33*1.1 -> 286 | I33: =CONCATENATE(A33,",",D33) -> ENGL 158,ED1-CE
A34: ENGL 158 | B34: =IFERROR(VLOOKUP($I34,'[5]Combined Data'!$D$1:$H$534,2,FALSE),0) -> Communication Skills II | C34: Yeboah Philomena Ama Okyeso | D34: ED1-EE | E34: 378 | G34: =E34*1.1 -> 415.8 | I34: =CONCATENATE(A34,",",D34) -> ENGL 158,ED1-EE
A35: ENGL 158 | B35: =IFERROR(VLOOKUP($I35,'[5]Combined Data'!$D$1:$H$534,2,FALSE),0) -> Communication Skills II | C35: Sarfo-Adu Kwasi | D35: ED1-AUTO | E35: 78 | G35: =E35*1.1 -> 85.8 | I35: =CONCATENATE(A35,",",D35) -> ENGL 158,ED1-AUTO
A36: ENGL 158 | B36: =IFERROR(VLOOKUP($I36,'[5]Combined Data'!$D$1:$H$534,2,FALSE),0) -> Communication Skills II | C36: Yeboah Philomena Ama Okyeso | D36: ED1-GEOL | E36: 156 | G36: =E36*1.1 -> 171.6 | I36: =CONCATENATE(A36,",",D36) -> ENGL 158,ED1-GEOL
A37: ENGL 158 | B37: =IFERROR(VLOOKUP($I37,'[5]Combined Data'!$D$1:$H$534,2,FALSE),0) -> Communication Skills II | C37: Yeboah Philomena Ama Okyeso | D37: ED1-PCE | E37: 59 | G37: =E37*1.1 -> 64.9 | I37: =CONCATENATE(A37,",",D37) -> ENGL 158,ED1-PCE
A38: AERO 374 | B38: =IFERROR(VLOOKUP($I38,'[5]Combined Data'!$D$1:$H$534,2,FALSE),0) -> Aircraft Performance and Design | C38: Agyei Agyemang Anthony | D38: ED3-AERO | E38: 63 | F38: LT/RMA/RMB | G38: =E38*1.1 -> 69.3 | H38: 23/20/20 | I38: =CONCATENATE(A38,",",D38) -> AERO 374,ED3-AERO
A39: GED 368 | B39: =IFERROR(VLOOKUP($I39,'[5]Combined Data'!$D$1:$H$534,2,FALSE),0) -> GIS Applications | C39: Appiah-Adjei Emmanuel Kwame | D39: ED3-GEOL | E39: 105 | F39: VSLA/303/304/LT | G39: =E39*1.1 -> 115.5 | H39: 40/25/20/20 | I39: =CONCATENATE(A39,",",D39) -> GED 368,ED3-GEOL
A40: METE 252 | B40: =IFERROR(VLOOKUP($I40,'[5]Combined Data'!$D$1:$H$534,2,FALSE),0) -> Metallurgical Rate Processes/Surface Phenomena | C40: Gikunoo Emmanuel | D40: ED2-METE | E40: 86 | F40: VSLA/N1/N2 | G40: =E40*1.1 -> 94.6 | H40: 40/25/21 | I40: =CONCATENATE(A40,",",D40) -> METE 252,ED2-METE
A41: GED 476 | B41: =IFERROR(VLOOKUP($I41,'[5]Combined Data'!$D$1:$H$534,2,FALSE),0) -> Groundwater Development | C41: Ali Bukari | D41: ED4-GEOL | E41: 142 | F41: PB001/PB020/PB014/PB008 | G41: =E41*1.1 -> 156.2 | H41: 39/39/39/25 | I41: =CONCATENATE(A41,",",D41) -> GED 476,ED4-GEOL
...

Sheet Sheet1
A1: Monday, 7 July 2025
A2: Session, 1 (8:15 AM - 9:15 AM)
A3: CODE | B3: COURSE NAME | C3: EXAMINER | D3: CLASS | E3: # STDS | G3: TO PRT
A4: ENGL 158 | B4: Communication Skills II | C4: Yeboah Philomena Ama Okyeso | D4: ED1-AERO | E4: 75 | F4: Computer Based | G4: 82.5
A5: ENGL 158 | B5: Communication Skills II | C5: Yeboah Philomena Ama Okyeso | D5: ED1-AE | E5: 157 | F5: Computer Based | G5: 172.7
A6: ENGL 158 | B6: Communication Skills II | C6: Z. Osei | D6: ED1-BME | E6: 86 | F6: Computer Based | G6: 94.6
A7: ENGL 158 | B7: Communication Skills II | C7: Yeboah Philomena Ama Okyeso | D7: ED1-CHE | E7: 155 | F7: Computer Based | G7: 170.5
A8: ENGL 158 | B8: Communication Skills II | C8: B. Ampong | D8: ED1-COE | E8: 255 | F8: Computer Based | G8: 280.5
A9: ENGL 158 | B9: Communication Skills II | C9: Yeboah Philomena Ama Okyeso | D9: ED1-IND | E9: 88 | F9: Computer Based | G9: 96.8
A10: ME 282 | B10: Mechanical Engineering Materials II | C10: Arthur Emmanuel Kwesi | D10: ED2-AE | E10: 111 | F10: NAF1/EA/A110/ECR | G10: 122.1 | H10: 40/25/25/25
A11: PE 264 | B11: Principles of Land Surveying and Hydrographic Science | C11: Asante Cosmas Yaw | D11: ED2-PETE | E11: 82 | F11: VSLA/303/LT | G11: 90.2 | H11: 40/25/20
A12: CE 262 | B12: Soil and Rocks Mechanics Laboratory | C12: Dzikunu-Bansah Nancy Anataba Kyorku | D12: ED2-CE | E12: 227 | F12: PB001/PB020/PB014/PB008/PB201/PB214 | G12: 249.7 | H12: 40/40/40/30/40/40
A13: CE 462 | B13: Construction Management | C13: Obeng Daniel Atuah | D13: ED4-CE | E13: 255 | F13: PB001/PB020/PB014/PB008/PB201/PB214/PB212 | G13: 280.5 | H13: 40/40/40/30/40/40/25
A14: AERO 452 | B14: Aerodynamics II | C14: Bofah Kwasi Kete | D14: ED4-AERO | E14: 75 | F14: NEB-FF1/NEB-FF2 | G14: 82.5 | H14: 50/25
A15: AME 368 | B15: Automotive Spark-Ignition Engines | C15: Abu Frimpong Solomon | D15: ED3-AUTO | E15: 32 | F15: RMA/RMB | G15: 35.2 | H15: 16/16
A16: BME 374 | B16: Biomedical Optics | C16: Kotei Addison Eric Clement | D16: ED3-BME | E16: 85 | F16: VSLA/303/LT | G16: 93.5 | H16: 40/25/20
A17: COE 372 | B17: Digital Systems Design II | C17: Boateng Kwame Osei | D17: ED3-COE | E17: 170 | F17: NEB-TF/NEB-SF/NEB-FF2 | G17: 187 | H17: 75/75/20
A18: COE 382 | B18: Digital Computer Design | C18: Boateng Kwame Osei | D18: ED3-EE | E18: 29 | F18: N1 | G18: 31.9 | H18: 29
A19: CHE 464 | B19: Adsorption Separation Process Technology | C19: Ohemeng-Boahen Godfred | D19: ED4-PCE | E19: 50 | F19: NEB-FF1 | G19: 55 | H19: 50
A20: ME 478 | B20: Production Engineering II | C20: Obeng George Yaw | D20: ED4-ME | E20: 53 | F20: PB208/PB212 | G20: 58.3 | H20: 30/25
A21: COE 486 | B21: Introduction to VLSI | C21: Agbemenu Andrew Selasi | D21: ED4-EE | E21: 7 | F21: N1 | G21: 7.7 | H21: 7
A22: COE 486 | B22: Introduction to VLSI | C22: Agbemenu Andrew Selasi | D22: ED4-COE | E22: 14 | F22: PB208 | G22: 15.4 | H22: 10
A23: GE 272 | B23: Engineering Survey II | C23: Arko-Adjei Anthony | D23: ED2-GEOM | E23: 122 | F23: NAF1/EA/A110/ECR | G23: 134.2 | H23: 40/30/30/25
A24: CHE 470 | B24: Pharmaceutical Technology | C24: Johnson Raphael | D24: ED4-CHE | E24: 71 | F24: RMA/RMB/206/N2 | G24: 78.1 | H24: 20/20/15/15
A25: TE 374 | B25: COMPUTER NETWORKING | C25: K. A.-B. Opare | D25: ED3-TEL | E25: 142 | F25: NEB-TF/NEB-SF | G25: 156.2 | H25: 72/70
D27: Total M1 | E27: 1525
A30: Monday, 7 July 2025
A31: Session, 2 (10:00 AM - 11:00 AM)
A32: CODE | B32: COURSE NAME | C32: EXAMINER | D32: CLASS | E32: # STDS | F32: ROOM NO. | G32: TO PRT
A33: ENGL 158 | B33: Communication Skills II | C33: P.G. Asamoah | D33: ED1-CE | E33: 260 | F33: Computer Based | G33: 286
A34: ENGL 158 | B34: Communication Skills II | C34: Yeboah Philomena Ama Okyeso | D34: ED1-EE | E34: 378 | F34: Computer Based | G34: 415.8
A35: ENGL 158 | B35: Communication Skills II | C35: Sarfo-Adu Kwasi | D35: ED1-AUTO | E35: 78 | F35: Computer Based | G35: 85.8
A36: ENGL 158 | B36: Communication Skills II | C36: Yeboah Philomena Ama Okyeso | D36: ED1-GEOL | E36: 156 | F36: Computer Based | G36: 171.6
A37: ENGL 158 | B37: Communication Skills II | C37: Yeboah Philomena Ama Okyeso | D37: ED1-PCE | E37: 59 | F37: Computer Based | G37: 64.9
A38: AERO 374 | B38: Aircraft Performance and Design | C38: Agyei Agyemang Anthony | D38: ED3-AERO | E38: 63 | F38: LT/RMA/RMB | G38: 69.3 | H38: 23/20/20
A39: GED 368 | B39: GIS Applications | C39: Appiah-Adjei Emmanuel Kwame | D39: ED3-GEOL | E39: 105 | F39: VSLA/303/304/LT | G39: 115.5 | H39: 40/25/20/20
A40: METE 252 | B40: Metallurgical Rate Processes/Surface Phenomena | C40: Gikunoo Emmanuel | D40: ED2-METE | E40: 86 | F40: VSLA/N1/N2 | G40: 94.6 | H40: 40/25/21
A41: GED 476 | B41: Groundwater Development | C41: Ali Bukari | D41: ED4-GEOL | E41: 142 | F41: PB001/PB020/PB014/PB008 | G41: 156.2 | H41: 39/39/39/25
A42: BME 462 | B42: Biomechanics II | C42: Odame Prince | D42: ED4-BME | E42: 62 | F42: RMA/RMB/206 | G42: 68.2 | H42: 20/20/22
A43: TE 258 | B43: Microprocessors | C43: Agyemang Justice Owusu | D43: ED2-TEL | E43: 147 | F43: NEB-TF | G43: 161.7 | H43: 147
...

Sheet TALLY
B1: M | I1: T | P1: W | W1: H | AD1: F
B2: =[2]FREQ!$B2/1900 -> 0.74736842 | C2: =[2]FREQ!$B3/1900 -> 0.83526316 | D2: =[2]FREQ!$B4/1900 -> 0.82578947 | E2: =[2]FREQ!$B5/1900 -> 0.58789474 | F2: =[2]FREQ!$B6/1900 -> 0.88947368 | G2: =[2]FREQ!$B7/1900 -> 0.76473684 | H2: =[2]FREQ!$B8/1900 -> 0.74 | I2: =[2]FREQ!$B10/1900 -> 0.87526316 | J2: =[2]FREQ!$B11/1900 -> 0.92789474 | K2: =[2]FREQ!$B12/1900 -> 0.90526316 | L2: =[2]FREQ!$B13/1900 -> 0.94526316 | M2: =[2]FREQ!$B14/1900 -> 0.93894737 | N2: =[2]FREQ!$B15/1900 -> 0.89736842 | O2: =[2]FREQ!$B16/1900 -> 0.86684211 | P2: =[2]FREQ!$B18/1900 -> 0.84210526 | Q2: =[2]FREQ!$B19/1900 -> 1.0115789 | R2: =[2]FREQ!$B20/1900 -> 0.90368421 | S2: =[2]FREQ!$B21/1900 -> 0.74631579 | T2: =[2]FREQ!$B22/1900 -> 0.96736842 | U2: =[2]FREQ!$B23/1900 -> 0.90578947 | V2: =[2]FREQ!$B24/1900 -> 0.96631579 | W2: =[2]FREQ!$B26/1900 -> 0.87789474 | X2: =[2]FREQ!$B27/1900 -> 0.88736842 | Y2: =[2]FREQ!$B28/1900 -> 0.87631579 | Z2: =[2]FREQ!$B29/1900 -> 0.95368421 | AA2: =[2]FREQ!$B30/1900 -> 0.95368421 | AB2: =[2]FREQ!$B30/1900 -> 0.95368421 | AC2: =[2]FREQ!$B30/1900 -> 0.95368421 | AD2: =[2]FREQ!$B34/1900 -> 0.93315789 | AE2: =[2]FREQ!$B35/1900 -> 0.80684211 | AF2: =[2]FREQ!$B36/1900 -> 0.80263158 | AG2: =[2]FREQ!$B37/1900 -> 0.83473684 | AH2: =[2]FREQ!$B38/1900 -> 0.80526316 | AI2: =[2]FREQ!$B39/1900 -> 0.83578947 | AJ2: =[2]FREQ!$B40/1900 -> 0
B3: S1 | C3: S2 | D3: S3 | E3: S4 | F3: S5 | G3: S6 | H3: S7 | I3: S1 | J3: S2 | K3: S3 | L3: S4 | M3: S5 | N3: S6 | O3: S7 | P3: S1 | Q3: S2 | R3: S3 | S3: S4 | T3: S5 | U3: S6 | V3: S7 | W3: S1 | X3: S2 | Y3: S3 | Z3: S4 | AA3: S5 | AB3: S6 | AC3: S7 | AD3: S1 | AE3: S2 | AF3: S3 | AG3: S4 | AH3: S5 | AI3: S6 | AJ3: S7 | AL3: M | AM3: T | AN3: W | AO3: H | AP3: F
A4: ED1-AE | B4: =COUNTIF(TT!$D$4:$D$25,TALLY!A4) -> 1 | C4: =COUNTIF(TT!$D$33:$D$50,TALLY!A4) -> 0 | D4: =COUNTIF(TT!$D$57:$D$75,TALLY!A4) -> 0 | E4: =COUNTIF(TT!$D$82:$D$95,TALLY!A4) -> 1 | F4: =COUNTIF(TT!$D$103:$D$112,TALLY!A4) -> 0 | G4: =COUNTIF(TT!$D$120:$D$130,TALLY!A4) -> 0 | H4: =COUNTIF(TT!$D$138:$D$153,TALLY!A4) -> 0 | I4: =COUNTIF(TT!$D$160:$D$170,TALLY!A4) -> 0 | J4: =COUNTIF(TT!$D$177:$D$187,TALLY!A4) -> 1 | K4: =COUNTIF(TT!$D$194:$D$206,TALLY!A4) -> 0 | L4: =COUNTIF(TT!$D$215:$D$226,TALLY!A4) -> 1 | M4: =COUNTIF(TT!$D$234:$D$243,TALLY!A4) -> 0 | N4: =COUNTIF(TT!$D$250:$D$262,TALLY!A4) -> 0 | O4: =COUNTIF(TT!$D$270:$D$277,TALLY!A4) -> 0 | P4: =COUNTIF(TT!$D$284:$D$293,TALLY!A4) -> 0 | Q4: =COUNTIF(TT!$D$300:$D$313,TALLY!A4) -> 1 | R4: =COUNTIF(TT!$D$320:$D$333,TALLY!A4) -> 0 | S4: =COUNTIF(TT!$D$342:$D$352,TALLY!A4) -> 0 | T4: =COUNTIF(TT!$D$359:$D$376,TALLY!A4) -> 0 | U4: =COUNTIF(TT!$D$383:$D$398,TALLY!A4) -> 0 | V4: =COUNTIF(TT!$D$405:$D$424,TALLY!A4) -> 1 | W4: =COUNTIF(TT!$D$432:$D$442,TALLY!A4) -> 0 | X4: =COUNTIF(TT!$D$449:$D$460,TALLY!A4) -> 0 | Y4: =COUNTIF(TT!$D$467:$D$476,TALLY!A4) -> 1 | Z4: =COUNTIF(TT!$D$483:$D$500,TALLY!A4) -> 0 | AA4: =COUNTIF(TT!$D$507:$D$522,TALLY!A4) -> 0 | AB4: =COUNTIF(TT!$D$529:$D$540,TALLY!A4) -> 0 | AC4: =COUNTIF(TT!$D$546:$D$555,TALLY!A4) -> 0 | AD4: =COUNTIF(TT!$D$563:$D$573,TALLY!A4) -> 0 | AE4: =COUNTIF(TT!$D$582:$D$609,TALLY!A4) -> 1 | AF4: =COUNTIF(TT!$D$615:$D$625,TALLY!A4) -> 0 | AG4: =COUNTIF(TT!$D$635:$D$648,TALLY!A4) -> 0 | AH4: =COUNTIF(TT!$D$655:$D$668,TALLY!A4) -> 0 | AI4: =COUNTIF(TT!$D$675:$D$687,TALLY!A4) -> 0 | AK4: ED1-AE | AL4: =SUM($B4:$H4) -> 2 | AM4: =SUM(I4:O4) -> 2 | AN4: =SUM(P4:V4) -> 2 | AO4: =SUM(W4:AA4) -> 1 | AP4: =SUM(AD4:AJ4) -> 1 | AQ4: =SUM(AL4:AP4) -> 8
A5: ED1-AERO | B5: =COUNTIF(TT!$D$4:$D$25,TALLY!A5) -> 1 | C5: =COUNTIF(TT!$D$33:$D$50,TALLY!A5) -> 0 | D5: =COUNTIF(TT!$D$57:$D$75,TALLY!A5) -> 0 | E5: =COUNTIF(TT!$D$82:$D$95,TALLY!A5) -> 0 | F5: =COUNTIF(TT!$D$103:$D$112,TALLY!A5) -> 0 | G5: =COUNTIF(TT!$D$120:$D$130,TALLY!A5) -> 0 | H5: =COUNTIF(TT!$D$138:$D$153,TALLY!A5) -> 0 | I5: =COUNTIF(TT!$D$160:$D$170,TALLY!A5) -> 0 | J5: =COUNTIF(TT!$D$177:$D$187,TALLY!A5) -> 1 | K5: =COUNTIF(TT!$D$194:$D$206,TALLY!A5) -> 0 | L5: =COUNTIF(TT!$D$215:$D$226,TALLY!A5) -> 1 | M5: =COUNTIF(TT!$D$234:$D$243,TALLY!A5) -> 0 | N5: =COUNTIF(TT!$D$250:$D$262,TALLY!A5) -> 0 | O5: =COUNTIF(TT!$D$270:$D$277,TALLY!A5) -> 0 | P5: =COUNTIF(TT!$D$284:$D$293,TALLY!A5) -> 0 | Q5: =COUNTIF(TT!$D$300:$D$313,TALLY!A5) -> 0 | R5: =COUNTIF(TT!$D$320:$D$333,TALLY!A5) -> 0 | S5: =COUNTIF(TT!$D$342:$D$352,TALLY!A5) -> 1 | T5: =COUNTIF(TT!$D$359:$D$376,TALLY!A5) -> 0 | U5: =COUNTIF(TT!$D$383:$D$398,TALLY!A5) -> 0 | V5: =COUNTIF(TT!$D$405:$D$424,TALLY!A5) -> 0 | W5: =COUNTIF(TT!$D$432:$D$442,TALLY!A5) -> 1 | X5: =COUNTIF(TT!$D$449:$D$460,TALLY!A5) -> 0 | Y5: =COUNTIF(TT!$D$467:$D$476,TALLY!A5) -> 0 | Z5: =COUNTIF(TT!$D$483:$D$500,TALLY!A5) -> 0 | AA5: =COUNTIF(TT!$D$507:$D$522,TALLY!A5) -> 0 | AB5: =COUNTIF(TT!$D$529:$D$540,TALLY!A5) -> 1 | AC5: =COUNTIF(TT!$D$546:$D$555,TALLY!A5) -> 0 | AD5: =COUNTIF(TT!$D$563:$D$573,TALLY!A5) -> 0 | AE5: =COUNTIF(TT!$D$582:$D$609,TALLY!A5) -> 0 | AF5: =COUNTIF(TT!$D$615:$D$625,TALLY!A5) -> 1 | AG5: =COUNTIF(TT!$D$635:$D$648,TALLY!A5) -> 0 | AH5: =COUNTIF(TT!$D$655:$D$668,TALLY!A5) -> 0 | AI5: =COUNTIF(TT!$D$675:$D$687,TALLY!A5) -> 0 | AK5: ED1-AERO | AL5: =SUM($B5:$H5) -> 1 | AM5: =SUM(I5:O5) -> 2 | AN5: =SUM(P5:V5) -> 1 | AO5: =SUM(W5:AA5) -> 1 | AP5: =SUM(AD5:AJ5) -> 1 | AQ5: =SUM(AL5:AP5) -> 6
A6: ED1-AUTO | B6: =COUNTIF(TT!$D$4:$D$25,TALLY!A6) -> 0 | C6: =COUNTIF(TT!$D$33:$D$50,TALLY!A6) -> 1 | D6: =COUNTIF(TT!$D$57:$D$75,TALLY!A6) -> 0 | E6: =COUNTIF(TT!$D$82:$D$95,TALLY!A6) -> 0 | F6: =COUNTIF(TT!$D$103:$D$112,TALLY!A6) -> 0 | G6: =COUNTIF(TT!$D$120:$D$130,TALLY!A6) -> 0 | H6: =COUNTIF(TT!$D$138:$D$153,TALLY!A6) -> 0 | I6: =COUNTIF(TT!$D$160:$D$170,TALLY!A6) -> 1 | J6: =COUNTIF(TT!$D$177:$D$187,TALLY!A6) -> 0 | K6: =COUNTIF(TT!$D$194:$D$206,TALLY!A6) -> 0 | L6: =COUNTIF(TT!$D$215:$D$226,TALLY!A6) -> 1 | M6: =COUNTIF(TT!$D$234:$D$243,TALLY!A6) -> 0 | N6: =COUNTIF(TT!$D$250:$D$262,TALLY!A6) -> 0 | O6: =COUNTIF(TT!$D$270:$D$277,TALLY!A6) -> 0 | P6: =COUNTIF(TT!$D$284:$D$293,TALLY!A6) -> 0 | Q6: =COUNTIF(TT!$D$300:$D$313,TALLY!A6) -> 0 | R6: =COUNTIF(TT!$D$320:$D$333,TALLY!A6) -> 0 | S6: =COUNTIF(TT!$D$342:$D$352,TALLY!A6) -> 0 | T6: =COUNTIF(TT!$D$359:$D$376,TALLY!A6) -> 0 | U6: =COUNTIF(TT!$D$383:$D$398,TALLY!A6) -> 0 | V6: =COUNTIF(TT!$D$405:$D$424,TALLY!A6) -> 0 | W6: =COUNTIF(TT!$D$432:$D$442,TALLY!A6) -> 1 | X6: =COUNTIF(TT!$D$449:$D$460,TALLY!A6) -> 0 | Y6: =COUNTIF(TT!$D$467:$D$476,TALLY!A6) -> 0 | Z6: =COUNTIF(TT!$D$483:$D$500,TALLY!A6) -> 0 | AA6: =COUNTIF(TT!$D$507:$D$522,TALLY!A6) -> 0 | AB6: =COUNTIF(TT!$D$529:$D$540,TALLY!A6) -> 0 | AC6: =COUNTIF(TT!$D$546:$D$555,TALLY!A6) -> 1 | AD6: =COUNTIF(TT!$D$563:$D$573,TALLY!A6) -> 0 | AE6: =COUNTIF(TT!$D$582:$D$609,TALLY!A6) -> 0 | AF6: =COUNTIF(TT!$D$615:$D$625,TALLY!A6) -> 0 | AG6: =COUNTIF(TT!$D$635:$D$648,TALLY!A6) -> 0 | AH6: =COUNTIF(TT!$D$655:$D$668,TALLY!A6) -> 0 | AI6: =COUNTIF(TT!$D$675:$D$687,TALLY!A6) -> 1 | AK6: ED1-AUTO | AL6: =SUM($B6:$H6) -> 1 | AM6: =SUM(I6:O6) -> 2 | AN6: =SUM(P6:V6) -> 0 | AO6: =SUM(W6:AA6) -> 1 | AP6: =SUM(AD6:AJ6) -> 1 | AQ6: =SUM(AL6:AP6) -> 5
A7: ED1-BME | B7: =COUNTIF(TT!$D$4:$D$25,TALLY!A7) -> 1 | C7: =COUNTIF(TT!$D$33:$D$50,TALLY!A7) -> 0 | D7: =COUNTIF(TT!$D$57:$D$75,TALLY!A7) -> 1 | E7: =COUNTIF(TT!$D$82:$D$95,TALLY!A7) -> 0 | F7: =COUNTIF(TT!$D$103:$D$112,TALLY!A7) -> 0 | G7: =COUNTIF(TT!$D$120:$D$130,TALLY!A7) -> 0 | H7: =COUNTIF(TT!$D$138:$D$153,TALLY!A7) -> 0 | I7: =COUNTIF(TT!$D$160:$D$170,TALLY!A7) -> 1 | J7: =COUNTIF(TT!$D$177:$D$187,TALLY!A7) -> 0 | K7: =COUNTIF(TT!$D$194:$D$206,TALLY!A7) -> 0 | L7: =COUNTIF(TT!$D$215:$D$226,TALLY!A7) -> 1 | M7: =COUNTIF(TT!$D$234:$D$243,TALLY!A7) -> 0 | N7: =COUNTIF(TT!$D$250:$D$262,TALLY!A7) -> 0 | O7: =COUNTIF(TT!$D$270:$D$277,TALLY!A7) -> 0 | P7: =COUNTIF(TT!$D$284:$D$293,TALLY!A7) -> 0 | Q7: =COUNTIF(TT!$D$300:$D$313,TALLY!A7) -> 0 | R7: =COUNTIF(TT!$D$320:$D$333,TALLY!A7) -> 0 | S7: =COUNTIF(TT!$D$342:$D$352,TALLY!A7) -> 0 | T7: =COUNTIF(TT!$D$359:$D$376,TALLY!A7) -> 0 | U7: =COUNTIF(TT!$D$383:$D$398,TALLY!A7) -> 0 | V7: =COUNTIF(TT!$D$405:$D$424,TALLY!A7) -> 1 | W7: =COUNTIF(TT!$D$432:$D$442,TALLY!A7) -> 0 | X7: =COUNTIF(TT!$D$449:$D$460,TALLY!A7) -> 0 | Y7: =COUNTIF(TT!$D$467:$D$476,TALLY!A7) -> 0 | Z7: =COUNTIF(TT!$D$483:$D$500,TALLY!A7) -> 0 | AA7: =COUNTIF(TT!$D$507:$D$522,TALLY!A7) -> 1 | AB7: =COUNTIF(TT!$D$529:$D$540,TALLY!A7) -> 0 | AC7: =COUNTIF(TT!$D$546:$D$555,TALLY!A7) -> 0 | AD7: =COUNTIF(TT!$D$563:$D$573,TALLY!A7) -> 0 | AE7: =COUNTIF(TT!$D$582:$D$609,TALLY!A7) -> 0 | AF7: =COUNTIF(TT!$D$615:$D$625,TALLY!A7) -> 0 | AG7: =COUNTIF(TT!$D$635:$D$648,TALLY!A7) -> 1 | AH7: =COUNTIF(TT!$D$655:$D$668,TALLY!A7) -> 0 | AI7: =COUNTIF(TT!$D$675:$D$687,TALLY!A7) -> 0 | AK7: ED1-BME | AL7: =SUM($B7:$H7) -> 2 | AM7: =SUM(I7:O7) -> 2 | AN7: =SUM(P7:V7) -> 1 | AO7: =SUM(W7:AA7) -> 1 | AP7: =SUM(AD7:AJ7) -> 1 | AQ7: =SUM(AL7:AP7) -> 7
A8: ED1-CE | B8: =COUNTIF(TT!$D$4:$D$25,TALLY!A8) -> 0 | C8: =COUNTIF(TT!$D$33:$D$50,TALLY!A8) -> 1 | D8: =COUNTIF(TT!$D$57:$D$75,TALLY!A8) -> 0 | E8: =COUNTIF(TT!$D$82:$D$95,TALLY!A8) -> 0 | F8: =COUNTIF(TT!$D$103:$D$112,TALLY!A8) -> 1 | G8: =COUNTIF(TT!$D$120:$D$130,TALLY!A8) -> 0 | H8: =COUNTIF(TT!$D$138:$D$153,TALLY!A8) -> 0 | I8: =COUNTIF(TT!$D$160:$D$170,TALLY!A8) -> 1 | J8: =COUNTIF(TT!$D$177:$D$187,TALLY!A8) -> 0 | K8: =COUNTIF(TT!$D$194:$D$206,TALLY!A8) -> 0 | L8: =COUNTIF(TT!$D$215:$D$226,TALLY!A8) -> 0 | M8: =COUNTIF(TT!$D$234:$D$243,TALLY!A8) -> 1 | N8: =COUNTIF(TT!$D$250:$D$262,TALLY!A8) -> 0 | O8: =COUNTIF(TT!$D$270:$D$277,TALLY!A8) -> 0 | P8: =COUNTIF(TT!$D$284:$D$293,TALLY!A8) -> 0 | Q8: =COUNTIF(TT!$D$300:$D$313,TALLY!A8) -> 0 | R8: =COUNTIF(TT!$D$320:$D$333,TALLY!A8) -> 0 | S8: =COUNTIF(TT!$D$342:$D$352,TALLY!A8) -> 0 | T8: =COUNTIF(TT!$D$359:$D$376,TALLY!A8) -> 1 | U8: =COUNTIF(TT!$D$383:$D$398,TALLY!A8) -> 0 | V8: =COUNTIF(TT!$D$405:$D$424,TALLY!A8) -> 0 | W8: =COUNTIF(TT!$D$432:$D$442,TALLY!A8) -> 1 | X8: =COUNTIF(TT!$D$449:$D$460,TALLY!A8) -> 0 | Y8: =COUNTIF(TT!$D$467:$D$476,TALLY!A8) -> 0 | Z8: =COUNTIF(TT!$D$483:$D$500,TALLY!A8) -> 0 | AA8: =COUNTIF(TT!$D$507:$D$522,TALLY!A8) -> 0 | AB8: =COUNTIF(TT!$D$529:$D$540,TALLY!A8) -> 1 | AC8: =COUNTIF(TT!$D$546:$D$555,TALLY!A8) -> 0 | AD8: =COUNTIF(TT!$D$563:$D$573,TALLY!A8) -> 0 | AE8: =COUNTIF(TT!$D$582:$D$609,TALLY!A8) -> 0 | AF8: =COUNTIF(TT!$D$615:$D$625,TALLY!A8) -> 0 | AG8: =COUNTIF(TT!$D$635:$D$648,TALLY!A8) -> 0 | AH8: =COUNTIF(TT!$D$655:$D$668,TALLY!A8) -> 1 | AI8: =COUNTIF(TT!$D$675:$D$687,TALLY!A8) -> 0 | AK8: ED1-CE | AL8: =SUM($B8:$H8) -> 2 | AM8: =SUM(I8:O8) -> 2 | AN8: =SUM(P8:V8) -> 1 | AO8: =SUM(W8:AA8) -> 1 | AP8: =SUM(AD8:AJ8) -> 1 | AQ8: =SUM(AL8:AP8) -> 7
A9: ED1-CHE | B9: =COUNTIF(TT!$D$4:$D$25,TALLY!A9) -> 1 | C9: =COUNTIF(TT!$D$33:$D$50,TALLY!A9) -> 0 | D9: =COUNTIF(TT!$D$57:$D$75,TALLY!A9) -> 0 | E9: =COUNTIF(TT!$D$82:$D$95,TALLY!A9) -> 1 | F9: =COUNTIF(TT!$D$103:$D$112,TALLY!A9) -> 0 | G9: =COUNTIF(TT!$D$120:$D$130,TALLY!A9) -> 0 | H9: =COUNTIF(TT!$D$138:$D$153,TALLY!A9) -> 0 | I9: =COUNTIF(TT!$D$160:$D$170,TALLY!A9) -> 1 | J9: =COUNTIF(TT!$D$177:$D$187,TALLY!A9) -> 0 | K9: =COUNTIF(TT!$D$194:$D$206,TALLY!A9) -> 0 | L9: =COUNTIF(TT!$D$215:$D$226,TALLY!A9) -> 1 | M9: =COUNTIF(TT!$D$234:$D$243,TALLY!A9) -> 0 | N9: =COUNTIF(TT!$D$250:$D$262,TALLY!A9) -> 0 | O9: =COUNTIF(TT!$D$270:$D$277,TALLY!A9) -> 0 | P9: =COUNTIF(TT!$D$284:$D$293,TALLY!A9) -> 0 | Q9: =COUNTIF(TT!$D$300:$D$313,TALLY!A9) -> 0 | R9: =COUNTIF(TT!$D$320:$D$333,TALLY!A9) -> 0 | S9: =COUNTIF(TT!$D$342:$D$352,TALLY!A9) -> 0 | T9: =COUNTIF(TT!$D$359:$D$376,TALLY!A9) -> 0 | U9: =COUNTIF(TT!$D$383:$D$398,TALLY!A9) -> 0 | V9: =COUNTIF(TT!$D$405:$D$424,TALLY!A9) -> 1 | W9: =COUNTIF(TT!$D$432:$D$442,TALLY!A9) -> 1 | X9: =COUNTIF(TT!$D$449:$D$460,TALLY!A9) -> 0 | Y9: =COUNTIF(TT!$D$467:$D$476,TALLY!A9) -> 0 | Z9: =COUNTIF(TT!$D$483:$D$500,TALLY!A9) -> 0 | AA9: =COUNTIF(TT!$D$507:$D$522,TALLY!A9) -> 0 | AB9: =COUNTIF(TT!$D$529:$D$540,TALLY!A9) -> 0 | AC9: =COUNTIF(TT!$D$546:$D$555,TALLY!A9) -> 0 | AD9: =COUNTIF(TT!$D$563:$D$573,TALLY!A9) -> 0 | AE9: =COUNTIF(TT!$D$582:$D$609,TALLY!A9) -> 0 | AF9: =COUNTIF(TT!$D$615:$D$625,TALLY!A9) -> 0 | AG9: =COUNTIF(TT!$D$635:$D$648,TALLY!A9) -> 1 | AH9: =COUNTIF(TT!$D$655:$D$668,TALLY!A9) -> 0 | AI9: =COUNTIF(TT!$D$675:$D$687,TALLY!A9) -> 0 | AK9: ED1-CHE | AL9: =SUM($B9:$H9) -> 2 | AM9: =SUM(I9:O9) -> 2 | AN9: =SUM(P9:V9) -> 1 | AO9: =SUM(W9:AA9) -> 1 | AP9: =SUM(AD9:AJ9) -> 1 | AQ9: =SUM(AL9:AP9) -> 7
A10: ED1-COE | B10: =COUNTIF(TT!$D$4:$D$25,TALLY!A10) -> 1 | C10: =COUNTIF(TT!$D$33:$D$50,TALLY!A10) -> 0 | D10: =COUNTIF(TT!$D$57:$D$75,TALLY!A10) -> 0 | E10: =COUNTIF(TT!$D$82:$D$95,TALLY!A10) -> 0 | F10: =COUNTIF(TT!$D$103:$D$112,TALLY!A10) -> 0 | G10: =COUNTIF(TT!$D$120:$D$130,TALLY!A10) -> 0 | H10: =COUNTIF(TT!$D$138:$D$153,TALLY!A10) -> 0 | I10: =COUNTIF(TT!$D$160:$D$170,TALLY!A10) -> 1 | J10: =COUNTIF(TT!$D$177:$D$187,TALLY!A10) -> 0 | K10: =COUNTIF(TT!$D$194:$D$206,TALLY!A10) -> 0 | L10: =COUNTIF(TT!$D$215:$D$226,TALLY!A10) -> 0 | M10: =COUNTIF(TT!$D$234:$D$243,TALLY!A10) -> 0 | N10: =COUNTIF(TT!$D$250:$D$262,TALLY!A10) -> 0 | O10: =COUNTIF(TT!$D$270:$D$277,TALLY!A10) -> 0 | P10: =COUNTIF(TT!$D$284:$D$293,TALLY!A10) -> 0 | Q10: =COUNTIF(TT!$D$300:$D$313,TALLY!A10) -> 0 | R10: =COUNTIF(TT!$D$320:$D$333,TALLY!A10) -> 0 | S10: =COUNTIF(TT!$D$342:$D$352,TALLY!A10) -> 0 | T10: =COUNTIF(TT!$D$359:$D$376,TALLY!A10) -> 1 | U10: =COUNTIF(TT!$D$383:$D$398,TALLY!A10) -> 0 | V10: =COUNTIF(TT!$D$405:$D$424,TALLY!A10) -> 0 | W10: =COUNTIF(TT!$D$432:$D$442,TALLY!A10) -> 1 | X10: =COUNTIF(TT!$D$449:$D$460,TALLY!A10) -> 0 | Y10: =COUNTIF(TT!$D$467:$D$476,TALLY!A10) -> 0 | Z10: =COUNTIF(TT!$D$483:$D$500,TALLY!A10) -> 0 | AA10: =COUNTIF(TT!$D$507:$D$522,TALLY!A10) -> 0 | AB10: =COUNTIF(TT!$D$529:$D$540,TALLY!A10) -> 0 | AC10: =COUNTIF(TT!$D$546:$D$555,TALLY!A10) -> 0 | AD10: =COUNTIF(TT!$D$563:$D$573,TALLY!A10) -> 1 | AE10: =COUNTIF(TT!$D$582:$D$609,TALLY!A10) -> 0 | AF10: =COUNTIF(TT!$D$615:$D$625,TALLY!A10) -> 0 | AG10: =COUNTIF(TT!$D$635:$D$648,TALLY!A10) -> 0 | AH10: =COUNTIF(TT!$D$655:$D$668,TALLY!A10) -> 0 | AI10: =COUNTIF(TT!$D$675:$D$687,TALLY!A10) -> 1 | AK10: ED1-COE | AL10: =SUM($B10:$H10) -> 1 | AM10: =SUM(I10:O10) -> 1 | AN10: =SUM(P10:V10) -> 1 | AO10: =SUM(W10:AA10) -> 1 | AP10: =SUM(AD10:AJ10) -> 2 | AQ10: =SUM(AL10:AP10) -> 6
A11: ED1-EE | B11: =COUNTIF(TT!$D$4:$D$25,TALLY!A11) -> 0 | C11: =COUNTIF(TT!$D$33:$D$50,TALLY!A11) -> 1 | D11: =COUNTIF(TT!$D$57:$D$75,TALLY!A11) -> 0 | E11: =COUNTIF(TT!$D$82:$D$95,TALLY!A11) -> 0 | F11: =COUNTIF(TT!$D$103:$D$112,TALLY!A11) -> 0 | G11: =COUNTIF(TT!$D$120:$D$130,TALLY!A11) -> 0 | H11: =COUNTIF(TT!$D$138:$D$153,TALLY!A11) -> 0 | I11: =COUNTIF(TT!$D$160:$D$170,TALLY!A11) -> 0 | J11: =COUNTIF(TT!$D$177:$D$187,TALLY!A11) -> 1 | K11: =COUNTIF(TT!$D$194:$D$206,TALLY!A11) -> 0 | L11: =COUNTIF(TT!$D$215:$D$226,TALLY!A11) -> 0 | M11: =COUNTIF(TT!$D$234:$D$243,TALLY!A11) -> 0 | N11: =COUNTIF(TT!$D$250:$D$262,TALLY!A11) -> 0 | O11: =COUNTIF(TT!$D$270:$D$277,TALLY!A11) -> 1 | P11: =COUNTIF(TT!$D$284:$D$293,TALLY!A11) -> 0 | Q11: =COUNTIF(TT!$D$300:$D$313,TALLY!A11) -> 1 | R11: =COUNTIF(TT!$D$320:$D$333,TALLY!A11) -> 0 | S11: =COUNTIF(TT!$D$342:$D$352,TALLY!A11) -> 0 | T11: =COUNTIF(TT!$D$359:$D$376,TALLY!A11) -> 1 | U11: =COUNTIF(TT!$D$383:$D$398,TALLY!A11) -> 0 | V11: =COUNTIF(TT!$D$405:$D$424,TALLY!A11) -> 0 | W11: =COUNTIF(TT!$D$432:$D$442,TALLY!A11) -> 0 | X11: =COUNTIF(TT!$D$449:$D$460,TALLY!A11) -> 0 | Y11: =COUNTIF(TT!$D$467:$D$476,TALLY!A11) -> 0 | Z11: =COUNTIF(TT!$D$483:$D$500,TALLY!A11) -> 0 | AA11: =COUNTIF(TT!$D$507:$D$522,TALLY!A11) -> 0 | AB11: =COUNTIF(TT!$D$529:$D$540,TALLY!A11) -> 0 | AC11: =COUNTIF(TT!$D$546:$D$555,TALLY!A11) -> 0 | AD11: =COUNTIF(TT!$D$563:$D$573,TALLY!A11) -> 0 | AE11: =COUNTIF(TT!$D$582:$D$609,TALLY!A11) -> 0 | AF11: =COUNTIF(TT!$D$615:$D$625,TALLY!A11) -> 0 | AG11: =COUNTIF(TT!$D$635:$D$648,TALLY!A11) -> 0 | AH11: =COUNTIF(TT!$D$655:$D$668,TALLY!A11) -> 1 | AI11: =COUNTIF(TT!$D$675:$D$687,TALLY!A11) -> 0 | AK11: ED1-EE | AL11: =SUM($B11:$H11) -> 1 | AM11: =SUM(I11:O11) -> 2 | AN11: =SUM(P11:V11) -> 2 | AO11: 1 | AP11: =SUM(AD11:AJ11) -> 1 | AQ11: =SUM(AL11:AP11) -> 7
A12: ED1-GEOL | B12: =COUNTIF(TT!$D$4:$D$25,TALLY!A12) -> 0 | C12: =COUNTIF(TT!$D$33:$D$50,TALLY!A12) -> 1 | D12: =COUNTIF(TT!$D$57:$D$75,TALLY!A12) -> 0 | E12: =COUNTIF(TT!$D$82:$D$95,TALLY!A12) -> 0 | F12: =COUNTIF(TT!$D$103:$D$112,TALLY!A12) -> 1 | G12: =COUNTIF(TT!$D$120:$D$130,TALLY!A12) -> 0 | H12: =COUNTIF(TT!$D$138:$D$153,TALLY!A12) -> 0 | I12: =COUNTIF(TT!$D$160:$D$170,TALLY!A12) -> 0 | J12: =COUNTIF(TT!$D$177:$D$187,TALLY!A12) -> 1 | K12: =COUNTIF(TT!$D$194:$D$206,TALLY!A12) -> 0 | L12: =COUNTIF(TT!$D$215:$D$226,TALLY!A12) -> 0 | M12: =COUNTIF(TT!$D$234:$D$243,TALLY!A12) -> 1 | N12: =COUNTIF(TT!$D$250:$D$262,TALLY!A12) -> 0 | O12: =COUNTIF(TT!$D$270:$D$277,TALLY!A12) -> 0 | P12: =COUNTIF(TT!$D$284:$D$293,TALLY!A12) -> 0 | Q12: =COUNTIF(TT!$D$300:$D$313,TALLY!A12) -> 1 | R12: =COUNTIF(TT!$D$320:$D$333,TALLY!A12) -> 0 | S12: =COUNTIF(TT!$D$342:$D$352,TALLY!A12) -> 0 | T12: =COUNTIF(TT!$D$359:$D$376,TALLY!A12) -> 1 | U12: =COUNTIF(TT!$D$383:$D$398,TALLY!A12) -> 0 | V12: =COUNTIF(TT!$D$405:$D$424,TALLY!A12) -> 0 | W12: =COUNTIF(TT!$D$432:$D$442,TALLY!A12) -> 0 | X12: =COUNTIF(TT!$D$449:$D$460,TALLY!A12) -> 0 | Y12: =COUNTIF(TT!$D$467:$D$476,TALLY!A12) -> 0 | Z12: =COUNTIF(TT!$D$483:$D$500,TALLY!A12) -> 0 | AA12: =COUNTIF(TT!$D$507:$D$522,TALLY!A12) -> 0 | AB12: =COUNTIF(TT!$D$529:$D$540,TALLY!A12) -> 0 | AC12: =COUNTIF(TT!$D$546:$D$555,TALLY!A12) -> 1 | AD12: =COUNTIF(TT!$D$563:$D$573,TALLY!A12) -> 0 | AE12: =COUNTIF(TT!$D$582:$D$609,TALLY!A12) -> 0 | AF12: =COUNTIF(TT!$D$615:$D$625,TALLY!A12) -> 0 | AG12: =COUNTIF(TT!$D$635:$D$648,TALLY!A12) -> 0 | AH12: =COUNTIF(TT!$D$655:$D$668,TALLY!A12) -> 1 | AI12: =COUNTIF(TT!$D$675:$D$687,TALLY!A12) -> 0 | AK12: ED1-GEOL | AL12: =SUM($B12:$H12) -> 2 | AM12: =SUM(I12:O12) -> 2 | AN12: =SUM(P12:V12) -> 2 | AO12: =SUM(W12:AA12) -> 0 | AP12: =SUM(AD12:AJ12) -> 1 | AQ12: =SUM(AL12:AP12) -> 7
A13: ED1-GEOM | B13: =COUNTIF(TT!$D$4:$D$25,TALLY!A13) -> 0 | C13: =COUNTIF(TT!$D$33:$D$50,TALLY!A13) -> 0 | D13: =COUNTIF(TT!$D$57:$D$75,TALLY!A13) -> 1 | E13: =COUNTIF(TT!$D$82:$D$95,TALLY!A13) -> 0 | F13: =COUNTIF(TT!$D$103:$D$112,TALLY!A13) -> 0 | G13: =COUNTIF(TT!$D$120:$D$130,TALLY!A13) -> 1 | H13: =COUNTIF(TT!$D$138:$D$153,TALLY!A13) -> 0 | I13: =COUNTIF(TT!$D$160:$D$170,TALLY!A13) -> 0 | J13: =COUNTIF(TT!$D$177:$D$187,TALLY!A13) -> 1 | K13: =COUNTIF(TT!$D$194:$D$206,TALLY!A13) -> 0 | L13: =COUNTIF(TT!$D$215:$D$226,TALLY!A13) -> 0 | M13: =COUNTIF(TT!$D$234:$D$243,TALLY!A13) -> 0 | N13: =COUNTIF(TT!$D$250:$D$262,TALLY!A13) -> 0 | O13: =COUNTIF(TT!$D$270:$D$277,TALLY!A13) -> 0 | P13: =COUNTIF(TT!$D$284:$D$293,TALLY!A13) -> 0 | Q13: =COUNTIF(TT!$D$300:$D$313,TALLY!A13) -> 0 | R13: =COUNTIF(TT!$D$320:$D$333,TALLY!A13) -> 0 | S13: =COUNTIF(TT!$D$342:$D$352,TALLY!A13) -> 1 | T13: =COUNTIF(TT!$D$359:$D$376,TALLY!A13) -> 0 | U13: =COUNTIF(TT!$D$383:$D$398,TALLY!A13) -> 0 | V13: =COUNTIF(TT!$D$405:$D$424,TALLY!A13) -> 0 | W13: =COUNTIF(TT!$D$432:$D$442,TALLY!A13) -> 0 | X13: =COUNTIF(TT!$D$449:$D$460,TALLY!A13) -> 0 | Y13: =COUNTIF(TT!$D$467:$D$476,TALLY!A13) -> 0 | Z13: =COUNTIF(TT!$D$483:$D$500,TALLY!A13) -> 0 | AA13: =COUNTIF(TT!$D$507:$D$522,TALLY!A13) -> 0 | AB13: =COUNTIF(TT!$D$529:$D$540,TALLY!A13) -> 0 | AC13: =COUNTIF(TT!$D$546:$D$555,TALLY!A13) -> 0 | AD13: =COUNTIF(TT!$D$563:$D$573,TALLY!A13) -> 0 | AE13: =COUNTIF(TT!$D$582:$D$609,TALLY!A13) -> 0 | AF13: =COUNTIF(TT!$D$615:$D$625,TALLY!A13) -> 0 | AG13: =COUNTIF(TT!$D$635:$D$648,TALLY!A13) -> 0 | AH13: =COUNTIF(TT!$D$655:$D$668,TALLY!A13) -> 0 | AI13: =COUNTIF(TT!$D$675:$D$687,TALLY!A13) -> 1 | AK13: ED1-GEOM | AL13: =SUM($B13:$H13) -> 2 | AM13: =SUM(I13:O13) -> 1 | AN13: =SUM(P13:V13) -> 1 | AO13: =SUM(W13:AA13) -> 0 | AP13: =SUM(AD13:AJ13) -> 1 | AQ13: =SUM(AL13:AP13) -> 5
A14: ED1-IND | B14: =COUNTIF(TT!$D$4:$D$25,TALLY!A14) -> 1 | C14: =COUNTIF(TT!$D$33:$D$50,TALLY!A14) -> 0 | D14: =COUNTIF(TT!$D$57:$D$75,TALLY!A14) -> 0 | E14: =COUNTIF(TT!$D$82:$D$95,TALLY!A14) -> 0 | F14: =COUNTIF(TT!$D$103:$D$112,TALLY!A14) -> 0 | G14: =COUNTIF(TT!$D$120:$D$130,TALLY!A14) -> 0 | H14: =COUNTIF(TT!$D$138:$D$153,TALLY!A14) -> 0 | I14: =COUNTIF(TT!$D$160:$D$170,TALLY!A14) -> 0 | J14: =COUNTIF(TT!$D$177:$D$187,TALLY!A14) -> 1 | K14: =COUNTIF(TT!$D$194:$D$206,TALLY!A14) -> 0 | L14: =COUNTIF(TT!$D$215:$D$226,TALLY!A14) -> 0 | M14: =COUNTIF(TT!$D$234:$D$243,TALLY!A14) -> 0 | N14: =COUNTIF(TT!$D$250:$D$262,TALLY!A14) -> 1 | O14: =COUNTIF(TT!$D$270:$D$277,TALLY!A14) -> 0 | P14: =COUNTIF(TT!$D$284:$D$293,TALLY!A14) -> 0 | Q14: =COUNTIF(TT!$D$300:$D$313,TALLY!A14) -> 0 | R14: =COUNTIF(TT!$D$320:$D$333,TALLY!A14) -> 0 | S14: =COUNTIF(TT!$D$342:$D$352,TALLY!A14) -> 0 | T14: =COUNTIF(TT!$D$359:$D$376,TALLY!A14) -> 0 | U14: =COUNTIF(TT!$D$383:$D$398,TALLY!A14) -> 0 | V14: =COUNTIF(TT!$D$405:$D$424,TALLY!A14) -> 0 | W14: =COUNTIF(TT!$D$432:$D$442,TALLY!A14) -> 1 | X14: =COUNTIF(TT!$D$449:$D$460,TALLY!A14) -> 0 | Y14: =COUNTIF(TT!$D$467:$D$476,TALLY!A14) -> 0 | Z14: =COUNTIF(TT!$D$483:$D$500,TALLY!A14) -> 0 | AA14: =COUNTIF(TT!$D$507:$D$522,TALLY!A14) -> 0 | AB14: =COUNTIF(TT!$D$529:$D$540,TALLY!A14) -> 0 | AC14: =COUNTIF(TT!$D$546:$D$555,TALLY!A14) -> 1 | AD14: =COUNTIF(TT!$D$563:$D$573,TALLY!A14) -> 0 | AE14: =COUNTIF(TT!$D$582:$D$609,TALLY!A14) -> 0 | AF14: =COUNTIF(TT!$D$615:$D$625,TALLY!A14) -> 1 | AG14: =COUNTIF(TT!$D$635:$D$648,TALLY!A14) -> 0 | AH14: =COUNTIF(TT!$D$655:$D$668,TALLY!A14) -> 0 | AI14: =COUNTIF(TT!$D$675:$D$687,TALLY!A14) -> 0 | AK14: ED1-IND | AL14: =SUM($B14:$H14) -> 1 | AM14: =SUM(I14:O14) -> 2 | AN14: =SUM(P14:V14) -> 0 | AO14: =SUM(W14:AA14) -> 1 | AP14: =SUM(AD14:AJ14) -> 1 | AQ14: =SUM(AL14:AP14) -> 5
A15: ED1-MARI | B15: =COUNTIF(TT!$D$4:$D$25,TALLY!A15) -> 0 | C15: =COUNTIF(TT!$D$33:$D$50,TALLY!A15) -> 0 | D15: =COUNTIF(TT!$D$57:$D$75,TALLY!A15) -> 1 | E15: =COUNTIF(TT!$D$82:$D$95,TALLY!A15) -> 0 | F15: =COUNTIF(TT!$D$103:$D$112,TALLY!A15) -> 0 | G15: =COUNTIF(TT!$D$120:$D$130,TALLY!A15) -> 0 | H15: =COUNTIF(TT!$D$138:$D$153,TALLY!A15) -> 0 | I15: =COUNTIF(TT!$D$160:$D$170,TALLY!A15) -> 1 | J15: =COUNTIF(TT!$D$177:$D$187,TALLY!A15) -> 0 | K15: =COUNTIF(TT!$D$194:$D$206,TALLY!A15) -> 0 | L15: =COUNTIF(TT!$D$215:$D$226,TALLY!A15) -> 0 | M15: =COUNTIF(TT!$D$234:$D$243,TALLY!A15) -> 0 | N15: =COUNTIF(TT!$D$250:$D$262,TALLY!A15) -> 1 | O15: =COUNTIF(TT!$D$270:$D$277,TALLY!A15) -> 0 | P15: =COUNTIF(TT!$D$284:$D$293,TALLY!A15) -> 0 | Q15: =COUNTIF(TT!$D$300:$D$313,TALLY!A15) -> 0 | R15: =COUNTIF(TT!$D$320:$D$333,TALLY!A15) -> 0 | S15: =COUNTIF(TT!$D$342:$D$352,TALLY!A15) -> 0 | T15: =COUNTIF(TT!$D$359:$D$376,TALLY!A15) -> 0 | U15: =COUNTIF(TT!$D$383:$D$398,TALLY!A15) -> 0 | V15: =COUNTIF(TT!$D$405:$D$424,TALLY!A15) -> 0 | W15: =COUNTIF(TT!$D$432:$D$442,TALLY!A15) -> 1 | X15: =COUNTIF(TT!$D$449:$D$460,TALLY!A15) -> 0 | Y15: =COUNTIF(TT!$D$467:$D$476,TALLY!A15) -> 0 | Z15: =COUNTIF(TT!$D$483:$D$500,TALLY!A15) -> 0 | AA15: =COUNTIF(TT!$D$507:$D$522,TALLY!A15) -> 0 | AB15: =COUNTIF(TT!$D$529:$D$540,TALLY!A15) -> 0 | AC15: =COUNTIF(TT!$D$546:$D$555,TALLY!A15) -> 1 | AD15: =COUNTIF(TT!$D$563:$D$573,TALLY!A15) -> 0 | AE15: =COUNTIF(TT!$D$582:$D$609,TALLY!A15) -> 0 | AF15: =COUNTIF(TT!$D$615:$D$625,TALLY!A15) -> 1 | AG15: =COUNTIF(TT!$D$635:$D$648,TALLY!A15) -> 0 | AH15: =COUNTIF(TT!$D$655:$D$668,TALLY!A15) -> 1 | AI15: =COUNTIF(TT!$D$675:$D$687,TALLY!A15) -> 0 | AK15: ED1-MARI | AL15: =SUM($B15:$H15) -> 1 | AM15: =SUM(I15:O15) -> 2 | AN15: =SUM(P15:V15) -> 0 | AO15: =SUM(W15:AA15) -> 1 | AP15: =SUM(AD15:AJ15) -> 2 | AQ15: =SUM(AL15:AP15) -> 6
A16: ED1-ME | B16: =COUNTIF(TT!$D$4:$D$25,TALLY!A16) -> 0 | C16: =COUNTIF(TT!$D$33:$D$50,TALLY!A16) -> 0 | D16: =COUNTIF(TT!$D$57:$D$75,TALLY!A16) -> 1 | E16: =COUNTIF(TT!$D$82:$D$95,TALLY!A16) -> 0 | F16: =COUNTIF(TT!$D$103:$D$112,TALLY!A16) -> 0 | G16: =COUNTIF(TT!$D$120:$D$130,TALLY!A16) -> 0 | H16: =COUNTIF(TT!$D$138:$D$153,TALLY!A16) -> 0 | I16: =COUNTIF(TT!$D$160:$D$170,TALLY!A16) -> 1 | J16: =COUNTIF(TT!$D$177:$D$187,TALLY!A16) -> 0 | K16: =COUNTIF(TT!$D$194:$D$206,TALLY!A16) -> 0 | L16: =COUNTIF(TT!$D$215:$D$226,TALLY!A16) -> 0 | M16: =COUNTIF(TT!$D$234:$D$243,TALLY!A16) -> 0 | N16: =COUNTIF(TT!$D$250:$D$262,TALLY!A16) -> 0 | O16: =COUNTIF(TT!$D$270:$D$277,TALLY!A16) -> 0 | P16: =COUNTIF(TT!$D$284:$D$293,TALLY!A16) -> 0 | Q16: =COUNTIF(TT!$D$300:$D$313,TALLY!A16) -> 0 | R16: =COUNTIF(TT!$D$320:$D$333,TALLY!A16) -> 0 | S16: =COUNTIF(TT!$D$342:$D$352,TALLY!A16) -> 0 | T16: =COUNTIF(TT!$D$359:$D$376,TALLY!A16) -> 0 | U16: =COUNTIF(TT!$D$383:$D$398,TALLY!A16) -> 1 | V16: =COUNTIF(TT!$D$405:$D$424,TALLY!A16) -> 0 | W16: =COUNTIF(TT!$D$432:$D$442,TALLY!A16) -> 1 | X16: =COUNTIF(TT!$D$449:$D$460,TALLY!A16) -> 0 | Y16: =COUNTIF(TT!$D$467:$D$476,TALLY!A16) -> 0 | Z16: =COUNTIF(TT!$D$483:$D$500,TALLY!A16) -> 0 | AA16: =COUNTIF(TT!$D$507:$D$522,TALLY!A16) -> 0 | AB16: =COUNTIF(TT!$D$529:$D$540,TALLY!A16) -> 0 | AC16: =COUNTIF(TT!$D$546:$D$555,TALLY!A16) -> 1 | AD16: =COUNTIF(TT!$D$563:$D$573,TALLY!A16) -> 0 | AE16: =COUNTIF(TT!$D$582:$D$609,TALLY!A16) -> 0 | AF16: =COUNTIF(TT!$D$615:$D$625,TALLY!A16) -> 1 | AG16: =COUNTIF(TT!$D$635:$D$648,TALLY!A16) -> 0 | AH16: =COUNTIF(TT!$D$655:$D$668,TALLY!A16) -> 0 | AI16: =COUNTIF(TT!$D$675:$D$687,TALLY!A16) -> 0 | AK16: ED1-ME | AL16: =SUM($B16:$H16) -> 1 | AM16: =SUM(I16:O16) -> 1 | AN16: =SUM(P16:V16) -> 1 | AO16: =SUM(W16:AA16) -> 1 | AP16: =SUM(AD16:AJ16) -> 1 | AQ16: =SUM(AL16:AP16) -> 5
A17: ED1-METE | B17: =COUNTIF(TT!$D$4:$D$25,TALLY!A17) -> 0 | C17: =COUNTIF(TT!$D$33:$D$50,TALLY!A17) -> 0 | D17: =COUNTIF(TT!$D$57:$D$75,TALLY!A17) -> 1 | E17: =COUNTIF(TT!$D$82:$D$95,TALLY!A17) -> 0 | F17: =COUNTIF(TT!$D$103:$D$112,TALLY!A17) -> 0 | G17: =COUNTIF(TT!$D$120:$D$130,TALLY!A17) -> 0 | H17: =COUNTIF(TT!$D$138:$D$153,TALLY!A17) -> 1 | I17: =COUNTIF(TT!$D$160:$D$170,TALLY!A17) -> 0 | J17: =COUNTIF(TT!$D$177:$D$187,TALLY!A17) -> 0 | K17: =COUNTIF(TT!$D$194:$D$206,TALLY!A17) -> 0 | L17: =COUNTIF(TT!$D$215:$D$226,TALLY!A17) -> 0 | M17: =COUNTIF(TT!$D$234:$D$243,TALLY!A17) -> 0 | N17: =COUNTIF(TT!$D$250:$D$262,TALLY!A17) -> 1 | O17: =COUNTIF(TT!$D$270:$D$277,TALLY!A17) -> 0 | P17: =COUNTIF(TT!$D$284:$D$293,TALLY!A17) -> 1 | Q17: =COUNTIF(TT!$D$300:$D$313,TALLY!A17) -> 0 | R17: =COUNTIF(TT!$D$320:$D$333,TALLY!A17) -> 0 | S17: =COUNTIF(TT!$D$342:$D$352,TALLY!A17) -> 0 | T17: =COUNTIF(TT!$D$359:$D$376,TALLY!A17) -> 1 | U17: =COUNTIF(TT!$D$383:$D$398,TALLY!A17) -> 0 | V17: =COUNTIF(TT!$D$405:$D$424,TALLY!A17) -> 0 | W17: =COUNTIF(TT!$D$432:$D$442,TALLY!A17) -> 1 | X17: =COUNTIF(TT!$D$449:$D$460,TALLY!A17) -> 0 | Y17: =COUNTIF(TT!$D$467:$D$476,TALLY!A17) -> 1 | Z17: =COUNTIF(TT!$D$483:$D$500,TALLY!A17) -> 0 | AA17: =COUNTIF(TT!$D$507:$D$522,TALLY!A17) -> 0 | AB17: =COUNTIF(TT!$D$529:$D$540,TALLY!A17) -> 0 | AC17: =COUNTIF(TT!$D$546:$D$555,TALLY!A17) -> 0 | AD17: =COUNTIF(TT!$D$563:$D$573,TALLY!A17) -> 0 | AE17: =COUNTIF(TT!$D$582:$D$609,TALLY!A17) -> 1 | AF17: =COUNTIF(TT!$D$615:$D$625,TALLY!A17) -> 0 | AG17: =COUNTIF(TT!$D$635:$D$648,TALLY!A17) -> 0 | AH17: =COUNTIF(TT!$D$655:$D$668,TALLY!A17) -> 0 | AI17: =COUNTIF(TT!$D$675:$D$687,TALLY!A17) -> 0 | AK17: ED1-METE | AL17: =SUM($B17:$H17) -> 2 | AM17: =SUM(I17:O17) -> 1 | AN17: =SUM(P17:V17) -> 2 | AO17: =SUM(W17:AA17) -> 2 | AP17: =SUM(AD17:AJ17) -> 1 | AQ17: =SUM(AL17:AP17) -> 8
A18: ED1-MSE | B18: =COUNTIF(TT!$D$4:$D$25,TALLY!A18) -> 0 | C18: =COUNTIF(TT!$D$33:$D$50,TALLY!A18) -> 0 | D18: =COUNTIF(TT!$D$57:$D$75,TALLY!A18) -> 1 | E18: =COUNTIF(TT!$D$82:$D$95,TALLY!A18) -> 0 | F18: =COUNTIF(TT!$D$103:$D$112,TALLY!A18) -> 0 | G18: =COUNTIF(TT!$D$120:$D$130,TALLY!A18) -> 0 | H18: =COUNTIF(TT!$D$138:$D$153,TALLY!A18) -> 1 | I18: =COUNTIF(TT!$D$160:$D$170,TALLY!A18) -> 0 | J18: =COUNTIF(TT!$D$177:$D$187,TALLY!A18) -> 0 | K18: =COUNTIF(TT!$D$194:$D$206,TALLY!A18) -> 0 | L18: =COUNTIF(TT!$D$215:$D$226,TALLY!A18) -> 0 | M18: =COUNTIF(TT!$D$234:$D$243,TALLY!A18) -> 0 | N18: =COUNTIF(TT!$D$250:$D$262,TALLY!A18) -> 0 | O18: =COUNTIF(TT!$D$270:$D$277,TALLY!A18) -> 0 | P18: =COUNTIF(TT!$D$284:$D$293,TALLY!A18) -> 0 | Q18: =COUNTIF(TT!$D$300:$D$313,TALLY!A18) -> 0 | R18: =COUNTIF(TT!$D$320:$D$333,TALLY!A18) -> 0 | S18: =COUNTIF(TT!$D$342:$D$352,TALLY!A18) -> 0 | T18: =COUNTIF(TT!$D$359:$D$376,TALLY!A18) -> 1 | U18: =COUNTIF(TT!$D$383:$D$398,TALLY!A18) -> 0 | V18: =COUNTIF(TT!$D$405:$D$424,TALLY!A18) -> 0 | W18: =COUNTIF(TT!$D$432:$D$442,TALLY!A18) -> 1 | X18: =COUNTIF(TT!$D$449:$D$460,TALLY!A18) -> 0 | Y18: =COUNTIF(TT!$D$467:$D$476,TALLY!A18) -> 0 | Z18: =COUNTIF(TT!$D$483:$D$500,TALLY!A18) -> 0 | AA18: =COUNTIF(TT!$D$507:$D$522,TALLY!A18) -> 0 | AB18: =COUNTIF(TT!$D$529:$D$540,TALLY!A18) -> 0 | AC18: =COUNTIF(TT!$D$546:$D$555,TALLY!A18) -> 1 | AD18: =COUNTIF(TT!$D$563:$D$573,TALLY!A18) -> 0 | AE18: =COUNTIF(TT!$D$582:$D$609,TALLY!A18) -> 1 | AF18: =COUNTIF(TT!$D$615:$D$625,TALLY!A18) -> 0 | AG18: =COUNTIF(TT!$D$635:$D$648,TALLY!A18) -> 0 | AH18: =COUNTIF(TT!$D$655:$D$668,TALLY!A18) -> 0 | AI18: =COUNTIF(TT!$D$675:$D$687,TALLY!A18) -> 0 | AK18: ED1-MSE | AL18: =SUM($B18:$H18) -> 2 | AM18: =SUM(I18:O18) -> 0 | AN18: =SUM(P18:V18) -> 1 | AO18: =SUM(W18:AA18) -> 1 | AP18: =SUM(AD18:AJ18) -> 1 | AQ18: =SUM(AL18:AP18) -> 5
A19: ED1-PCE | B19: =COUNTIF(TT!$D$4:$D$25,TALLY!A19) -> 0 | C19: =COUNTIF(TT!$D$33:$D$50,TALLY!A19) -> 1 | D19: =COUNTIF(TT!$D$57:$D$75,TALLY!A19) -> 0 | E19: =COUNTIF(TT!$D$82:$D$95,TALLY!A19) -> 0 | F19: =COUNTIF(TT!$D$103:$D$112,TALLY!A19) -> 0 | G19: =COUNTIF(TT!$D$120:$D$130,TALLY!A19) -> 0 | H19: =COUNTIF(TT!$D$138:$D$153,TALLY!A19) -> 0 | I19: =COUNTIF(TT!$D$160:$D$170,TALLY!A19) -> 0 | J19: =COUNTIF(TT!$D$177:$D$187,TALLY!A19) -> 1 | K19: =COUNTIF(TT!$D$194:$D$206,TALLY!A19) -> 0 | L19: =COUNTIF(TT!$D$215:$D$226,TALLY!A19) -> 0 | M19: =COUNTIF(TT!$D$234:$D$243,TALLY!A19) -> 0 | N19: =COUNTIF(TT!$D$250:$D$262,TALLY!A19) -> 1 | O19: =COUNTIF(TT!$D$270:$D$277,TALLY!A19) -> 0 | P19: =COUNTIF(TT!$D$284:$D$293,TALLY!A19) -> 0 | Q19: =COUNTIF(TT!$D$300:$D$313,TALLY!A19) -> 0 | R19: =COUNTIF(TT!$D$320:$D$333,TALLY!A19) -> 0 | S19: =COUNTIF(TT!$D$342:$D$352,TALLY!A19) -> 0 | T19: =COUNTIF(TT!$D$359:$D$376,TALLY!A19) -> 0 | U19: =COUNTIF(TT!$D$383:$D$398,TALLY!A19) -> 0 | V19: =COUNTIF(TT!$D$405:$D$424,TALLY!A19) -> 1 | W19: =COUNTIF(TT!$D$432:$D$442,TALLY!A19) -> 1 | X19: =COUNTIF(TT!$D$449:$D$460,TALLY!A19) -> 0 | Y19: =COUNTIF(TT!$D$467:$D$476,TALLY!A19) -> 0 | Z19: =COUNTIF(TT!$D$483:$D$500,TALLY!A19) -> 1 | AA19: =COUNTIF(TT!$D$507:$D$522,TALLY!A19) -> 0 | AB19: =COUNTIF(TT!$D$529:$D$540,TALLY!A19) -> 0 | AC19: =COUNTIF(TT!$D$546:$D$555,TALLY!A19) -> 0 | AD19: =COUNTIF(TT!$D$563:$D$573,TALLY!A19) -> 0 | AE19: =COUNTIF(TT!$D$582:$D$609,TALLY!A19) -> 0 | AF19: =COUNTIF(TT!$D$615:$D$626,TALLY!A19) -> 0 | AG19: =COUNTIF(TT!$D$635:$D$648,TALLY!A19) -> 1 | AH19: =COUNTIF(TT!$D$655:$D$668,TALLY!A19) -> 0 | AI19: =COUNTIF(TT!$D$675:$D$687,TALLY!A19) -> 0 | AK19: ED1-PCE | AL19: =SUM($B19:$H19) -> 1 | AM19: =SUM(I19:O19) -> 2 | AN19: =SUM(P19:V19) -> 1 | AO19: =SUM(W19:AA19) -> 2 | AP19: =SUM(AD19:AJ19) -> 1 | AQ19: =SUM(AL19:AP19) -> 7
A20: ED1-PETE | B20: =COUNTIF(TT!$D$4:$D$25,TALLY!A20) -> 0 | C20: =COUNTIF(TT!$D$33:$D$50,TALLY!A20) -> 0 | D20: =COUNTIF(TT!$D$57:$D$75,TALLY!A20) -> 1 | E20: =COUNTIF(TT!$D$82:$D$95,TALLY!A20) -> 0 | F20: =COUNTIF(TT!$D$103:$D$112,TALLY!A20) -> 0 | G20: =COUNTIF(TT!$D$120:$D$130,TALLY!A20) -> 0 | H20: =COUNTIF(TT!$D$138:$D$153,TALLY!A20) -> 0 | I20: =COUNTIF(TT!$D$160:$D$170,TALLY!A20) -> 0 | J20: =COUNTIF(TT!$D$177:$D$187,TALLY!A20) -> 1 | K20: =COUNTIF(TT!$D$194:$D$206,TALLY!A20) -> 0 | L20: =COUNTIF(TT!$D$215:$D$226,TALLY!A20) -> 0 | M20: =COUNTIF(TT!$D$234:$D$243,TALLY!A20) -> 0 | N20: =COUNTIF(TT!$D$250:$D$262,TALLY!A20) -> 0 | O20: =COUNTIF(TT!$D$270:$D$277,TALLY!A20) -> 0 | P20: =COUNTIF(TT!$D$284:$D$293,TALLY!A20) -> 0 | Q20: =COUNTIF(TT!$D$300:$D$313,TALLY!A20) -> 1 | R20: =COUNTIF(TT!$D$320:$D$333,TALLY!A20) -> 0 | S20: =COUNTIF(TT!$D$342:$D$352,TALLY!A20) -> 0 | T20: =COUNTIF(TT!$D$359:$D$376,TALLY!A20) -> 0 | U20: =COUNTIF(TT!$D$383:$D$398,TALLY!A20) -> 0 | V20: =COUNTIF(TT!$D$405:$D$424,TALLY!A20) -> 1 | W20: =COUNTIF(TT!$D$432:$D$442,TALLY!A20) -> 0 | X20: =COUNTIF(TT!$D$449:$D$460,TALLY!A20) -> 0 | Y20: =COUNTIF(TT!$D$467:$D$476,TALLY!A20) -> 0 | Z20: =COUNTIF(TT!$D$483:$D$500,TALLY!A20) -> 1 | AA20: =COUNTIF(TT!$D$507:$D$522,TALLY!A20) -> 0 | AB20: =COUNTIF(TT!$D$529:$D$540,TALLY!A20) -> 0 | AC20: =COUNTIF(TT!$D$546:$D$555,TALLY!A20) -> 0 | AD20: =COUNTIF(TT!$D$563:$D$573,TALLY!A20) -> 1 | AE20: =COUNTIF(TT!$D$582:$D$609,TALLY!A20) -> 0 | AF20: =COUNTIF(TT!$D$615:$D$626,TALLY!A20) -> 0 | AG20: =COUNTIF(TT!$D$635:$D$648,TALLY!A20) -> 0 | AH20: =COUNTIF(TT!$D$655:$D$668,TALLY!A20) -> 0 | AI20: =COUNTIF(TT!$D$675:$D$687,TALLY!A20) -> 0 | AK20: ED1-PETE | AL20: =SUM($B20:$H20) -> 1 | AM20: =SUM(I20:O20) -> 1 | AN20: =SUM(P20:V20) -> 2 | AO20: =SUM(W20:AA20) -> 1 | AP20: =SUM(AD20:AJ20) -> 1 | AQ20: =SUM(AL20:AP20) -> 6
A21: ED1-TEL | B21: =COUNTIF(TT!$D$4:$D$25,TALLY!A21) -> 0 | C21: =COUNTIF(TT!$D$33:$D$50,TALLY!A21) -> 0 | D21: =COUNTIF(TT!$D$57:$D$75,TALLY!A21) -> 1 | E21: =COUNTIF(TT!$D$82:$D$95,TALLY!A21) -> 0 | F21: =COUNTIF(TT!$D$103:$D$112,TALLY!A21) -> 0 | G21: =COUNTIF(TT!$D$120:$D$130,TALLY!A21) -> 1 | H21: =COUNTIF(TT!$D$138:$D$153,TALLY!A21) -> 0 | I21: =COUNTIF(TT!$D$160:$D$170,TALLY!A21) -> 0 | J21: =COUNTIF(TT!$D$177:$D$187,TALLY!A21) -> 1 | K21: =COUNTIF(TT!$D$194:$D$206,TALLY!A21) -> 0 | L21: =COUNTIF(TT!$D$215:$D$226,TALLY!A21) -> 0 | M21: =COUNTIF(TT!$D$234:$D$243,TALLY!A21) -> 1 | N21: =COUNTIF(TT!$D$250:$D$262,TALLY!A21) -> 0 | O21: =COUNTIF(TT!$D$270:$D$277,TALLY!A21) -> 0 | P21: =COUNTIF(TT!$D$284:$D$293,TALLY!A21) -> 1 | Q21: =COUNTIF(TT!$D$300:$D$313,TALLY!A21) -> 0 | R21: =COUNTIF(TT!$D$320:$D$333,TALLY!A21) -> 0 | S21: =COUNTIF(TT!$D$342:$D$352,TALLY!A21) -> 1 | T21: =COUNTIF(TT!$D$359:$D$376,TALLY!A21) -> 0 | U21: =COUNTIF(TT!$D$383:$D$398,TALLY!A21) -> 0 | V21: =COUNTIF(TT!$D$405:$D$424,TALLY!A21) -> 0 | W21: =COUNTIF(TT!$D$432:$D$442,TALLY!A21) -> 0 | X21: =COUNTIF(TT!$D$449:$D$460,TALLY!A21) -> 0 | Y21: =COUNTIF(TT!$D$467:$D$476,TALLY!A21) -> 0 | Z21: =COUNTIF(TT!$D$483:$D$500,TALLY!A21) -> 1 | AA21: =COUNTIF(TT!$D$507:$D$522,TALLY!A21) -> 0 | AB21: =COUNTIF(TT!$D$529:$D$540,TALLY!A21) -> 0 | AC21: =COUNTIF(TT!$D$546:$D$555,TALLY!A21) -> 0 | AD21: =COUNTIF(TT!$D$563:$D$573,TALLY!A21) -> 1 | AE21: =COUNTIF(TT!$D$582:$D$609,TALLY!A21) -> 0 | AF21: =COUNTIF(TT!$D$615:$D$626,TALLY!A21) -> 0 | AG21: =COUNTIF(TT!$D$635:$D$648,TALLY!A21) -> 0 | AH21: =COUNTIF(TT!$D$655:$D$668,TALLY!A21) -> 0 | AI21: =COUNTIF(TT!$D$675:$D$687,TALLY!A21) -> 0 | AK21: ED1-TEL | AL21: =SUM($B21:$H21) -> 2 | AM21: =SUM(I21:O21) -> 2 | AN21: =SUM(P21:V21) -> 2 | AO21: =SUM(W21:AA21) -> 1 | AP21: =SUM(AD21:AJ21) -> 1 | AQ21: =SUM(AL21:AP21) -> 8
A22: ED2-AE | B22: =COUNTIF(TT!$D$4:$D$25,TALLY!A22) -> 1 | C22: =COUNTIF(TT!$D$33:$D$50,TALLY!A22) -> 0 | D22: =COUNTIF(TT!$D$57:$D$75,TALLY!A22) -> 0 | E22: =COUNTIF(TT!$D$82:$D$95,TALLY!A22) -> 0 | F22: =COUNTIF(TT!$D$103:$D$112,TALLY!A22) -> 1 | G22: =COUNTIF(TT!$D$120:$D$130,TALLY!A22) -> 0 | H22: =COUNTIF(TT!$D$138:$D$153,TALLY!A22) -> 0 | I22: =COUNTIF(TT!$D$160:$D$170,TALLY!A22) -> 0 | J22: =COUNTIF(TT!$D$177:$D$187,TALLY!A22) -> 0 | K22: =COUNTIF(TT!$D$194:$D$206,TALLY!A22) -> 0 | L22: =COUNTIF(TT!$D$215:$D$226,TALLY!A22) -> 0 | M22: =COUNTIF(TT!$D$234:$D$243,TALLY!A22) -> 0 | N22: =COUNTIF(TT!$D$250:$D$262,TALLY!A22) -> 0 | O22: =COUNTIF(TT!$D$270:$D$277,TALLY!A22) -> 0 | P22: =COUNTIF(TT!$D$284:$D$293,TALLY!A22) -> 0 | Q22: =COUNTIF(TT!$D$300:$D$313,TALLY!A22) -> 1 | R22: =COUNTIF(TT!$D$320:$D$333,TALLY!A22) -> 0 | S22: =COUNTIF(TT!$D$342:$D$352,TALLY!A22) -> 0 | T22: =COUNTIF(TT!$D$359:$D$376,TALLY!A22) -> 0 | U22: =COUNTIF(TT!$D$383:$D$398,TALLY!A22) -> 0 | V22: =COUNTIF(TT!$D$405:$D$424,TALLY!A22) -> 0 | W22: =COUNTIF(TT!$D$432:$D$442,TALLY!A22) -> 0 | X22: =COUNTIF(TT!$D$449:$D$460,TALLY!A22) -> 0 | Y22: =COUNTIF(TT!$D$467:$D$476,TALLY!A22) -> 1 | Z22: =COUNTIF(TT!$D$483:$D$500,TALLY!A22) -> 0 | AA22: =COUNTIF(TT!$D$507:$D$522,TALLY!A22) -> 0 | AB22: =COUNTIF(TT!$D$529:$D$540,TALLY!A22) -> 0 | AC22: =COUNTIF(TT!$D$546:$D$555,TALLY!A22) -> 0 | AD22: =COUNTIF(TT!$D$563:$D$573,TALLY!A22) -> 1 | AE22: =COUNTIF(TT!$D$582:$D$609,TALLY!A22) -> 1 | AF22: =COUNTIF(TT!$D$615:$D$626,TALLY!A22) -> 0 | AG22: =COUNTIF(TT!$D$635:$D$648,TALLY!A22) -> 0 | AH22: =COUNTIF(TT!$D$655:$D$668,TALLY!A22) -> 0 | AI22: =COUNTIF(TT!$D$675:$D$687,TALLY!A22) -> 0 | AK22: ED2-AE | AL22: =SUM($B22:$H22) -> 2 | AM22: =SUM(I22:O22) -> 0 | AN22: =SUM(P22:V22) -> 1 | AO22: =SUM(W22:AA22) -> 1 | AP22: =SUM(AD22:AJ22) -> 2 | AQ22: =SUM(AL22:AP22) -> 6
A23: ED2-AERO | B23: =COUNTIF(TT!$D$4:$D$25,TALLY!A23) -> 0 | C23: =COUNTIF(TT!$D$33:$D$50,TALLY!A23) -> 1 | D23: =COUNTIF(TT!$D$57:$D$75,TALLY!A23) -> 0 | E23: =COUNTIF(TT!$D$82:$D$95,TALLY!A23) -> 0 | F23: =COUNTIF(TT!$D$103:$D$112,TALLY!A23) -> 0 | G23: =COUNTIF(TT!$D$120:$D$130,TALLY!A23) -> 0 | H23: =COUNTIF(TT!$D$138:$D$153,TALLY!A23) -> 0 | I23: =COUNTIF(TT!$D$160:$D$170,TALLY!A23) -> 1 | J23: =COUNTIF(TT!$D$177:$D$187,TALLY!A23) -> 0 | K23: =COUNTIF(TT!$D$194:$D$206,TALLY!A23) -> 0 | L23: =COUNTIF(TT!$D$215:$D$226,TALLY!A23) -> 0 | M23: =COUNTIF(TT!$D$234:$D$243,TALLY!A23) -> 0 | N23: =COUNTIF(TT!$D$250:$D$262,TALLY!A23) -> 0 | O23: =COUNTIF(TT!$D$270:$D$277,TALLY!A23) -> 0 | P23: =COUNTIF(TT!$D$284:$D$293,TALLY!A23) -> 0 | Q23: =COUNTIF(TT!$D$300:$D$313,TALLY!A23) -> 1 | R23: =COUNTIF(TT!$D$320:$D$333,TALLY!A23) -> 0 | S23: =COUNTIF(TT!$D$342:$D$352,TALLY!A23) -> 0 | T23: =COUNTIF(TT!$D$359:$D$376,TALLY!A23) -> 0 | U23: =COUNTIF(TT!$D$383:$D$398,TALLY!A23) -> 0 | V23: =COUNTIF(TT!$D$405:$D$424,TALLY!A23) -> 0 | W23: =COUNTIF(TT!$D$432:$D$442,TALLY!A23) -> 0 | X23: =COUNTIF(TT!$D$449:$D$460,TALLY!A23) -> 0 | Y23: =COUNTIF(TT!$D$467:$D$476,TALLY!A23) -> 1 | Z23: =COUNTIF(TT!$D$483:$D$500,TALLY!A23) -> 0 | AA23: =COUNTIF(TT!$D$507:$D$522,TALLY!A23) -> 0 | AB23: =COUNTIF(TT!$D$529:$D$540,TALLY!A23) -> 0 | AC23: =COUNTIF(TT!$D$546:$D$555,TALLY!A23) -> 0 | AD23: =COUNTIF(TT!$D$563:$D$573,TALLY!A23) -> 0 | AE23: =COUNTIF(TT!$D$582:$D$609,TALLY!A23) -> 1 | AF23: =COUNTIF(TT!$D$615:$D$626,TALLY!A23) -> 0 | AG23: =COUNTIF(TT!$D$635:$D$648,TALLY!A23) -> 0 | AH23: =COUNTIF(TT!$D$655:$D$668,TALLY!A23) -> 0 | AI23: =COUNTIF(TT!$D$675:$D$687,TALLY!A23) -> 1 | AK23: ED2-AERO | AL23: =SUM($B23:$H23) -> 1 | AM23: =SUM(I23:O23) -> 1 | AN23: =SUM(P23:V23) -> 1 | AO23: =SUM(W23:AA23) -> 1 | AP23: =SUM(AD23:AJ23) -> 2 | AQ23: =SUM(AL23:AP23) -> 6
A24: ED2-AUTO | B24: =COUNTIF(TT!$D$4:$D$25,TALLY!A24) -> 0 | C24: =COUNTIF(TT!$D$33:$D$50,TALLY!A24) -> 0 | D24: =COUNTIF(TT!$D$57:$D$75,TALLY!A24) -> 0 | E24: =COUNTIF(TT!$D$82:$D$95,TALLY!A24) -> 0 | F24: =COUNTIF(TT!$D$103:$D$112,TALLY!A24) -> 0 | G24: =COUNTIF(TT!$D$120:$D$130,TALLY!A24) -> 1 | H24: =COUNTIF(TT!$D$138:$D$153,TALLY!A24) -> 0 | I24: =COUNTIF(TT!$D$160:$D$170,TALLY!A24) -> 1 | J24: =COUNTIF(TT!$D$177:$D$187,TALLY!A24) -> 0 | K24: =COUNTIF(TT!$D$194:$D$206,TALLY!A24) -> 0 | L24: =COUNTIF(TT!$D$215:$D$226,TALLY!A24) -> 0 | M24: =COUNTIF(TT!$D$234:$D$243,TALLY!A24) -> 0 | N24: =COUNTIF(TT!$D$250:$D$262,TALLY!A24) -> 0 | O24: =COUNTIF(TT!$D$270:$D$277,TALLY!A24) -> 0 | P24: =COUNTIF(TT!$D$284:$D$293,TALLY!A24) -> 0 | Q24: =COUNTIF(TT!$D$300:$D$313,TALLY!A24) -> 0 | R24: =COUNTIF(TT!$D$320:$D$333,TALLY!A24) -> 0 | S24: =COUNTIF(TT!$D$342:$D$352,TALLY!A24) -> 0 | T24: =COUNTIF(TT!$D$359:$D$376,TALLY!A24) -> 0 | U24: =COUNTIF(TT!$D$383:$D$398,TALLY!A24) -> 1 | V24: =COUNTIF(TT!$D$405:$D$424,TALLY!A24) -> 0 | W24: =COUNTIF(TT!$D$432:$D$442,TALLY!A24) -> 0 | X24: =COUNTIF(TT!$D$449:$D$460,TALLY!A24) -> 0 | Y24: =COUNTIF(TT!$D$467:$D$476,TALLY!A24) -> 0 | Z24: =COUNTIF(TT!$D$483:$D$500,TALLY!A24) -> 1 | AA24: =COUNTIF(TT!$D$507:$D$522,TALLY!A24) -> 0 | AB24: =COUNTIF(TT!$D$529:$D$540,TALLY!A24) -> 0 | AC24: =COUNTIF(TT!$D$546:$D$555,TALLY!A24) -> 0 | AD24: =COUNTIF(TT!$D$563:$D$573,TALLY!A24) -> 0 | AE24: =COUNTIF(TT!$D$582:$D$609,TALLY!A24) -> 1 | AF24: =COUNTIF(TT!$D$615:$D$626,TALLY!A24) -> 0 | AG24: =COUNTIF(TT!$D$635:$D$648,TALLY!A24) -> 0 | AH24: =COUNTIF(TT!$D$655:$D$668,TALLY!A24) -> 0 | AI24: =COUNTIF(TT!$D$675:$D$687,TALLY!A24) -> 0 | AK24: ED2-AUTO | AL24: =SUM($B24:$H24) -> 1 | AM24: =SUM(I24:O24) -> 1 | AN24: =SUM(P24:V24) -> 1 | AO24: =SUM(W24:AA24) -> 1 | AP24: =SUM(AD24:AJ24) -> 1 | AQ24: =SUM(AL24:AP24) -> 5
A25: ED2-BME | B25: =COUNTIF(TT!$D$4:$D$25,TALLY!A25) -> 0 | C25: =COUNTIF(TT!$D$33:$D$50,TALLY!A25) -> 0 | D25: =COUNTIF(TT!$D$57:$D$75,TALLY!A25) -> 1 | E25: =COUNTIF(TT!$D$82:$D$95,TALLY!A25) -> 0 | F25: =COUNTIF(TT!$D$103:$D$112,TALLY!A25) -> 0 | G25: =COUNTIF(TT!$D$120:$D$130,TALLY!A25) -> 0 | H25: =COUNTIF(TT!$D$138:$D$153,TALLY!A25) -> 0 | I25: =COUNTIF(TT!$D$160:$D$170,TALLY!A25) -> 0 | J25: =COUNTIF(TT!$D$177:$D$187,TALLY!A25) -> 0 | K25: =COUNTIF(TT!$D$194:$D$206,TALLY!A25) -> 1 | L25: =COUNTIF(TT!$D$215:$D$226,TALLY!A25) -> 0 | M25: =COUNTIF(TT!$D$234:$D$243,TALLY!A25) -> 0 | N25: =COUNTIF(TT!$D$250:$D$262,TALLY!A25) -> 1 | O25: =COUNTIF(TT!$D$270:$D$277,TALLY!A25) -> 0 | P25: =COUNTIF(TT!$D$284:$D$293,TALLY!A25) -> 0 | Q25: =COUNTIF(TT!$D$300:$D$313,TALLY!A25) -> 0 | R25: =COUNTIF(TT!$D$320:$D$333,TALLY!A25) -> 0 | S25: =COUNTIF(TT!$D$342:$D$352,TALLY!A25) -> 0 | T25: =COUNTIF(TT!$D$359:$D$376,TALLY!A25) -> 1 | U25: =COUNTIF(TT!$D$383:$D$398,TALLY!A25) -> 0 | V25: =COUNTIF(TT!$D$405:$D$424,TALLY!A25) -> 0 | W25: =COUNTIF(TT!$D$432:$D$442,TALLY!A25) -> 0 | X25: =COUNTIF(TT!$D$449:$D$460,TALLY!A25) -> 1 | Y25: =COUNTIF(TT!$D$467:$D$476,TALLY!A25) -> 0 | Z25: =COUNTIF(TT!$D$483:$D$500,TALLY!A25) -> 0 | AA25: =COUNTIF(TT!$D$507:$D$522,TALLY!A25) -> 0 | AB25: =COUNTIF(TT!$D$529:$D$540,TALLY!A25) -> 0 | AC25: =COUNTIF(TT!$D$546:$D$555,TALLY!A25) -> 0 | AD25: =COUNTIF(TT!$D$563:$D$573,TALLY!A25) -> 0 | AE25: =COUNTIF(TT!$D$582:$D$609,TALLY!A25) -> 1 | AF25: =COUNTIF(TT!$D$615:$D$626,TALLY!A25) -> 0 | AG25: =COUNTIF(TT!$D$635:$D$648,TALLY!A25) -> 0 | AH25: =COUNTIF(TT!$D$655:$D$668,TALLY!A25) -> 1 | AI25: =COUNTIF(TT!$D$675:$D$687,TALLY!A25) -> 0 | AK25: ED2-BME | AL25: =SUM($B25:$H25) -> 1 | AM25: =SUM(I25:O25) -> 2 | AN25: =SUM(P25:V25) -> 1 | AO25: =SUM(W25:AA25) -> 1 | AP25: =SUM(AD25:AJ25) -> 2 | AQ25: =SUM(AL25:AP25) -> 7
